File: Example - Raw files/oedometer.lvm
Oedometer-2	06.10.2015
*Header*
Operator	G2-1
Site	Stjørdal
Hole
Depth [m]	11,4
Comment	This sample might also be Group 1.2's
Sample area [cm2]	20
Sample height [mm]	20
*Calibration data *
Motor [steps/rev]	16000
Jack [µm/rev]	794
Load cell fact. [N/V]	488,3
Pore sens. fact. [kPa/V]	109
LVDT fact. [µm/V]	-1050
SelfDeform factor	,495368
SelfDeform exp	,75
Slack [steps]	0

        		Load	Pore			Vertica	Pore
Mean        	Deform.	cell	sens.	LVDT.	Deforma	stress	pressur
time        	[steps]	[V]		[V]		[V]		[µm]	[kPa]	[kPa]	MODE
------------	-------	-------	-------	-------	-------	-------	-------	-------
11:26:47,521	0		,003854	,7688		0	-0		0		0		ZERO
11:27:52,520	109,84	,011785	,769123	,766822	4,08338	1,9362	,035174	CRS
11:29:02,520	227,32	,015392	,769113	,76681	9,46932	2,81688	,034146	CRS
11:30:12,519	344,72	,018478	,769123	,766816	14,9428	3,57038	,035216	CRS
11:31:22,518	462,16	,021329	,769114	,766814	20,4615	4,26655	,03424	CRS
11:32:32,518	579,68	,023594	,769041	,766733	26,0567	4,81947	,026232	CRS
11:33:42,517	697,08	,025472	,76902	,76672	31,6916	5,27784	,023943	CRS
11:34:52,516	814,5	,027512	,769088	,766783	37,3155	5,7761	,031406	CRS
11:36:02,516	932	,029663	,769077	,766774	42,9372	6,3011	,03017	CRS
11:37:12,515	1049,44	,031519	,769137	,766838	48,588	6,75433	,03675	CRS
11:38:22,515	1166,84	,033003	,769183	,766884	54,2745	7,11661	,041729	CRS
11:39:32,514	1284,32	,034787	,769309	,767014	59,939	7,55227	,055514	CRS
11:40:42,513	1401,84	,036383	,769369	,767076	65,625	7,94189	,062003	CRS
11:41:52,513	1519,16	,037981	,769474	,767177	71,3026	8,33212	,073499	CRS
11:43:02,512	1636,68	,039443	,769571	,76728	77,004	8,68905	,084008	CRS
11:44:12,512	1754,16	,04158	,769825	,76754	82,6454	9,21084	,111717	CRS
11:45:22,511	1871,54	,043699	,770206	,767932	88,2862	9,72807	,153306	CRS
11:46:32,510	1989	,045292	,770356	,768086	93,9782	10,117	,169625	CRS
11:47:42,510	2106,5	,047603	,770626	,768363	99,6128	10,6811	,199051	CRS
11:48:52,510	2223,92	,050129	,77113	,76888	105,228	11,298	,254016	CRS
11:50:02,509	2341,32	,05262	,771777	,769535	110,848	11,9062	,32452	CRS
11:51:12,508	2458,84	,054752	,772408	,770154	116,506	12,4268	,393234	CRS
11:52:22,508	2576,26	,05642	,772873	,770615	122,198	12,8338	,443962	CRS
11:53:32,507	2693,68	,058791	,773775	,771488	127,835	13,4127	,542302	CRS
11:54:42,506	2811,16	,060511	,774298	,772003	133,528	13,8326	,599235	CRS
11:55:52,505	2928,68	,062182	,774877	,772575	139,228	14,2407	,662441	CRS
11:57:02,505	3046	,064374	,775901	,773617	144,879	14,7759	,773962	CRS
11:58:12,504	3163,5	,066467	,777001	,774743	150,548	15,2869	,893878	CRS
11:59:22,504	3281	,068308	,778021	,775757	156,237	15,7364	1,0051	CRS
12:00:32,503	3398,36	,070351	,779493	,777204	161,905	16,2351	1,16557	CRS
12:01:42,502	3515,84	,072642	,781163	,778902	167,562	16,7945	1,34758	CRS
12:02:52,502	3633,32	,075352	,782925	,78068	173,189	17,4561	1,5396	CRS
12:04:02,501	3750,76	,077802	,78429	,782018	178,835	18,0544	1,68839	CRS
12:05:12,501	3868,16	,080579	,786056	,783777	184,456	18,7324	1,88092	CRS
12:06:22,500	3985,68	,083159	,788089	,785848	190,1	19,3622	2,10255	CRS
12:07:32,499	4103,1	,085783	,789929	,787678	195,736	20,003	2,30309	CRS
12:08:42,499	4220,5	,088619	,791762	,789514	201,359	20,6952	2,50282	CRS
12:09:52,498	4338	,091565	,793717	,791425	206,98	21,4146	2,71595	CRS
12:11:02,497	4455,46	,094538	,795726	,79348	212,599	22,1404	2,9349	CRS
12:12:12,497	4572,84	,098247	,798745	,796477	218,164	23,046	3,26404	CRS
12:13:22,496	4690,32	,101691	,800887	,798637	223,756	23,8867	3,4975	CRS
12:14:32,496	4807,84	,105431	,803293	,801018	229,331	24,8	3,75971	CRS
12:15:42,495	4925,18	,109195	,806075	,803825	234,897	25,7188	4,06302	CRS
12:16:52,494	5042,68	,112936	,808453	,806212	240,476	26,6324	4,32216	CRS
12:18:02,494	5160,16	,117093	,811333	,809048	246,028	27,6472	4,63614	CRS
12:19:12,493	5277,58	,121221	,813826	,811587	251,582	28,6551	4,90783	CRS
12:20:22,493	5395	,125169	,816005	,813744	257,149	29,6191	5,14539	CRS
12:21:32,492	5512,5	,129094	,818334	,816075	262,725	30,5773	5,39922	CRS
12:22:42,492	5629,94	,13272	,819781	,817556	268,318	31,4626	5,55692	CRS
12:23:52,492	5747,32	,136537	,821242	,81898	273,898	32,3946	5,71617	CRS
12:25:02,490	5864,84	,139898	,822753	,820471	279,516	33,2151	5,88091	CRS
12:26:12,489	5982,3	,143253	,823947	,821691	285,133	34,0341	6,01102	CRS
12:27:22,489	6099,68	,146797	,8253	,823052	290,734	34,8995	6,15853	CRS
12:28:32,488	6217,16	,150083	,826544	,8243	296,359	35,7017	6,29407	CRS
12:29:42,488	6334,68	,153933	,828679	,826422	301,951	36,6416	6,52683	CRS
12:30:52,487	6452,04	,157112	,829855	,827581	307,578	37,4179	6,65505	CRS
12:32:02,486	6569,5	,160203	,830737	,82848	313,217	38,1726	6,75112	CRS
12:33:12,486	6687	,163879	,832173	,829935	318,823	39,07	6,90766	CRS
12:34:22,485	6804,4	,168517	,834458	,832219	324,367	40,2023	7,15671	CRS
12:35:32,485	6921,84	,173511	,836804	,834521	329,894	41,4217	7,41241	CRS
12:36:42,484	7039,32	,177581	,838014	,835776	335,48	42,4153	7,54437	CRS
12:37:52,484	7156,78	,181448	,838962	,836737	341,078	43,3596	7,6477	CRS
12:39:02,483	7274,16	,185404	,839865	,837631	346,669	44,3254	7,7461	CRS
12:40:12,482	7391,68	,18963	,841169	,838928	352,251	45,3571	7,88827	CRS
12:41:22,481	7509,14	,193767	,842136	,839902	357,838	46,3671	7,99364	CRS
12:42:32,481	7626,5	,197783	,84311	,840878	363,428	47,3476	8,09982	CRS
12:43:42,480	7744	,201693	,843904	,841671	369,032	48,3023	8,18632	CRS
12:44:52,480	7861,5	,205563	,844352	,842118	374,639	49,2471	8,23513	CRS
12:46:02,479	7978,88	,209604	,844989	,842753	380,232	50,2338	8,30461	CRS
12:47:12,478	8096,32	,213478	,845522	,843278	385,839	51,1795	8,36274	CRS
12:48:22,478	8213,84	,217649	,846112	,843853	391,433	52,1979	8,427	CRS
12:49:32,477	8331,22	,221766	,846611	,844345	397,025	53,2031	8,48138	CRS
12:50:42,477	8448,68	,225829	,847197	,844931	402,625	54,1952	8,54532	CRS
12:51:52,476	8566,16	,229971	,848548	,846327	408,223	55,2064	8,69249	CRS
12:53:02,475	8683,6	,234255	,849818	,847612	413,811	56,2523	8,83092	CRS
12:54:12,475	8801	,238416	,850387	,848174	419,406	57,2681	8,89299	CRS
12:55:22,474	8918,5	,242845	,851089	,848866	424,992	58,3495	8,96947	CRS
12:56:32,473	9035,98	,24691	,851786	,849556	430,598	59,3421	9,04552	CRS
12:57:42,473	9153,32	,251305	,852843	,850577	436,18	60,4151	9,16071	CRS
12:58:52,472	9270,84	,255929	,854184	,851936	441,76	61,5441	9,30685	CRS
13:00:02,472	9388,32	,260434	,855263	,853042	447,345	62,644	9,42451	CRS
13:01:12,471	9505,72	,264919	,856422	,854206	452,928	63,739	9,55075	CRS
13:02:22,470	9623,16	,269529	,856865	,854655	458,508	64,8645	9,5991	CRS
13:03:32,470	9740,68	,274069	,857088	,854881	464,096	65,973	9,62343	CRS
13:04:42,469	9858,06	,278669	,857062	,854854	469,675	67,0959	9,62059	CRS
13:05:52,469	9975,5	,283138	,857427	,85522	475,266	68,187	9,66037	CRS
13:07:02,468	10093	,288509	,859358	,857155	480,812	69,4984	9,87079	CRS
13:08:12,467	10210,4	,293233	,859762	,857555	486,39	70,6517	9,9149	CRS
13:09:22,467	10327,8	,29761	,859467	,857268	491,987	71,7203	9,88271	CRS
13:10:32,466	10445,3	,302789	,860402	,85818	497,546	72,9848	9,98458	CRS
13:11:42,466	10562,8	,307422	,860843	,858604	503,136	74,1161	10,0327	CRS
13:12:52,465	10680,2	,312483	,861691	,859438	508,696	75,3517	10,1251	CRS
13:14:02,464	10797,7	,318212	,863335	,861111	514,232	76,7505	10,3043	CRS
13:15:12,464	10915,2	,322805	,863192	,860972	519,826	77,8718	10,2888	CRS
13:16:22,463	11032,5	,327747	,864006	,861782	525,397	79,0783	10,3775	CRS
13:17:32,462	11150	,332394	,864197	,861969	530,989	80,213	10,3982	CRS
13:18:42,462	11267,5	,33717	,864353	,862128	536,577	81,379	10,4153	CRS
13:19:52,462	11384,9	,342268	,864778	,862555	542,144	82,6237	10,4616	CRS
13:21:02,460	11502,3	,346842	,864197	,861972	547,74	83,7405	10,3983	CRS
13:22:12,460	11619,8	,351717	,864532	,862319	553,327	84,9308	10,4348	CRS
13:23:22,460	11737,3	,35625	,86414	,861925	558,926	86,0375	10,3921	CRS
13:24:32,459	11854,7	,361115	,864267	,862054	564,51	87,2252	10,4059	CRS
13:25:42,458	11972,2	,366835	,865544	,86334	570,055	88,6216	10,5451	CRS
13:26:52,458	12089,7	,371541	,864804	,862595	575,652	89,7706	10,4644	CRS
13:28:02,458	12207	,376714	,865217	,863014	581,22	91,0337	10,5094	CRS
13:29:12,457	12324,5	,382821	,86669	,864517	586,749	92,5246	10,67	CRS
13:30:22,456	12442	,388845	,868707	,866528	592,285	93,9955	10,8898	CRS
13:31:32,455	12559,3	,395482	,871936	,869733	597,783	95,6158	11,2419	CRS
13:32:42,454	12676,8	,400506	,871211	,869021	603,369	96,8424	11,1628	CRS
13:33:52,455	12794,3	,405521	,871018	,868831	608,956	98,0668	11,1418	CRS
13:35:02,454	12911,7	,410917	,871454	,869258	614,522	99,3844	11,1893	CRS
13:36:12,453	13029,2	,415301	,870197	,868032	620,137	100,455	11,0523	CRS
13:37:22,452	13146,7	,420346	,870258	,868099	625,726	101,687	11,059	CRS
13:38:32,452	13264,1	,425583	,870932	,868756	631,301	102,965	11,1324	CRS
13:39:42,451	13381,5	,429897	,869579	,867424	636,922	104,018	10,9849	CRS
13:40:52,450	13499	,434913	,86896	,866804	642,513	105,243	10,9175	CRS
13:42:02,450	13616,5	,440228	,869554	,867406	648,09	106,541	10,9822	CRS
13:43:12,450	13733,8	,444814	,868926	,866771	653,697	107,66	10,9138	CRS
13:44:22,448	13851,3	,44958	,869377	,867232	659,302	108,824	10,9629	CRS
13:45:32,448	13968,8	,454081	,869735	,867594	664,921	109,923	11,0019	CRS
13:46:42,448	14086,2	,458427	,869554	,867412	670,54	110,984	10,9822	CRS
13:47:52,446	14203,7	,463472	,870185	,868046	676,134	112,216	11,051	CRS
13:49:02,446	14321,2	,468117	,86936	,86722	681,746	113,35	10,961	CRS
13:50:12,446	14438,6	,473231	,869842	,867706	687,334	114,598	11,0135	CRS
13:51:22,444	14556	,47898	,871929	,869754	692,894	116,002	11,2411	CRS
13:52:32,445	14673,5	,484691	,873501	,87135	698,46	117,396	11,4124	CRS
13:53:42,443	14790,9	,490146	,874195	,872059	704,034	118,728	11,488	CRS
13:54:52,443	14908,3	,495759	,87493	,872801	709,601	120,098	11,5681	CRS
13:56:02,443	15025,8	,502145	,876301	,874163	715,139	121,658	11,7176	CRS
13:57:12,441	15143,3	,507313	,875995	,873866	720,73	122,919	11,6843	CRS
13:58:22,441	15260,7	,511913	,875768	,873645	726,346	124,042	11,6595	CRS
13:59:32,441	15378,2	,516534	,875581	,873457	731,965	125,171	11,6391	CRS
14:00:42,440	15495,7	,520767	,875315	,873196	737,604	126,204	11,6102	CRS
14:01:52,440	15613	,525016	,874679	,872562	743,233	127,242	11,5409	CRS
14:03:02,439	15730,5	,529896	,875339	,873229	748,842	128,433	11,6128	CRS
14:04:12,438	15848	,534984	,875946	,873828	754,443	129,675	11,6789	CRS
14:05:22,438	15965,4	,540249	,876758	,874623	760,03	130,961	11,7674	CRS
14:06:32,437	16082,8	,544895	,876571	,874441	765,65	132,095	11,747	CRS
14:07:42,437	16200,3	,549544	,876197	,874077	771,271	133,23	11,7063	CRS
14:08:52,435	16317,8	,554798	,876988	,874853	776,863	134,513	11,7925	CRS
14:10:02,435	16435,2	,559658	,876987	,874859	782,471	135,7	11,7924	CRS
14:11:12,434	16552,7	,564349	,876562	,874443	788,094	136,845	11,746	CRS
14:12:22,434	16670,1	,568673	,87586	,873759	793,729	137,9	11,6696	CRS
14:13:32,434	16787,5	,572871	,875407	,873313	799,368	138,925	11,6202	CRS
14:14:42,433	16905	,576896	,874531	,872429	805,02	139,908	11,5247	CRS
14:15:52,432	17022,5	,581421	,875159	,87306	810,65	141,013	11,5931	CRS
14:17:02,432	17139,8	,585542	,874554	,872454	816,291	142,019	11,5272	CRS
14:18:12,430	17257,3	,589343	,873699	,871596	821,953	142,947	11,4339	CRS
14:19:22,430	17374,8	,593409	,873226	,87111	827,606	143,94	11,3825	CRS
14:20:32,430	17492,2	,598077	,873792	,871689	833,224	145,079	11,4442	CRS
14:21:42,428	17609,7	,60336	,875045	,872954	838,822	146,369	11,5807	CRS
14:22:52,428	17727,2	,608949	,876983	,874871	844,407	147,734	11,7919	CRS
14:24:02,428	17844,6	,614009	,877883	,875754	850,014	148,969	11,89	CRS
14:25:12,427	17962	,618908	,878709	,876581	855,626	150,165	11,9801	CRS
14:26:22,427	18079,5	,624711	,880595	,878518	861,205	151,582	12,1857	CRS
14:27:32,425	18197	,630169	,882419	,880311	866,797	152,915	12,3845	CRS
14:28:42,425	18314,3	,635593	,883774	,881678	872,386	154,239	12,5321	CRS
14:29:52,425	18431,8	,64143	,885116	,883027	877,965	155,664	12,6784	CRS
14:31:02,424	18549,3	,646147	,885461	,88338	883,592	156,816	12,7161	CRS
14:32:12,424	18666,7	,651332	,886142	,884056	889,193	158,082	12,7903	CRS
14:33:22,423	18784,2	,655444	,885207	,883127	894,846	159,086	12,6884	CRS
14:34:32,423	18901,7	,659379	,884507	,882423	900,509	160,046	12,6121	CRS
14:35:42,422	19019	,663548	,884507	,882424	906,154	161,064	12,6121	CRS
14:36:52,421	19136,5	,667718	,884489	,882411	911,804	162,082	12,6101	CRS
14:38:02,420	19254	,671918	,884313	,882237	917,456	163,108	12,5909	CRS
14:39:12,420	19371,4	,676013	,884178	,882101	923,107	164,108	12,5762	CRS
14:40:22,419	19488,8	,68049	,884646	,882573	928,744	165,201	12,6272	CRS
14:41:32,419	19606,3	,685417	,885693	,883627	934,365	166,403	12,7414	CRS
14:42:42,417	19723,8	,690568	,887276	,88519	939,976	167,661	12,9139	CRS
14:43:52,417	19841,2	,695283	,887993	,885888	945,601	168,812	12,992	CRS
14:45:02,417	19958,7	,700093	,888596	,886488	951,229	169,987	13,0577	CRS
14:46:12,416	20076,2	,704523	,888791	,88668	956,872	171,068	13,0791	CRS
14:47:22,416	20193,5	,7091	,889337	,887229	962,503	172,186	13,1386	CRS
14:48:32,414	20311	,713037	,88855	,886447	968,167	173,147	13,0528	CRS
14:49:42,414	20428,5	,717631	,889351	,887258	973,805	174,269	13,14	CRS
14:50:52,414	20545,9	,723073	,891069	,889021	979,402	175,597	13,3274	CRS
14:52:02,413	20663,3	,727232	,89111	,889062	985,056	176,613	13,3318	CRS
14:53:12,413	20780,8	,731834	,89199	,889947	990,695	177,736	13,4277	CRS
14:54:22,412	20898,2	,735872	,891593	,889548	996,353	178,722	13,3844	CRS
14:55:32,411	21015,7	,739457	,89074	,888695	1002,03	179,597	13,2914	CRS
14:56:42,411	21133,2	,744153	,891823	,889781	1007,67	180,744	13,4095	CRS
14:57:52,410	21250,6	,748476	,892156	,890112	1013,32	181,799	13,4458	CRS
14:59:02,409	21368	,752887	,892948	,890903	1018,96	182,876	13,5321	CRS
15:00:12,409	21485,5	,757728	,894412	,892349	1024,59	184,058	13,6917	CRS
15:01:22,408	21603	,762054	,894331	,892279	1030,24	185,114	13,6829	CRS
15:02:32,408	21720,3	,766414	,894752	,892693	1035,88	186,179	13,7288	CRS
15:03:42,407	21837,8	,770279	,894242	,892188	1041,55	187,123	13,6732	CRS
15:04:52,407	21955,3	,774338	,894291	,892231	1047,22	188,114	13,6785	CRS
15:06:02,406	22072,7	,779241	,895194	,893127	1052,84	189,311	13,777	CRS
15:07:12,404	22190,2	,784145	,895962	,893894	1058,47	190,508	13,8606	CRS
15:08:22,405	22307,7	,789303	,89752	,895473	1064,09	191,767	14,0305	CRS
15:09:32,404	22425,1	,794148	,898205	,896169	1069,71	192,95	14,1052	CRS
15:10:42,403	22542,5	,797876	,897478	,895435	1075,39	193,86	14,0259	CRS
15:11:52,403	22660	,801784	,89751	,89547	1081,06	194,815	14,0294	CRS
15:13:02,401	22777,4	,806555	,898847	,896811	1086,69	195,979	14,1751	CRS
15:14:12,401	22894,8	,812553	,901383	,899407	1092,27	197,444	14,4516	CRS
15:15:22,401	23012,3	,819559	,905426	,90338	1097,82	199,154	14,8922	CRS
15:16:32,400	23129,8	,823991	,904644	,902638	1103,47	200,236	14,807	CRS
15:17:42,400	23247,2	,827815	,903901	,901994	1109,14	201,17	14,726	CRS
15:18:52,399	23364,7	,831776	,903544	,901673	1114,81	202,137	14,6871	CRS
15:20:02,398	23482,2	,83559	,903205	,901364	1120,49	203,068	14,6502	CRS
15:21:12,398	23599,5	,840002	,903456	,901601	1126,13	204,145	14,6776	CRS
15:22:22,397	23717	,844271	,903797	,901905	1131,79	205,188	14,7146	CRS
15:23:32,397	23834,5	,84852	,904355	,902392	1137,45	206,225	14,7754	CRS
15:24:42,396	23951,9	,852854	,904887	,902875	1143,1	207,283	14,8335	CRS
15:25:52,395	24069,3	,856221	,904161	,902223	1148,79	208,105	14,7543	CRS
15:27:02,395	24186,8	,860575	,904747	,902755	1154,45	209,168	14,8182	CRS
15:28:12,394	24304,3	,864025	,904064	,902144	1160,14	210,011	14,7438	CRS
15:29:22,393	24421,7	,867297	,903429	,901573	1165,83	210,81	14,6746	CRS
15:30:32,393	24539,2	,871262	,90345	,901598	1171,51	211,777	14,6768	CRS
15:31:42,392	24656,7	,875014	,903715	,901843	1177,19	212,694	14,7058	CRS
15:32:52,392	24774	,878925	,903945	,902047	1182,85	213,648	14,7308	CRS
15:34:02,391	24891,5	,882565	,903679	,901809	1188,54	214,537	14,7018	CRS
15:35:12,390	25009	,885621	,902682	,900844	1194,25	215,283	14,5931	CRS
15:36:22,390	25126,4	,889576	,903414	,901573	1199,92	216,249	14,6729	CRS
15:37:32,389	25243,8	,894308	,905493	,903471	1205,56	217,404	14,8996	CRS
15:38:42,388	25361,3	,898896	,906668	,904639	1211,2	218,524	15,0276	CRS
15:39:52,388	25478,7	,903601	,908366	,906361	1216,85	219,673	15,2127	CRS
15:41:02,387	25596,2	,908126	,909164	,907163	1222,49	220,778	15,2997	CRS
15:42:12,387	25713,7	,912393	,909649	,907647	1228,16	221,82	15,3525	CRS
15:43:22,386	25831,1	,915635	,908517	,906522	1233,86	222,611	15,2291	CRS
15:44:32,386	25948,5	,918928	,907771	,905761	1239,55	223,415	15,1478	CRS
15:45:42,385	26066	,924362	,910666	,908666	1245,17	224,742	15,4634	CRS
15:46:52,384	26183,5	,92988	,913246	,911244	1250,78	226,089	15,7446	CRS
15:48:02,384	26300,8	,933291	,912132	,910146	1256,47	226,922	15,6232	CRS
15:49:12,383	26418,3	,936846	,911714	,909734	1262,16	227,79	15,5777	CRS
15:50:22,382	26535,8	,94049	,911773	,909796	1267,85	228,68	15,5841	CRS
15:51:32,382	26653,2	,944624	,912442	,910457	1273,51	229,689	15,657	CRS
15:52:42,381	26770,7	,949821	,91455	,912534	1279,14	230,958	15,8867	CRS
15:53:52,381	26888,2	,953708	,914481	,912461	1284,82	231,907	15,8792	CRS
15:55:02,380	27005,6	,957448	,914174	,912161	1290,5	232,82	15,8458	CRS
15:56:12,379	27123	,960991	,913987	,911982	1296,19	233,685	15,8253	CRS
15:57:22,379	27240,5	,964948	,913943	,911938	1301,86	234,651	15,8206	CRS
15:58:32,378	27357,9	,968974	,914429	,912419	1307,53	235,634	15,8735	CRS
15:59:42,378	27475,3	,972979	,914807	,912797	1313,2	236,612	15,9148	CRS
16:00:52,377	27592,8	,977582	,915768	,913772	1318,86	237,736	16,0195	CRS
16:02:02,376	27710,3	,980646	,914088	,91208	1324,57	238,484	15,8364	CRS
16:03:12,376	27827,7	,984374	,914111	,912108	1330,25	239,394	15,8389	CRS
16:04:22,375	27945,2	,988229	,914255	,912252	1335,93	240,335	15,8546	CRS
16:05:32,374	28062,7	,990859	,912549	,910579	1341,66	240,977	15,6686	CRS
16:06:42,374	28180	,994886	,91346	,911472	1347,32	241,96	15,7679	CRS
16:07:52,373	28297,5	,999083	,914053	,91206	1352,99	242,985	15,8326	CRS
16:09:02,373	28415	1,00611	,918509	,916544	1358,55	244,7	16,3183	CRS
16:10:12,372	28532,4	1,01317	,922534	,920552	1364,1	246,424	16,7571	CRS
16:11:22,371	28649,8	1,01643	,920305	,918322	1369,81	247,219	16,514	CRS
16:12:32,371	28767,3	1,02021	,920174	,918194	1375,49	248,142	16,4998	CRS
16:13:42,370	28884,8	1,02383	,919716	,917747	1381,18	249,027	16,4498	CRS
16:14:52,370	29002,2	1,02718	,919668	,917706	1386,88	249,846	16,4446	CRS
16:16:02,369	29119,7	1,03198	,92097	,918977	1392,53	251,018	16,5865	CRS
16:17:12,368	29237,1	1,03626	,921453	,919462	1398,19	252,061	16,6392	CRS
16:18:22,368	29354,5	1,04024	,921809	,919819	1403,86	253,035	16,678	CRS
16:19:32,367	29472	1,04424	,922217	,920238	1409,54	254,01	16,7225	CRS
16:20:42,366	29589,5	1,04774	,921813	,919829	1415,24	254,864	16,6784	CRS
16:21:52,366	29706,9	1,05155	,921708	,919724	1420,92	255,794	16,667	CRS
16:23:02,365	29824,3	1,05524	,921687	,919706	1426,6	256,696	16,6647	CRS
16:24:12,365	29941,8	1,05822	,920785	,918803	1432,32	257,424	16,5663	CRS
16:25:22,364	30059,2	1,06181	,921134	,919148	1438,01	258,299	16,6044	CRS
16:26:32,363	30176,7	1,06573	,921776	,919798	1443,69	259,257	16,6743	CRS
16:27:42,363	30294,2	1,0695	,921665	,919685	1449,38	260,177	16,6623	CRS
16:28:52,362	30411,6	1,07336	,922017	,92004	1455,06	261,12	16,7007	CRS
16:30:02,362	30529	1,07867	,924545	,922585	1460,68	262,417	16,9762	CRS
16:31:12,361	30646,5	1,08316	,925436	,923476	1466,34	263,512	17,0733	CRS
16:32:22,360	30764	1,08766	,926753	,924802	1472	264,612	17,2169	CRS
16:33:32,360	30881,3	1,09302	,9291	,927159	1477,62	265,919	17,4727	CRS
16:34:42,359	30998,8	1,09986	,933261	,931317	1483,2	267,59	17,9262	CRS
16:35:52,358	31116,3	1,10454	,933194	,931247	1488,85	268,732	17,9189	CRS
16:37:02,358	31233,7	1,1098	,934435	,9325	1494,48	270,016	18,0542	CRS
16:38:12,357	31351,2	1,11335	,933045	,931098	1500,17	270,883	17,9027	CRS
16:39:22,357	31468,7	1,11646	,93151	,929542	1505,89	271,644	17,7354	CRS
16:40:32,356	31586	1,12035	,931225	,929259	1511,57	272,593	17,7043	CRS
16:41:42,355	31703,5	1,1242	,931138	,929178	1517,25	273,531	17,6948	CRS
16:42:52,355	31821	1,12892	,932467	,930515	1522,91	274,686	17,8397	CRS
16:44:02,354	31938,4	1,13305	,932916	,930967	1528,58	275,693	17,8887	CRS
16:45:12,354	32055,8	1,13621	,931399	,929437	1534,29	276,466	17,7233	CRS
16:46:22,353	32173,3	1,13957	,930704	,92876	1539,99	277,284	17,6476	CRS
16:47:32,352	32290,8	1,14387	,931738	,929775	1545,66	278,334	17,7603	CRS
16:48:42,352	32408,2	1,14736	,931409	,929449	1551,35	279,186	17,7244	CRS
16:49:52,351	32525,7	1,15072	,930642	,928705	1557,06	280,007	17,6408	CRS
16:51:02,351	32643,2	1,15431	,930766	,92882	1562,76	280,885	17,6543	CRS
16:52:12,350	32760,5	1,15776	,93036	,928435	1568,45	281,726	17,6101	CRS
16:53:22,349	32878	1,16137	,929877	,927955	1574,15	282,608	17,5574	CRS
16:54:32,349	32995,5	1,16548	,930109	,928188	1579,83	283,612	17,5827	CRS
16:55:42,348	33112,9	1,16939	,929596	,92768	1585,51	284,565	17,5267	CRS
16:56:52,347	33230,3	1,17316	,929844	,927923	1591,19	285,485	17,5538	CRS
16:58:02,347	33347,8	1,17662	,929435	,92752	1596,9	286,331	17,5092	CRS
16:59:12,346	33465,2	1,17998	,928942	,927033	1602,6	287,151	17,4555	CRS
17:00:22,346	33582,7	1,18389	,929306	,927392	1608,28	288,107	17,4951	CRS
17:01:32,345	33700,2	1,1893	,931968	,930023	1613,91	289,427	17,7854	CRS
17:02:42,344	33817,7	1,19401	,932818	,930893	1619,57	290,575	17,8779	CRS
17:03:52,344	33935	1,19887	,933919	,932023	1625,21	291,763	17,998	CRS
17:05:02,343	34052,5	1,20449	,936302	,934395	1630,83	293,135	18,2578	CRS
17:06:12,343	34170	1,21121	,939632	,937716	1636,42	294,776	18,6207	CRS
17:07:22,342	34287,3	1,21852	,943673	,941766	1641,97	296,56	19,0611	CRS
17:08:32,341	34404,8	1,22367	,943387	,941482	1647,61	297,819	19,03	CRS
17:09:42,341	34522,3	1,22904	,94429	,942364	1653,25	299,13	19,1284	CRS
17:10:52,340	34639,7	1,23495	,945351	,94339	1658,86	300,572	19,244	CRS
17:12:02,339	34757,2	1,23918	,944639	,942699	1664,53	301,605	19,1664	CRS
17:13:12,339	34874,7	1,24372	,944639	,942701	1670,2	302,714	19,1665	CRS
17:14:22,338	34992,1	1,24779	,943869	,941958	1675,87	303,706	19,0826	CRS
17:15:32,338	35109,5	1,25178	,943167	,941273	1681,55	304,681	19,006	CRS
17:16:42,337	35227	1,25578	,942685	,940795	1687,24	305,658	18,9535	CRS
17:17:52,336	35344,5	1,2595	,942104	,940209	1692,93	306,566	18,8901	CRS
17:19:02,336	35461,8	1,2631	,941332	,939439	1698,63	307,446	18,806	CRS
17:20:12,335	35579,3	1,26717	,941519	,93963	1704,31	308,439	18,8264	CRS
17:21:22,335	35696,8	1,27122	,942035	,940138	1709,99	309,428	18,8826	CRS
17:22:32,334	35814,2	1,27531	,942154	,940262	1715,67	310,425	18,8956	CRS
17:23:42,333	35931,7	1,27964	,942247	,940358	1721,34	311,484	18,9057	CRS
17:24:52,333	36049,2	1,28399	,94265	,940764	1727,01	312,545	18,9496	CRS
17:26:02,332	36166,5	1,28849	,943317	,941445	1732,67	313,643	19,0223	CRS
17:27:12,332	36284	1,29278	,94372	,941833	1738,35	314,691	19,0662	CRS
17:28:22,331	36401,5	1,29824	,946035	,944097	1743,98	316,025	19,3186	CRS
17:29:32,330	36518,9	1,30429	,948153	,946259	1749,59	317,501	19,5495	CRS
17:30:42,330	36636,3	1,3099	,949385	,94748	1755,21	318,87	19,6838	CRS
17:31:52,329	36753,8	1,31578	,950937	,949059	1760,83	320,306	19,8529	CRS
17:33:02,329	36871,3	1,31943	,949169	,947266	1766,53	321,199	19,6602	CRS
17:34:12,328	36988,7	1,32317	,947828	,945942	1772,22	322,11	19,5141	CRS
17:35:22,327	37106,2	1,32774	,947834	,945943	1777,88	323,226	19,5147	CRS
17:36:32,327	37223,7	1,33237	,948148	,946259	1783,55	324,357	19,549	CRS
17:37:42,326	37341	1,33734	,948862	,946972	1789,19	325,569	19,6267	CRS
17:38:52,326	37458,5	1,34237	,949596	,947713	1794,84	326,799	19,7067	CRS
17:40:02,325	37576	1,34671	,949072	,947186	1800,52	327,859	19,6497	CRS
17:41:12,324	37693,4	1,35161	,949738	,94785	1806,17	329,055	19,7222	CRS
17:42:22,324	37810,8	1,35535	,948318	,946433	1811,86	329,967	19,5674	CRS
17:43:32,323	37928,3	1,35893	,947215	,945339	1817,57	330,841	19,4472	CRS
17:44:42,323	38045,8	1,36316	,947015	,945134	1823,24	331,876	19,4255	CRS
17:45:52,322	38163,2	1,36802	,947878	,946005	1828,89	333,062	19,5195	CRS
17:47:02,321	38280,7	1,37445	,950395	,948532	1834,5	334,632	19,7938	CRS
17:48:12,321	38398,1	1,37946	,950134	,94827	1840,15	335,855	19,7655	CRS
17:49:22,320	38515,5	1,38425	,94943	,947547	1845,8	337,023	19,6886	CRS
17:50:32,320	38633	1,38949	,949798	,947928	1851,45	338,302	19,7288	CRS
17:51:42,319	38750,5	1,39483	,950221	,948365	1857,09	339,607	19,7749	CRS
17:52:52,318	38867,8	1,40288	,954567	,95272	1862,62	341,573	20,2486	CRS
17:54:02,318	38985,3	1,41283	,960794	,958963	1868,1	344,001	20,9273	CRS
17:55:12,317	39102,8	1,42107	,963409	,961533	1873,64	346,014	21,2123	CRS
17:56:22,316	39220,2	1,42586	,961055	,959214	1879,3	347,182	20,9558	CRS
17:57:32,316	39337,7	1,42989	,958711	,956884	1884,98	348,166	20,7003	CRS
17:58:42,315	39455,2	1,43413	,957336	,955485	1890,66	349,201	20,5504	CRS
17:59:52,315	39572,6	1,43924	,957141	,955289	1896,31	350,45	20,5292	CRS
18:01:02,314	39690	1,44405	,956994	,955143	1901,97	351,624	20,5132	CRS
18:02:12,313	39807,5	1,44946	,957786	,955952	1907,61	352,946	20,5995	CRS
18:03:22,314	39925	1,45452	,957652	,955813	1913,26	354,179	20,5849	CRS
18:04:32,312	40042,3	1,45935	,957461	,955621	1918,91	355,358	20,5641	CRS
18:05:42,312	40159,8	1,46493	,958428	,956604	1924,55	356,722	20,6695	CRS
18:06:52,311	40277,3	1,46968	,957872	,956045	1930,21	357,881	20,6089	CRS
18:08:02,310	40394,7	1,4745	,957744	,955912	1935,87	359,059	20,5949	CRS
18:09:12,310	40512,2	1,47916	,957586	,955754	1941,53	360,196	20,5777	CRS
18:10:22,309	40629,7	1,48397	,957557	,95573	1947,2	361,371	20,5745	CRS
18:11:32,309	40747	1,48966	,958578	,95677	1952,82	362,76	20,6858	CRS
18:12:42,308	40864,5	1,49483	,958368	,956557	1958,47	364,023	20,6629	CRS
18:13:52,307	40982	1,49907	,957189	,955367	1964,15	365,056	20,5344	CRS
18:15:02,308	41099,4	1,50445	,957841	,95603	1969,79	366,37	20,6055	CRS
18:16:12,307	41216,8	1,51034	,958922	,957124	1975,42	367,807	20,7233	CRS
18:17:22,306	41334,3	1,5159	,959236	,957442	1981,05	369,167	20,7576	CRS
18:18:32,305	41451,8	1,52176	,959788	,957993	1986,68	370,596	20,8177	CRS
18:19:42,305	41569,2	1,52724	,959807	,958016	1992,31	371,934	20,8197	CRS
18:20:52,304	41686,7	1,53353	,961208	,959411	1997,92	373,471	20,9725	CRS
18:22:02,304	41804,1	1,53876	,960815	,959017	2003,57	374,748	20,9297	CRS
18:23:12,303	41921,5	1,54361	,96012	,958332	2009,23	375,932	20,8539	CRS
18:24:22,303	42039	1,55079	,963172	,961351	2014,81	377,685	21,1866	CRS
18:25:32,302	42156,5	1,55909	,967707	,965912	2020,35	379,712	21,6809	CRS
18:26:42,301	42273,9	1,56584	,968511	,966719	2025,95	381,36	21,7685	CRS
18:27:52,300	42391,3	1,57123	,967603	,965811	2031,59	382,674	21,6695	CRS
18:29:02,300	42508,8	1,57665	,967089	,965308	2037,23	383,998	21,6135	CRS
18:30:12,300	42626,2	1,58247	,966898	,965114	2042,86	385,419	21,5927	CRS
18:31:22,299	42743,7	1,58915	,967974	,966191	2048,46	387,05	21,71	CRS
18:32:32,298	42861,2	1,59476	,96733	,965549	2054,09	388,42	21,6398	CRS
18:33:42,298	42978,6	1,59964	,965566	,963796	2059,75	389,611	21,4475	CRS
18:34:52,296	43096	1,60501	,965045	,963277	2065,4	390,923	21,3907	CRS
18:36:02,296	43213,5	1,6103	,964353	,962569	2071,05	392,214	21,3152	CRS
18:37:12,296	43331	1,61594	,964221	,962426	2076,68	393,591	21,3009	CRS
18:38:22,295	43448,3	1,62226	,964957	,963193	2082,29	395,135	21,3811	CRS
18:39:32,294	43565,8	1,62891	,965684	,963934	2087,89	396,757	21,4604	CRS
18:40:42,294	43683,3	1,63396	,964449	,962675	2093,55	397,99	21,3258	CRS
18:41:52,293	43800,7	1,64009	,964961	,963201	2099,17	399,487	21,3815	CRS
18:43:02,292	43918,2	1,64592	,96503	,963269	2104,8	400,91	21,3891	CRS
18:44:12,292	44035,7	1,6521	,965234	,963482	2110,42	402,419	21,4113	CRS
18:45:22,292	44153,1	1,65823	,965606	,963864	2116,03	403,916	21,4518	CRS
18:46:32,290	44270,5	1,66542	,966727	,96498	2121,62	405,671	21,5741	CRS
18:47:42,290	44388	1,67635	,973087	,971321	2127,08	408,341	22,2673	CRS
18:48:52,290	44505,4	1,68606	,975788	,974031	2132,58	410,711	22,5616	CRS
18:50:02,289	44622,8	1,69258	,974413	,972647	2138,18	412,303	22,4118	CRS
18:51:12,288	44740,3	1,69917	,973704	,971933	2143,79	413,911	22,3345	CRS
18:52:22,288	44857,8	1,70425	,971085	,96935	2149,45	415,151	22,0491	CRS
18:53:32,287	44975,2	1,71034	,970655	,968922	2155,06	416,638	22,0022	CRS
18:54:42,286	45092,7	1,71711	,971301	,969571	2160,67	418,291	22,0727	CRS
18:55:52,286	45210,2	1,72329	,971076	,969346	2166,29	419,801	22,0481	CRS
18:57:02,286	45327,5	1,73132	,973906	,972149	2171,84	421,76	22,3566	CRS
18:58:12,284	45445	1,73737	,973632	,971877	2177,47	423,239	22,3266	CRS
18:59:22,284	45562,5	1,74376	,973666	,971914	2183,09	424,798	22,3304	CRS
19:00:32,284	45679,9	1,751	,974752	,97301	2188,67	426,566	22,4488	CRS
19:01:42,282	45797,3	1,75777	,975229	,973496	2194,27	428,219	22,5008	CRS
19:02:52,282	45914,8	1,76399	,974507	,972766	2199,89	429,737	22,4221	CRS
19:04:02,282	46032,3	1,77075	,974941	,973204	2205,49	431,388	22,4694	CRS
19:05:12,281	46149,7	1,77733	,975102	,973371	2211,1	432,995	22,4869	CRS
19:06:22,280	46267,2	1,78342	,974213	,972474	2216,72	434,482	22,39	CRS
19:07:32,280	46384,7	1,79016	,974419	,972681	2222,33	436,128	22,4125	CRS
19:08:42,280	46502	1,79742	,975359	,97364	2227,91	437,899	22,5149	CRS
19:09:52,278	46619,5	1,80524	,976727	,975016	2233,48	439,809	22,664	CRS
19:11:02,278	46737	1,81352	,979022	,97724	2239,04	441,829	22,9142	CRS
19:12:12,278	46854,4	1,82172	,980656	,978917	2244,59	443,831	23,0923	CRS
19:13:22,276	46971,8	1,8309	,983226	,981534	2250,11	446,074	23,3724	CRS
19:14:32,276	47089,3	1,83847	,983249	,981557	2255,69	447,922	23,3749	CRS
19:15:42,276	47206,8	1,84649	,984083	,982388	2261,25	449,88	23,4658	CRS
19:16:52,275	47324,2	1,85352	,983552	,981859	2266,85	451,597	23,4079	CRS
19:18:02,274	47441,7	1,86077	,983173	,981496	2272,44	453,365	23,3667	CRS
19:19:12,274	47559,1	1,86841	,983694	,982009	2278,01	455,232	23,4234	CRS
19:20:22,274	47676,5	1,87623	,984196	,982515	2283,58	457,14	23,4782	CRS
19:21:32,272	47794	1,88477	,9863	,984631	2289,13	459,226	23,7075	CRS
19:22:42,272	47911,5	1,89245	,986555	,98489	2294,71	461,101	23,7353	CRS
19:23:52,272	48028,8	1,8996	,985929	,984271	2300,3	462,846	23,667	CRS
19:25:02,270	48146,3	1,90613	,984461	,982794	2305,91	464,442	23,5071	CRS
19:26:12,270	48263,8	1,91227	,982896	,981245	2311,54	465,94	23,3365	CRS
19:27:22,270	48381,2	1,91962	,983123	,981474	2317,12	467,734	23,3612	CRS
19:28:32,269	48498,7	1,92511	,980053	,978302	2322,78	469,074	23,0266	CRS
19:29:42,268	48616,2	1,93036	,977012	,97536	2328,43	470,358	22,6952	CRS
19:30:52,268	48733,6	1,9365	,975274	,973607	2334,06	471,856	22,5056	CRS
19:32:02,267	48851	1,94429	,976819	,975164	2339,63	473,758	22,674	CRS
19:33:12,266	48968,5	1,95228	,978111	,976432	2345,2	475,709	22,8149	CRS
19:34:22,266	49085,9	1,96054	,979343	,977607	2350,76	477,724	22,9492	CRS
19:35:32,266	49203,3	1,9672	,978013	,976338	2356,37	479,351	22,8042	CRS
19:36:42,265	49320,8	1,97495	,978204	,976529	2361,95	481,242	22,8251	CRS
19:37:52,264	49438,3	1,98258	,9785	,976803	2367,53	483,105	22,8573	CRS
19:39:02,264	49555,7	1,99068	,979638	,977902	2373,09	485,084	22,9813	CRS
19:40:12,262	49673,2	2,00005	,982129	,980553	2378,61	487,371	23,2528	CRS
19:41:22,262	49790,7	2,00894	,983263	,981629	2384,16	489,543	23,3765	CRS
19:42:32,262	49908	2,01805	,984687	,983071	2389,69	491,765	23,5316	CRS
19:43:42,261	50025,5	2,02712	,985913	,9843	2395,22	493,981	23,6653	CRS
19:44:52,260	50143	2,03654	,987397	,985782	2400,75	496,281	23,827	CRS
19:46:02,260	50260,4	2,04865	,99238	,990733	2406,18	499,237	24,3702	CRS
19:47:12,258	50377,8	2,0582	,993156	,991509	2411,7	501,567	24,4548	CRS
19:48:22,258	50495,3	2,06892	,995655	,994046	2417,19	504,185	24,7272	CRS
19:49:32,258	50612,8	2,07928	,996861	,995248	2422,68	506,715	24,8587	CRS
19:50:42,257	50730,2	2,08857	,997088	,995484	2428,21	508,983	24,8834	CRS
19:51:52,257	50847,7	2,09714	,996569	,99497	2433,77	511,075	24,8269	CRS
19:53:02,256	50965,1	2,10507	,995287	,993687	2439,34	513,012	24,687	CRS
19:54:12,256	51082,5	2,11314	,994881	,993282	2444,91	514,983	24,6428	CRS
19:55:22,254	51200	2,12183	,99519	,9936	2450,46	517,103	24,6765	CRS
19:56:32,254	51317,5	2,13002	,994472	,992867	2456,03	519,103	24,5983	CRS
19:57:42,254	51434,9	2,1389	,995175	,993585	2461,57	521,271	24,6749	CRS
19:58:52,253	51552,3	2,14683	,994205	,992605	2467,14	523,208	24,5691	CRS
20:00:02,253	51669,8	2,15632	,995749	,994162	2472,67	525,524	24,7374	CRS
20:01:12,252	51787,2	2,16557	,996494	,994918	2478,2	527,784	24,8186	CRS
20:02:22,251	51904,7	2,17473	,997081	,995502	2483,74	530,019	24,8826	CRS
20:03:32,251	52022,2	2,18409	,997962	,996375	2489,27	532,305	24,9786	CRS
20:04:42,250	52139,6	2,19296	,997628	,996047	2494,82	534,471	24,9423	CRS
20:05:52,249	52257	2,20152	,997703	,996126	2500,38	536,561	24,9504	CRS
20:07:02,249	52374,5	2,21141	,999296	,997699	2505,89	538,974	25,1241	CRS
20:08:12,248	52492	2,22068	,999309	,997718	2511,43	541,239	25,1255	CRS
20:09:22,248	52609,3	2,23011	,999961	,998393	2516,95	543,541	25,1965	CRS
20:10:32,246	52726,8	2,23917	,999834	,998261	2522,5	545,753	25,1827	CRS
20:11:42,246	52844,3	2,24758	,998688	,99711	2528,06	547,806	25,0578	CRS
20:12:52,246	52961,7	2,25694	,999204	,99763	2533,59	550,091	25,114	CRS
20:14:02,245	53079,2	2,26612	,999113	,997536	2539,13	552,332	25,1041	CRS
20:15:12,244	53196,7	2,27682	1,00169	1,00016	2544,63	554,944	25,3849	CRS
20:16:22,244	53314	2,28706	1,00254	1,001	2550,13	557,446	25,4772	CRS
20:17:32,243	53431,5	2,2971	1,00328	1,00174	2555,65	559,897	25,5585	CRS
20:18:42,243	53549	2,30638	1,0025	1,00097	2561,19	562,162	25,4732	CRS
20:19:52,242	53666,4	2,31621	1,00285	1,00132	2566,71	564,561	25,5116	CRS
20:21:02,241	53783,8	2,32497	1,00165	1,00013	2572,26	566,699	25,3808	CRS
20:22:12,241	53901,3	2,33328	1,00034	,998802	2577,83	568,73	25,2373	CRS
20:23:22,240	54018,8	2,34126	,998352	,996814	2583,41	570,677	25,0212	CRS
20:24:32,239	54136,2	2,35063	,998828	,997288	2588,94	572,965	25,0731	CRS
20:25:42,239	54253,7	2,36201	1,00144	,99994	2594,42	575,745	25,3581	CRS
20:26:52,238	54371,2	2,37294	1,00294	1,00143	2599,91	578,411	25,5215	CRS
20:28:02,238	54488,5	2,38264	1,00267	1,00117	2605,43	580,78	25,4919	CRS
20:29:12,237	54606	2,39242	1,00252	1,00103	2610,96	583,169	25,4756	CRS
20:30:22,236	54723,5	2,40254	1,00315	1,00165	2616,47	585,64	25,5439	CRS
20:31:32,236	54840,9	2,41447	1,00625	1,00474	2621,93	588,551	25,8823	CRS
20:32:42,235	54958,3	2,42844	1,01145	1,00996	2627,32	591,962	26,4491	CRS
20:33:52,234	55075,8	2,44313	1,01628	1,01477	2632,7	595,548	26,9756	CRS
20:35:02,234	55193,2	2,45637	1,01868	1,01719	2638,12	598,782	27,2365	CRS
20:36:12,233	55310,7	2,46714	1,01712	1,01562	2643,62	601,412	27,0672	CRS
20:37:22,232	55428,2	2,4778	1,01655	1,01506	2649,12	604,013	27,0049	CRS
20:38:32,232	55545,6	2,48847	1,0158	1,0143	2654,62	606,618	26,923	CRS
20:39:42,231	55663	2,49798	1,01396	1,01249	2660,15	608,94	26,7229	CRS
20:40:52,231	55780,5	2,50876	1,01406	1,01259	2665,65	611,572	26,7337	CRS
20:42:02,230	55898	2,5185	1,01295	1,01149	2671,18	613,951	26,6124	CRS
20:43:12,230	56015,3	2,52864	1,01247	1,01102	2676,7	616,427	26,5601	CRS
20:44:22,229	56132,8	2,53957	1,01297	1,01153	2682,19	619,094	26,6151	CRS
20:45:32,228	56250,3	2,54966	1,01227	1,01082	2687,71	621,559	26,5378	CRS
20:46:42,228	56367,7	2,56096	1,01362	1,01217	2693,2	624,316	26,685	CRS
20:47:52,227	56485,2	2,57099	1,01317	1,01173	2698,72	626,767	26,6368	CRS
20:49:02,226	56602,7	2,58212	1,0142	1,01277	2704,21	629,483	26,749	CRS
20:50:12,226	56720,1	2,59392	1,01618	1,01472	2709,68	632,365	26,964	CRS
20:51:22,225	56837,5	2,60448	1,01543	1,01399	2715,18	634,944	26,8828	CRS
20:52:32,225	56955	2,61563	1,01619	1,01474	2720,67	637,666	26,9653	CRS
20:53:42,224	57072,4	2,62678	1,01601	1,01458	2726,16	640,388	26,9463	CRS
20:54:52,223	57189,8	2,63809	1,01631	1,01487	2731,65	643,148	26,9787	CRS
20:56:02,223	57307,3	2,64987	1,01733	1,0159	2737,12	646,025	27,0901	CRS
20:57:12,222	57424,8	2,6616	1,01767	1,01625	2742,6	648,89	27,1269	CRS
20:58:22,221	57542,2	2,67318	1,01797	1,01656	2748,07	651,717	27,1594	CRS
20:59:32,220	57659,7	2,68479	1,01821	1,01681	2753,55	654,551	27,1862	CRS
21:00:42,220	57777,2	2,6956	1,01725	1,01584	2759,06	657,19	27,0812	CRS
21:01:52,220	57894,6	2,70717	1,01772	1,01632	2764,53	660,015	27,132	CRS
21:03:02,219	58012	2,72046	1,02104	1,01964	2769,96	663,259	27,4938	CRS
21:04:12,218	58129,5	2,73578	1,02709	1,02571	2775,33	667,001	28,1538	CRS
21:05:22,218	58246,9	2,74898	1,02825	1,02684	2780,76	670,222	28,2801	CRS
21:06:32,217	58364,3	2,76068	1,02722	1,02583	2786,24	673,078	28,1678	CRS
21:07:42,216	58481,8	2,77363	1,0285	1,0271	2791,68	676,241	28,3068	CRS
21:08:52,216	58599,3	2,78579	1,02833	1,02694	2797,15	679,209	28,2887	CRS
21:10:02,215	58716,7	2,79923	1,02992	1,02851	2802,57	682,49	28,4619	CRS
21:11:12,215	58834,2	2,81282	1,03164	1,03027	2808	685,808	28,6498	CRS
21:12:22,214	58951,7	2,82394	1,02921	1,02781	2813,5	688,524	28,3851	CRS
21:13:32,213	59069	2,83619	1,02912	1,02772	2818,95	691,515	28,3748	CRS
21:14:42,213	59186,5	2,84758	1,02721	1,02588	2824,45	694,296	28,1672	CRS
21:15:52,212	59304	2,8589	1,02583	1,02449	2829,94	697,059	28,0166	CRS
21:17:02,211	59421,4	2,87065	1,02497	1,02362	2835,42	699,928	27,9227	CRS
21:18:12,211	59538,8	2,88323	1,02551	1,02416	2840,87	702,999	27,9811	CRS
21:19:22,210	59656,3	2,89469	1,02412	1,02277	2846,36	705,799	27,83	CRS
21:20:32,210	59773,8	2,90679	1,02405	1,02271	2851,83	708,751	27,8223	CRS
21:21:42,209	59891,2	2,91807	1,02215	1,02084	2857,33	711,506	27,6156	CRS
21:22:52,208	60008,7	2,93109	1,02366	1,02233	2862,77	714,686	27,7802	CRS
21:24:02,208	60126,1	2,9428	1,02269	1,02137	2868,26	717,544	27,6736	CRS
21:25:12,207	60243,5	2,95523	1,02302	1,0217	2873,72	720,578	27,71	CRS
21:26:22,206	60361	2,97228	1,02987	1,02853	2879,05	724,742	28,4566	CRS
21:27:32,206	60478,5	2,98654	1,031	1,02969	2884,46	728,222	28,5796	CRS
21:28:42,205	60595,8	3,00243	1,03453	1,03321	2889,81	732,101	28,9648	CRS
21:29:52,205	60713,3	3,01698	1,03567	1,03437	2895,22	735,654	29,0888	CRS
21:31:02,204	60830,8	3,02904	1,03312	1,03183	2900,7	738,599	28,8107	CRS
21:32:12,203	60948,2	3,0428	1,03379	1,03249	2906,12	741,958	28,8835	CRS
21:33:22,203	61065,7	3,05587	1,03294	1,03166	2911,57	745,15	28,7915	CRS
21:34:32,202	61183,2	3,06907	1,03283	1,03155	2917,01	748,372	28,7789	CRS
21:35:42,202	61300,6	3,08377	1,03486	1,03358	2922,41	751,961	29,0001	CRS
21:36:52,201	61418	3,09703	1,03428	1,03299	2927,85	755,2	28,937	CRS
21:38:02,200	61535,5	3,11061	1,03412	1,03285	2933,29	758,513	28,9203	CRS
21:39:12,200	61653	3,1251	1,03546	1,03419	2938,69	762,052	29,0655	CRS
21:40:22,199	61770,3	3,13876	1,03512	1,03385	2944,12	765,387	29,0284	CRS
21:41:32,198	61887,8	3,15357	1,03669	1,03546	2949,52	769,002	29,2005	CRS
21:42:42,198	62005,3	3,16773	1,03734	1,03611	2954,94	772,461	29,2709	CRS
21:43:52,197	62122,7	3,18184	1,03735	1,03612	2960,36	775,905	29,2718	CRS
21:45:02,197	62240,2	3,19648	1,03846	1,03724	2965,77	779,48	29,3927	CRS
21:46:12,196	62357,7	3,21163	1,0397	1,03847	2971,16	783,179	29,5282	CRS
21:47:22,195	62475	3,22732	1,04191	1,04068	2976,53	787,009	29,7689	CRS
21:48:32,195	62592,5	3,24375	1,04432	1,04312	2981,89	791,021	30,0316	CRS
21:49:42,194	62710	3,25943	1,04542	1,04421	2987,27	794,849	30,1513	CRS
21:50:52,193	62827,4	3,2753	1,04698	1,04576	2992,64	798,724	30,3219	CRS
21:52:02,193	62944,8	3,29256	1,05019	1,049	2997,97	802,938	30,6714	CRS
21:53:12,192	63062,3	3,30792	1,05007	1,04888	3003,36	806,688	30,658	CRS
21:54:22,192	63179,8	3,32303	1,04961	1,04843	3008,76	810,377	30,6088	CRS
21:55:32,191	63297,2	3,33779	1,04921	1,04802	3014,16	813,98	30,5644	CRS
21:56:42,190	63414,7	3,35275	1,04915	1,04798	3019,57	817,633	30,5584	CRS
21:57:52,190	63532,1	3,36712	1,04803	1,04684	3024,99	821,142	30,4361	CRS
21:59:02,189	63649,5	3,38213	1,04817	1,047	3030,38	824,807	30,4516	CRS
22:00:12,188	63767	3,39827	1,04959	1,04844	3035,76	828,747	30,6061	CRS
22:01:22,188	63884,5	3,41388	1,05006	1,04891	3041,14	832,558	30,657	CRS
22:02:32,187	64001,9	3,43024	1,05154	1,05038	3046,5	836,551	30,8181	CRS
22:03:42,187	64119,3	3,44455	1,04953	1,04839	3051,93	840,045	30,5994	CRS
22:04:52,186	64236,8	3,45906	1,04807	1,04692	3057,35	843,589	30,4402	CRS
22:06:02,185	64354,2	3,47493	1,04903	1,0479	3062,72	847,464	30,5452	CRS
22:07:12,185	64471,7	3,48811	1,04577	1,04463	3068,18	850,681	30,1892	CRS
22:08:22,184	64589,2	3,50171	1,04368	1,04257	3073,63	854	29,9622	CRS
22:09:32,183	64706,6	3,51596	1,04264	1,04152	3079,05	857,481	29,848	CRS
22:10:42,183	64824	3,52992	1,04131	1,04019	3084,48	860,888	29,7033	CRS
22:11:52,182	64941,5	3,54502	1,04146	1,04034	3089,89	864,575	29,7195	CRS
22:13:02,181	65059	3,56006	1,04127	1,04015	3095,3	868,247	29,6991	CRS
22:14:12,181	65176,3	3,57427	1,03992	1,03883	3100,72	871,716	29,5524	CRS
22:15:22,180	65293,8	3,5893	1,03984	1,03875	3106,13	875,385	29,5431	CRS
22:16:32,180	65411,3	3,60348	1,03879	1,03771	3111,56	878,848	29,429	CRS
22:17:42,179	65528,7	3,61982	1,04068	1,03958	3116,93	882,839	29,6344	CRS
22:18:52,178	65646,2	3,63697	1,04351	1,04245	3122,28	887,024	29,9433	CRS
22:20:02,178	65763,7	3,65416	1,04574	1,04467	3127,63	891,221	30,1862	CRS
22:21:12,177	65881,1	3,67238	1,04854	1,04748	3132,95	895,67	30,4919	CRS
22:22:22,176	65998,5	3,69035	1,05062	1,04957	3138,28	900,058	30,718	CRS
22:23:32,176	66116	3,70926	1,05427	1,05322	3143,58	904,674	31,1159	CRS
22:24:42,175	66233,4	3,72849	1,05706	1,05599	3148,87	909,369	31,4202	CRS
22:25:52,175	66350,8	3,7467	1,05824	1,05718	3154,19	913,817	31,5491	CRS
22:27:02,174	66468,3	3,76469	1,05946	1,05841	3159,53	918,207	31,6817	CRS
22:28:12,173	66585,8	3,78209	1,05929	1,05824	3164,87	922,456	31,663	CRS
22:29:22,173	66703,2	3,79979	1,06006	1,05904	3170,21	926,779	31,7476	CRS
22:30:32,172	66820,7	3,81801	1,06108	1,06007	3175,54	931,227	31,8584	CRS
22:31:42,171	66938,2	3,83481	1,06033	1,05933	3180,9	935,329	31,7771	CRS
22:32:52,171	67055,5	3,85226	1,06069	1,05968	3186,25	939,588	31,8155	CRS
22:34:02,170	67173	3,86975	1,06077	1,05977	3191,59	943,858	31,8245	CRS
22:35:12,170	67290,5	3,88703	1,06036	1,05938	3196,95	948,078	31,7801	CRS
22:36:22,170	67407,9	3,90496	1,06143	1,06044	3202,28	952,456	31,8962	CRS
22:37:32,168	67525,3	3,92307	1,06235	1,06136	3207,61	956,877	31,9974	CRS
22:38:42,168	67642,8	3,94062	1,06251	1,06154	3212,96	961,161	32,0146	CRS
22:39:52,167	67760,2	3,96024	1,06523	1,06425	3218,25	965,952	32,3109	CRS
22:41:02,166	67877,7	3,97793	1,06447	1,06352	3223,6	970,271	32,2283	CRS
22:42:12,166	67995,2	3,99777	1,06728	1,06631	3228,88	975,115	32,5339	CRS
22:43:22,165	68112,7	4,01552	1,06613	1,06516	3234,23	979,448	32,4087	CRS
22:44:32,165	68230	4,03379	1,06634	1,06539	3239,56	983,909	32,4321	CRS
22:45:42,164	68347,5	4,05371	1,06862	1,06769	3244,84	988,772	32,6801	CRS
22:46:52,163	68465	4,07288	1,06895	1,06802	3250,15	993,452	32,7162	CRS
22:48:02,163	68582,3	4,09261	1,07097	1,07006	3255,44	998,271	32,9369	CRS
22:49:12,162	68699,8	4,11108	1,07011	1,0692	3260,77	1002,78	32,8424	CRS
22:50:22,161	68817,3	4,13017	1,07066	1,06975	3266,08	1007,44	32,9029	CRS
22:51:32,162	68934,7	4,14994	1,07191	1,07101	3271,38	1012,27	33,0392	CRS
22:52:42,160	69052,2	4,16809	1,07015	1,06925	3276,71	1016,7	32,8467	CRS
22:53:52,160	69169,7	4,18815	1,07208	1,07119	3282	1021,59	33,0574	CRS
22:55:02,160	69287,1	4,20817	1,0733	1,07242	3287,29	1026,48	33,1905	CRS
22:56:12,158	69404,5	4,22785	1,07407	1,07319	3292,59	1031,29	33,2744	CRS
22:57:22,158	69522	4,24809	1,07526	1,07438	3297,87	1036,23	33,4046	CRS
22:58:32,157	69639,5	4,26689	1,07451	1,07365	3303,2	1040,82	33,3223	CRS
22:59:42,156	69756,8	4,28608	1,07434	1,07349	3308,51	1045,51	33,3044	CRS
23:00:52,156	69874,3	4,30532	1,07394	1,07309	3313,82	1050,2	33,2603	CRS
23:02:02,155	69991,8	4,32344	1,07198	1,07113	3319,17	1054,63	33,0466	CRS
23:03:12,154	70109,2	4,34276	1,07226	1,07142	3324,47	1059,34	33,0774	CRS
23:04:22,154	70226,7	4,36298	1,07352	1,07269	3329,76	1064,28	33,2148	CRS
23:05:32,154	70344,2	4,38248	1,07324	1,07243	3335,07	1069,04	33,1842	CRS
23:06:42,153	70461,6	4,40096	1,07136	1,07054	3340,41	1073,55	32,9786	CRS
23:07:52,152	70579	4,41944	1,07059	1,06978	3345,74	1078,07	32,895	CRS
23:09:02,151	70696,5	4,43947	1,07143	1,07063	3351,04	1082,96	32,9871	CRS
23:10:12,151	70813,9	4,46166	1,0749	1,0741	3356,28	1088,37	33,3651	CRS
23:11:22,150	70931,3	4,48403	1,07773	1,07694	3361,51	1093,83	33,6737	CRS
23:12:32,150	71048,8	4,50817	1,08251	1,08172	3366,7	1099,73	34,1949	CRS
23:13:42,149	71166,3	4,53165	1,08559	1,08482	3371,91	1105,46	34,5304	CRS
23:14:52,148	71283,7	4,56003	1,07403	1,07327	3376,98	1112,39	33,2701	CRS
23:16:02,148	71401,2	4,59901	1,07246	1,07171	3381,78	1121,91	33,0992	CRS
23:17:12,147	71518,7	4,63795	1,07236	1,07162	3386,59	1131,41	33,0877	CRS
23:18:22,146	71636	4,67679	1,07283	1,07212	3391,39	1140,9	33,1397	CRS
23:19:32,146	71753,5	4,71503	1,07433	1,07363	3396,22	1150,23	33,3032	CRS
23:20:42,145	71871	4,75218	1,07452	1,07383	3401,08	1159,3	33,3235	CRS
23:21:52,144	71988,4	4,7894	1,07552	1,07484	3405,93	1168,39	33,4327	CRS
23:23:02,144	72105,8	4,82505	1,07533	1,07466	3410,83	1177,1	33,4121	CRS
23:24:12,143	72223,3	4,86052	1,07558	1,07491	3415,74	1185,76	33,439	CRS
23:25:22,142	72340,8	4,8962	1,07633	1,07567	3420,64	1194,47	33,5205	CRS
23:26:32,142	72458,2	4,93025	1,07552	1,07488	3425,58	1202,78	33,4322	CRS
23:27:42,142	72575,7	4,96495	1,07646	1,07584	3430,52	1211,25	33,5353	CRS
23:28:52,141	72693,1	4,9996	1,07722	1,07661	3435,45	1219,71	33,6181	CRS
23:30:02,140	72810,5	5,03364	1,07787	1,07728	3440,4	1228,02	33,6891	CRS
23:31:12,140	72928	5,06756	1,08012	1,07954	3445,35	1236,3	33,9338	CRS
23:32:22,140	73045,5	5,10062	1,08092	1,08035	3450,33	1244,37	34,0207	CRS
23:33:32,138	73162,8	5,13321	1,08388	1,08331	3455,32	1252,33	34,3438	CRS
23:34:42,138	73280,3	5,16495	1,0875	1,08695	3460,34	1260,08	34,7385	CRS
23:35:52,137	73397,8	5,1942	1,08888	1,08834	3465,42	1267,22	34,889	CRS
23:37:02,136	73515,2	5,22232	1,09118	1,09064	3470,53	1274,09	35,1389	CRS
23:38:12,136	73632,7	5,25318	1,089	1,08847	3475,57	1281,62	34,9014	CRS
23:39:22,135	73750,2	5,28651	1,08627	1,08576	3480,55	1289,76	34,6039	CRS
23:40:32,134	73867,6	5,32147	1,08509	1,0846	3485,49	1298,3	34,4758	CRS
23:41:42,134	73985	5,35596	1,08746	1,08697	3490,44	1306,72	34,734	CRS
23:42:52,134	74102,5	5,39172	1,08944	1,08896	3495,36	1315,45	34,9495	CRS
23:44:02,133	74220	5,42999	1,09275	1,09228	3500,22	1324,79	35,3101	CRS
23:45:12,132	74337,3	5,4661	1,09308	1,09262	3505,14	1333,61	35,3469	CRS
23:46:22,131	74454,8	5,50135	1,09479	1,09435	3510,08	1342,21	35,5334	CRS
23:47:32,131	74572,3	5,53505	1,09597	1,09554	3515,06	1350,44	35,6611	CRS
23:48:42,130	74689,7	5,56869	1,09864	1,09822	3520,04	1358,66	35,9527	CRS
23:49:52,129	74807,2	5,59862	1,10152	1,1011	3525,12	1365,96	36,266	CRS
23:51:02,129	74924,7	5,62044	1,10307	1,10267	3530,4	1371,29	36,4352	CRS
23:52:12,128	75042	5,62945	1,1108	1,1104	3536	1373,49	37,2778	CRS
23:53:22,128	75159,5	5,61472	1,11898	1,11857	3542,2	1369,89	38,1698	CRS
23:54:32,128	75277	5,57489	1,12761	1,12718	3549,03	1360,17	39,1102	CRS
23:55:42,126	75394,4	5,53345	1,12084	1,12041	3555,9	1350,05	38,3726	CRS
23:56:52,126	75511,8	5,50135	1,12158	1,12113	3562,53	1342,21	38,4534	CRS
23:58:02,126	75629,3	5,47117	1,11294	1,11247	3569,12	1334,85	37,5118	CRS
23:59:12,124	75746,8	5,47184	1,09255	1,0921	3574,94	1335,01	35,2883	CRS
00:00:22,124	75864,2	5,49255	1,08372	1,08327	3580,24	1340,06	34,3257	CRS
00:01:32,124	75981,7	5,51934	1,08341	1,08298	3585,4	1346,61	34,2927	CRS
00:02:42,122	76099,1	5,5494	1,0807	1,08028	3590,47	1353,94	33,9971	CRS
00:03:52,123	76216,5	5,58337	1,08593	1,08552	3595,44	1362,24	34,5672	CRS
00:05:02,121	76334	5,617	1,09292	1,09251	3600,43	1370,45	35,3289	CRS
00:06:12,121	76451,5	5,6521	1,09236	1,09197	3605,38	1379,02	35,2685	CRS
00:07:22,121	76568,9	5,68677	1,10186	1,10148	3610,33	1387,49	36,3039	CRS
00:08:32,119	76686,3	5,70955	1,11058	1,1102	3615,59	1393,05	37,2537	CRS
00:09:42,119	76803,8	5,7318	1,11261	1,11222	3620,87	1398,48	37,4755	CRS
00:10:52,118	76921,2	5,75633	1,11121	1,11085	3626,08	1404,47	37,3227	CRS
00:12:02,117	77038,7	5,78642	1,10919	1,10884	3631,16	1411,81	37,1027	CRS
00:13:12,117	77156,2	5,81754	1,11211	1,11177	3636,22	1419,41	37,4213	CRS
00:14:22,117	77273,6	5,85065	1,11178	1,11144	3641,23	1427,5	37,3843	CRS
00:15:32,115	77391	5,88501	1,11132	1,111	3646,2	1435,88	37,3347	CRS
00:16:42,115	77508,5	5,91726	1,11724	1,11693	3651,23	1443,76	37,9803	CRS
00:17:52,115	77626	5,94541	1,1179	1,11759	3656,36	1450,63	38,0519	CRS
00:19:02,114	77743,3	5,97793	1,11604	1,11576	3661,38	1458,57	37,8492	CRS
00:20:12,113	77860,8	6,01372	1,1176	1,11732	3666,33	1467,31	38,0194	CRS
00:21:22,112	77978,3	6,04343	1,12031	1,12005	3671,43	1474,56	38,3143	CRS
00:22:32,112	78095,7	6,07494	1,12063	1,12038	3676,48	1482,26	38,3498	CRS
00:23:42,112	78213,2	6,10567	1,11949	1,11924	3681,55	1489,76	38,225	CRS
00:24:52,110	78330,7	6,13849	1,11925	1,11902	3686,58	1497,77	38,1996	CRS
00:26:02,110	78448,1	6,17382	1,12109	1,12086	3691,54	1506,4	38,3992	CRS
00:27:12,109	78565,5	6,20981	1,12442	1,1242	3696,49	1515,18	38,7627	CRS
00:28:22,109	78683	6,24538	1,12702	1,12683	3701,45	1523,87	39,0463	CRS
00:29:32,109	78800,4	6,27795	1,12842	1,12822	3706,48	1531,82	39,1984	CRS
00:30:32,108	78901,1	6,3046	1,12946	1,12927	3710,83	1538,33	39,3116	CRS