File: Example - Raw files/Ødo 2015/G1-1_CRS_D10-4m.lvm
Oedometer-2	14.10.2015
*Header*
Operator	G1-1_2015
Site	Stjørdal
Hole
Depth [m]	10,4
Comment
Sample area [cm2]	20
Sample height [mm]	20
*Calibration data *
Motor [steps/rev]	16000
Jack [µm/rev]	794
Load cell fact. [N/V]	488,3
Pore sens. fact. [kPa/V]	109
LVDT fact. [µm/V]	-1050
SelfDeform factor	,495368
SelfDeform exp	,75
Slack [steps]	0

        		Load	Pore			Vertica	Pore
Mean        	Deform.	cell	sens.	LVDT.	Deforma	stress	pressur
time        	[steps]	[V]	[V]	[V]	[µm]	[kPa]	[kPa]	MODE
------------	-------	-------	-------	-------	-------	-------	-------	-------
11:19:18,072	0	,004604	,791691	0	-0	0	0	ZERO
11:20:23,072	106,28	,013681	,818448	,816148	3,76095	2,21615	2,91645	CRS
11:21:33,071	223,68	,017349	,820842	,818557	9,14822	3,11183	3,17745	CRS
11:22:43,070	341,16	,020852	,823203	,820882	14,5883	3,96701	3,43483	CRS
11:23:53,070	458,68	,023762	,825106	,82282	20,1123	4,67736	3,64219	CRS
11:25:03,069	576,02	,024237	,825694	,823402	25,8861	4,79353	3,70635	CRS
11:26:13,069	693,5	,025365	,826721	,824426	31,6006	5,06875	3,81824	CRS
11:27:23,068	811	,026689	,827893	,825615	37,298	5,39199	3,94597	CRS
11:28:33,067	928,38	,027933	,829061	,826751	42,9992	5,6959	4,07335	CRS
11:29:43,067	1045,84	,028848	,830169	,827848	48,7382	5,91928	4,19414	CRS
11:30:53,066	1163,32	,030348	,831465	,829176	54,4226	6,28545	4,33537	CRS
11:32:03,065	1280,78	,031108	,832627	,830345	60,1786	6,47097	4,46201	CRS
11:33:13,065	1398,16	,031956	,833853	,83158	65,9228	6,67812	4,59566	CRS
11:34:23,064	1515,68	,032746	,83502	,832714	71,68	6,8709	4,72286	CRS
11:35:33,064	1633,14	,033159	,836081	,833747	77,4701	6,97182	4,83852	CRS
11:36:43,063	1750,5	,033905	,837518	,835206	83,2243	7,15388	4,99515	CRS
11:37:53,062	1868	,035019	,839131	,83686	88,9518	7,42589	5,17099	CRS
11:39:03,062	1985,5	,036191	,840779	,838486	94,675	7,71195	5,35059	CRS
11:40:13,061	2102,86	,037608	,842648	,840365	100,37	8,05798	5,55432	CRS
11:41:23,061	2220,32	,039493	,844613	,842325	106,029	8,5182	5,76845	CRS
11:42:33,060	2337,84	,041249	,846928	,844592	111,705	8,94701	6,0208	CRS
11:43:43,059	2455,2	,042773	,84908	,846805	117,396	9,31895	6,25541	CRS
11:44:53,059	2572,68	,044122	,851249	,848956	123,108	9,64846	6,49181	CRS
11:46:03,058	2690,16	,04536	,853113	,850771	128,832	9,95067	6,69493	CRS
11:47:13,057	2807,6	,046668	,855046	,852751	134,548	10,2699	6,90566	CRS
11:48:23,057	2925	,048295	,857526	,855225	140,236	10,6672	7,17601	CRS
11:49:33,056	3042,5	,049579	,859935	,857637	145,959	10,9808	7,43856	CRS
11:50:43,056	3159,96	,051148	,862314	,859968	151,657	11,3637	7,69787	CRS
11:51:53,055	3277,32	,052305	,864391	,862061	157,385	11,6461	7,9243	CRS
11:53:03,054	3394,84	,053267	,866503	,864205	163,138	11,8811	8,15453	CRS
11:54:13,054	3512,32	,053972	,868552	,86625	168,91	12,0533	8,37783	CRS
11:55:23,053	3629,7	,053923	,869727	,867436	174,739	12,0412	8,50586	CRS
11:56:33,052	3747,16	,054059	,870652	,868353	180,556	12,0744	8,60672	CRS
11:57:43,052	3864,68	,053792	,871199	,868885	186,41	12,0094	8,66631	CRS
11:58:53,051	3982,04	,052205	,870156	,867873	192,365	11,6218	8,55263	CRS
12:00:03,051	4099,5	,050612	,868185	,865887	198,326	11,233	8,33782	CRS
12:01:13,050	4217	,04939	,865908	,863602	204,259	10,9344	8,08959	CRS
12:02:23,049	4334,42	,048108	,863522	,861195	210,194	10,6216	7,82961	CRS
12:03:33,049	4451,84	,045433	,858648	,856356	216,249	9,96856	7,29826	CRS
12:04:43,048	4569,32	,042939	,853525	,851185	222,294	9,35958	6,73988	CRS
12:05:53,047	4686,82	,041205	,849937	,847659	228,278	8,93607	6,34882	CRS
12:07:03,047	4804,16	,040099	,84758	,845255	234,198	8,66626	6,09191	CRS
12:08:13,046	4921,68	,039041	,844935	,842644	240,125	8,40793	5,80355	CRS
12:09:23,046	5039,16	,038244	,843239	,840954	246,026	8,21328	5,61868	CRS
12:10:33,045	5156,52	,037367	,841497	,839207	251,93	7,99909	5,42879	CRS
12:11:43,044	5274	,037026	,84067	,838382	257,791	7,9159	5,33868	CRS
12:12:53,044	5391,5	,030981	,828385	,8261	264,185	6,43992	3,99967	CRS
12:14:03,043	5508,88	,029775	,826278	,823991	270,126	6,14565	3,76998	CRS
12:15:13,042	5626,32	,030212	,826999	,824708	275,912	6,25225	3,84856	CRS
12:16:23,042	5743,84	,03049	,827706	,825424	281,717	6,32017	3,92563	CRS
12:17:33,041	5861,24	,03033	,828093	,825815	287,559	6,28105	3,96784	CRS
12:18:43,041	5978,68	,030638	,828947	,826636	293,357	6,35623	4,06084	CRS
12:19:53,040	6096,16	,03084	,829298	,826989	299,168	6,40545	4,09918	CRS
12:21:03,039	6213,64	,031796	,830782	,828474	304,906	6,6389	4,2609	CRS
12:22:13,039	6331	,032756	,832117	,82984	310,639	6,87327	4,40647	CRS
12:23:23,038	6448,5	,033319	,833449	,83118	316,417	7,01092	4,55163	CRS
12:24:33,038	6566	,033457	,833855	,831573	322,235	7,04438	4,59582	CRS
12:25:43,037	6683,34	,033806	,834293	,832003	328,026	7,12977	4,64361	CRS
12:26:53,037	6800,84	,034367	,834963	,832666	333,804	7,26669	4,71661	CRS
12:28:03,036	6918,32	,035227	,836211	,83388	339,555	7,47675	4,85262	CRS
12:29:13,035	7035,72	,036024	,837583	,835279	345,307	7,67123	5,00225	CRS
12:30:23,034	7153,16	,037005	,839337	,837061	351,046	7,91067	5,19335	CRS
12:31:33,034	7270,68	,038745	,842259	,83997	356,721	8,33546	5,51188	CRS
12:32:43,033	7388,08	,039468	,843109	,840823	362,482	8,51212	5,60455	CRS
12:33:53,033	7505,5	,04032	,844211	,841923	368,233	8,72017	5,72465	CRS
12:35:03,032	7623	,041377	,845686	,843382	373,97	8,97815	5,88548	CRS
12:36:13,031	7740,44	,042865	,847631	,845313	379,668	9,34152	6,09749	CRS
12:37:23,031	7857,84	,044876	,850372	,848095	385,319	9,8325	6,39622	CRS
12:38:33,031	7975,32	,046849	,852818	,850479	390,98	10,3141	6,66285	CRS
12:39:43,029	8092,84	,048849	,855535	,853246	396,643	10,8024	6,95901	CRS
12:40:53,029	8210,16	,050799	,857875	,855576	402,302	11,2785	7,21399	CRS
12:42:03,028	8327,68	,052738	,860043	,857752	407,973	11,752	7,4504	CRS
12:43:13,027	8445,16	,054435	,862105	,859758	413,664	12,1662	7,67511	CRS
12:44:23,027	8562,54	,05581	,863596	,861273	419,377	12,5021	7,83766	CRS
12:45:33,027	8680	,057194	,86486	,862538	425,094	12,8398	7,97537	CRS
12:46:43,026	8797,5	,058689	,865959	,863661	430,805	13,205	8,09523	CRS
12:47:53,025	8914,92	,060495	,867232	,864933	436,488	13,6459	8,23394	CRS
12:49:03,025	9032,32	,062606	,868476	,866178	442,147	14,1613	8,3695	CRS
12:50:13,024	9149,84	,06439	,869625	,867342	447,839	14,5967	8,4948	CRS
12:51:23,023	9267,26	,065372	,870394	,868105	453,59	14,8366	8,57863	CRS
12:52:33,023	9384,68	,066284	,870103	,867811	459,346	15,0592	8,54684	CRS
12:53:43,023	9502,16	,067227	,869318	,867026	465,103	15,2896	8,46132	CRS
12:54:53,021	9619,68	,067907	,868452	,866156	470,883	15,4554	8,36697	CRS
12:56:03,020	9737	,067855	,866219	,863929	476,709	15,4428	8,12356	CRS
12:57:13,021	9854,5	,068169	,86431	,861988	482,515	15,5193	7,91545	CRS
12:58:23,019	9972	,069172	,863085	,860764	488,269	15,7644	7,78198	CRS
12:59:33,019	10089,4	,070323	,862001	,859657	494,005	16,0453	7,66374	CRS
13:00:43,018	10206,8	,072037	,861544	,859201	499,705	16,4637	7,61395	CRS
13:01:53,017	10324,3	,073923	,861217	,858885	505,393	16,9242	7,57831	CRS
13:03:03,017	10441,8	,076233	,861234	,858901	511,048	17,4882	7,58014	CRS
13:04:13,016	10559,2	,078341	,861187	,858856	516,717	18,0029	7,57504	CRS
13:05:23,016	10676,7	,080707	,861581	,85924	522,374	18,5805	7,61795	CRS
13:06:33,015	10794,1	,082758	,861612	,859278	528,051	19,0813	7,62142	CRS
13:07:43,015	10911,5	,084819	,862215	,859886	533,727	19,5844	7,68711	CRS
13:08:53,014	11029	,086759	,861943	,859607	539,418	20,0581	7,65746	CRS
13:10:03,013	11146,5	,089159	,862118	,859791	545,075	20,6443	7,67658	CRS
13:11:13,013	11263,8	,090632	,861814	,859483	550,794	21,0037	7,64345	CRS
13:12:23,012	11381,3	,091865	,861261	,858939	556,536	21,3049	7,58315	CRS
13:13:33,011	11498,8	,093595	,860845	,858533	562,246	21,7271	7,53782	CRS
13:14:43,010	11616,2	,095703	,860886	,858571	567,92	22,2418	7,54222	CRS
13:15:53,011	11733,7	,098565	,86081	,858498	573,551	22,9405	7,53391	CRS
13:17:03,009	11851,2	,10177	,861427	,85909	579,159	23,7232	7,6012	CRS
13:18:13,009	11968,6	,104722	,861261	,858939	584,782	24,4439	7,5831	CRS
13:19:23,009	12086	,107992	,861696	,859368	590,386	25,2422	7,63048	CRS
13:20:33,007	12203,5	,110765	,861593	,859273	596,029	25,9192	7,61934	CRS
13:21:43,007	12320,9	,113782	,861504	,859182	601,653	26,6558	7,60956	CRS
13:22:53,006	12438,3	,116776	,861369	,859044	607,278	27,3868	7,59486	CRS
13:24:03,005	12555,8	,118976	,860597	,858299	612,964	27,9239	7,51073	CRS
13:25:13,005	12673,3	,121495	,860057	,857783	618,626	28,539	7,45189	CRS
13:26:23,005	12790,7	,124752	,860141	,857863	624,237	29,3341	7,46098	CRS
13:27:33,003	12908,2	,12738	,859168	,856913	629,895	29,9757	7,35495	CRS
13:28:43,003	13025,7	,130168	,859447	,857191	635,545	30,6565	7,38543	CRS
13:29:53,003	13143	,133215	,858889	,856633	641,171	31,4004	7,32461	CRS
13:31:03,002	13260,5	,136728	,859353	,857101	646,776	32,2582	7,37513	CRS
13:32:13,001	13378	,140369	,860185	,857911	652,374	33,1471	7,46588	CRS
13:33:23,001	13495,4	,143354	,859614	,857359	658,011	33,8759	7,40355	CRS
13:34:33,001	13612,8	,146678	,86035	,858076	663,629	34,6875	7,48377	CRS
13:35:42,999	13730,3	,150108	,860574	,858286	669,244	35,5249	7,50827	CRS
13:36:52,999	13847,8	,153601	,860718	,858428	674,856	36,3776	7,52395	CRS
13:38:02,999	13965,2	,157017	,860952	,858659	680,469	37,2117	7,54943	CRS
13:39:12,997	14082,7	,160758	,860916	,858625	686,071	38,125	7,54556	CRS
13:40:22,997	14200,1	,164925	,861486	,859181	691,645	39,1425	7,60761	CRS
13:41:32,997	14317,5	,168409	,861298	,858998	697,257	39,9931	7,58713	CRS
13:42:42,996	14435	,17208	,861019	,858729	702,866	40,8894	7,55671	CRS
13:43:52,995	14552,5	,175898	,860569	,858299	708,467	41,8216	7,50773	CRS
13:45:02,995	14669,9	,180025	,860618	,858341	714,044	42,829	7,51298	CRS
13:46:12,993	14787,3	,183927	,860375	,858111	719,641	43,7819	7,48658	CRS
13:47:22,993	14904,8	,188101	,86019	,857937	725,226	44,8009	7,46639	CRS
13:48:32,993	15022,2	,192286	,860012	,857767	730,805	45,8227	7,44702	CRS
13:49:42,992	15139,7	,196195	,85975	,85751	736,405	46,7771	7,41843	CRS
13:50:52,991	15257,2	,199558	,858119	,855876	742,039	47,5981	7,24063	CRS
13:52:02,990	15374,6	,204535	,859448	,857214	747,579	48,8133	7,38545	CRS
13:53:12,990	15492	,209588	,859926	,85769	753,115	50,0469	7,43764	CRS
13:54:22,990	15609,5	,214947	,860315	,858063	758,639	51,3553	7,48	CRS
13:55:32,989	15727	,220242	,86077	,85851	764,168	52,648	7,52964	CRS
13:56:42,988	15844,3	,225067	,860953	,858681	769,719	53,826	7,54957	CRS
13:57:52,988	15961,8	,230051	,862032	,859754	775,271	55,043	7,66719	CRS
13:59:02,987	16079,3	,234983	,861412	,859135	780,825	56,2471	7,59958	CRS
14:00:12,987	16196,7	,239853	,860864	,858611	786,38	57,4362	7,53981	CRS
14:01:22,985	16314,2	,244487	,859626	,857405	791,952	58,5676	7,40489	CRS
14:02:32,985	16431,7	,250183	,859832	,857616	797,471	59,9582	7,42734	CRS
14:03:42,985	16549,1	,255517	,859541	,85733	803,005	61,2604	7,39568	CRS
14:04:52,983	16666,5	,261046	,85989	,85767	808,532	62,6103	7,43369	CRS
14:06:02,983	16784	,266196	,859256	,857053	814,084	63,8677	7,36459	CRS
14:07:12,983	16901,4	,271283	,858867	,856659	819,637	65,1096	7,3222	CRS
14:08:22,982	17018,8	,276349	,858573	,856369	825,193	66,3466	7,29008	CRS
14:09:32,982	17136,3	,282078	,858943	,856747	830,717	67,7453	7,33047	CRS
14:10:42,980	17253,8	,28773	,858942	,856743	836,248	69,1252	7,33037	CRS
14:11:52,980	17371,2	,293186	,858196	,855998	841,784	70,4573	7,24908	CRS
14:13:02,979	17488,7	,29886	,857843	,855642	847,317	71,8427	7,21061	CRS
14:14:12,978	17606,2	,30447	,857468	,85527	852,854	73,2124	7,1697	CRS
14:15:22,978	17723,5	,310221	,856851	,85466	858,379	74,6165	7,10239	CRS
14:16:32,978	17841	,316066	,856765	,854578	863,906	76,0435	7,093	CRS
14:17:42,976	17958,5	,321978	,856756	,854564	869,432	77,4868	7,09205	CRS
14:18:52,977	18075,9	,327963	,856876	,854687	874,951	78,9482	7,10519	CRS
14:20:02,976	18193,3	,333359	,856533	,854347	880,503	80,2656	7,06772	CRS
14:21:12,975	18310,8	,339342	,855835	,853656	886,03	81,7264	6,99166	CRS
14:22:22,974	18428,2	,345569	,85593	,853751	891,541	83,2467	7,002	CRS
14:23:32,974	18545,7	,352594	,857136	,854956	897,015	84,9617	7,13345	CRS
14:24:42,973	18663,2	,359595	,858332	,856156	902,494	86,6711	7,26383	CRS
14:25:52,972	18780,6	,366866	,859346	,85717	907,962	88,4464	7,37437	CRS
14:27:02,972	18898	,374495	,860607	,858406	913,407	90,3089	7,51188	CRS
14:28:12,972	19015,5	,382547	,861883	,859661	918,841	92,2749	7,65095	CRS
14:29:22,971	19133	,391279	,863509	,861312	924,243	94,4068	7,8281	CRS
14:30:32,970	19250,3	,398949	,862978	,860778	929,692	96,2794	7,77026	CRS
14:31:42,969	19367,8	,407561	,864171	,861981	935,104	98,3819	7,90034	CRS
14:32:52,969	19485,3	,415921	,86562	,863443	940,53	100,423	8,05822	CRS
14:34:02,968	19602,7	,423844	,86541	,863236	945,975	102,357	8,03539	CRS
14:35:12,968	19720,2	,430759	,86438	,862195	951,472	104,046	7,92309	CRS
14:36:22,967	19837,7	,438497	,863815	,861633	956,936	105,935	7,86148	CRS
14:37:32,966	19955,1	,446034	,863645	,861463	962,404	107,775	7,84293	CRS
14:38:42,966	20072,5	,453903	,86321	,86103	967,859	109,696	7,79553	CRS
14:39:52,965	20190	,461392	,862357	,860173	973,338	111,525	7,70253	CRS
14:41:02,965	20307,4	,468926	,862181	,860001	978,813	113,364	7,6834	CRS
14:42:12,963	20424,8	,476991	,86286	,860686	984,262	115,333	7,75737	CRS
14:43:22,963	20542,3	,484999	,862498	,860331	989,72	117,289	7,71795	CRS
14:44:32,963	20659,8	,493464	,862849	,860691	995,161	119,355	7,75623	CRS
14:45:42,962	20777,2	,50144	,862482	,860315	1000,62	121,303	7,71621	CRS
14:46:52,961	20894,7	,509845	,862897	,860745	1006,06	123,355	7,76139	CRS
14:48:02,961	21012,2	,518168	,863007	,860852	1011,51	125,387	7,77341	CRS
14:49:12,959	21129,5	,526186	,863009	,860872	1016,97	127,344	7,77367	CRS
14:50:22,959	21247	,534705	,864566	,862424	1022,41	129,424	7,94332	CRS
14:51:32,959	21364,5	,543083	,864814	,862671	1027,87	131,47	7,97044	CRS
14:52:42,958	21481,9	,552072	,866015	,863904	1033,29	133,664	8,10133	CRS
14:53:52,958	21599,3	,559987	,86509	,862955	1038,76	135,597	8,00045	CRS
14:55:02,957	21716,8	,567847	,863899	,861769	1044,24	137,516	7,87067	CRS
14:56:12,957	21834,3	,575811	,863446	,861322	1049,72	139,46	7,82127	CRS
14:57:22,956	21951,7	,583936	,86328	,861148	1055,18	141,444	7,80314	CRS
14:58:32,954	22069,2	,592167	,863252	,861133	1060,65	143,454	7,80017	CRS
14:59:42,955	22186,7	,600547	,863757	,861638	1066,11	145,5	7,85519	CRS
15:00:52,954	22304	,609222	,864233	,862116	1071,55	147,618	7,90706	CRS
15:02:02,953	22421,5	,617559	,864081	,86197	1077,02	149,653	7,89044	CRS
15:03:12,953	22539	,626151	,863904	,861796	1082,48	151,751	7,87125	CRS
15:04:22,952	22656,4	,634293	,863603	,861504	1087,95	153,739	7,83841	CRS
15:05:32,952	22773,8	,642619	,863718	,861616	1093,42	155,771	7,85094	CRS
15:06:42,951	22891,3	,65161	,865258	,863172	1098,86	157,967	8,01883	CRS
15:07:52,950	23008,8	,660544	,866392	,864323	1104,3	160,148	8,14243	CRS
15:09:02,950	23126,2	,66962	,867909	,86584	1109,74	162,364	8,30776	CRS
15:10:12,949	23243,7	,677613	,867234	,865169	1115,23	164,315	8,2342	CRS
15:11:22,948	23361,1	,68571	,867088	,865026	1120,72	166,292	8,21822	CRS
15:12:32,948	23478,5	,694054	,866931	,864874	1126,19	168,329	8,2012	CRS
15:13:42,947	23596	,702269	,866235	,864179	1131,67	170,335	8,12529	CRS
15:14:52,946	23713,5	,711089	,867292	,865246	1137,13	172,488	8,24047	CRS
15:16:02,946	23830,8	,720278	,868863	,866813	1142,57	174,732	8,41169	CRS
15:17:12,945	23948,3	,730358	,87077	,86872	1147,97	177,193	8,61956	CRS
15:18:22,945	24065,8	,739203	,870046	,868006	1153,44	179,352	8,54066	CRS
15:19:32,944	24183,2	,747379	,869581	,867549	1158,92	181,349	8,49005	CRS
15:20:42,943	24300,7	,755563	,869199	,867163	1164,41	183,347	8,44831	CRS
15:21:52,943	24418,2	,763849	,869538	,867508	1169,9	185,37	8,48528	CRS
15:23:02,941	24535,6	,771654	,869002	,866984	1175,4	187,275	8,4269	CRS
15:24:12,941	24653	,78002	,869711	,867691	1180,89	189,318	8,50413	CRS
15:25:22,941	24770,5	,78801	,870038	,868015	1186,39	191,269	8,53983	CRS
15:26:32,940	24887,9	,795449	,869972	,867956	1191,91	193,085	8,53261	CRS
15:27:42,940	25005,3	,803075	,870665	,868637	1197,42	194,947	8,60818	CRS
15:28:52,939	25122,8	,810187	,870071	,868057	1202,97	196,683	8,54339	CRS
15:30:02,938	25240,3	,817522	,870397	,868377	1208,5	198,474	8,5789	CRS
15:31:12,938	25357,7	,824976	,870585	,868575	1214,02	200,294	8,59945	CRS
15:32:22,937	25475,2	,831879	,869866	,867858	1219,57	201,979	8,52104	CRS
15:33:32,936	25592,7	,838983	,869711	,867713	1225,11	203,714	8,50416	CRS
15:34:42,936	25710	,846443	,86999	,867992	1230,64	205,535	8,53456	CRS
15:35:52,935	25827,5	,853312	,869282	,867286	1236,19	207,212	8,45737	CRS
15:37:02,935	25945	,861304	,870589	,868584	1241,7	209,163	8,59985	CRS
15:38:12,934	26062,4	,868597	,871305	,869297	1247,23	210,944	8,67788	CRS
15:39:22,933	26179,8	,876365	,872237	,870229	1252,75	212,84	8,77945	CRS
15:40:32,933	26297,3	,883941	,872571	,870567	1258,28	214,69	8,81594	CRS
15:41:42,932	26414,8	,890956	,872864	,870867	1263,83	216,403	8,84789	CRS
15:42:52,931	26532,2	,898238	,873851	,871861	1269,36	218,181	8,9554	CRS
15:44:02,931	26649,7	,904472	,873534	,871551	1274,95	219,703	8,9209	CRS
15:45:12,930	26767,1	,911414	,873785	,871806	1280,5	221,398	8,94824	CRS
15:46:22,930	26884,5	,918883	,875449	,873485	1286,03	223,221	9,12965	CRS
15:47:32,929	27002	,926305	,876997	,87501	1291,57	225,033	9,2983	CRS
15:48:42,928	27119,5	,932343	,876266	,874293	1297,16	226,508	9,21868	CRS
15:49:52,928	27236,9	,938563	,875628	,873669	1302,74	228,026	9,14914	CRS
15:51:02,927	27354,3	,944953	,875263	,873302	1308,32	229,586	9,10933	CRS
15:52:12,926	27471,8	,950784	,874787	,872827	1313,92	231,01	9,05746	CRS
15:53:22,926	27589,2	,957294	,875563	,873604	1319,5	232,599	9,142	CRS
15:54:32,925	27706,7	,963913	,875466	,873512	1325,07	234,215	9,13146	CRS
15:55:42,924	27824,2	,969911	,87554	,873592	1330,66	235,68	9,13951	CRS
15:56:52,924	27941,6	,975963	,875018	,873072	1336,25	237,157	9,0826	CRS
15:58:02,923	28059	,982165	,875298	,873355	1341,84	238,672	9,11317	CRS
15:59:12,923	28176,5	,987146	,875003	,87306	1347,48	239,888	9,08101	CRS
16:00:22,922	28294	,99314	,875397	,873455	1353,07	241,351	9,12399	CRS
16:01:32,921	28411,3	,998934	,875711	,873769	1358,67	242,766	9,15821	CRS
16:02:42,921	28528,8	1,00416	,875036	,873102	1364,3	244,043	9,0846	CRS
16:03:52,920	28646,3	1,00998	,875814	,873878	1369,91	245,463	9,16941	CRS
16:05:02,919	28763,7	1,0149	,875762	,873827	1375,55	246,663	9,16368	CRS
16:06:12,919	28881,2	1,01987	,875903	,873967	1381,18	247,876	9,17906	CRS
16:07:22,918	28998,7	1,02536	,876288	,874348	1386,8	249,218	9,22106	CRS
16:08:32,918	29116,1	1,02983	,874861	,872934	1392,46	250,309	9,06552	CRS
16:09:42,917	29233,5	1,03574	,876095	,874163	1398,06	251,751	9,20002	CRS
16:10:52,916	29351	1,04237	,878586	,876629	1403,64	253,369	9,47159	CRS
16:12:02,916	29468,4	1,04857	,879132	,87719	1409,23	254,885	9,53103	CRS
16:13:12,915	29585,8	1,05427	,879619	,877694	1414,84	256,277	9,5841	CRS
16:14:22,914	29703,3	1,05895	,878544	,876591	1420,49	257,419	9,46693	CRS
16:15:32,914	29820,8	1,06438	,878852	,876901	1426,11	258,743	9,50048	CRS
16:16:42,913	29938,2	1,0695	,879105	,877168	1431,74	259,995	9,52806	CRS
16:17:52,913	30055,7	1,07446	,878756	,876813	1437,38	261,205	9,49003	CRS
16:19:02,912	30173,2	1,07984	,880152	,878239	1443,01	262,519	9,64225	CRS
16:20:12,911	30290,5	1,08458	,880235	,878324	1448,65	263,676	9,6513	CRS
16:21:22,911	30408	1,08999	,881472	,879558	1454,28	264,996	9,78614	CRS
16:22:32,910	30525,5	1,09543	,882451	,880531	1459,9	266,324	9,89285	CRS
16:23:42,909	30642,9	1,10004	,882297	,880371	1465,56	267,45	9,87609	CRS
16:24:52,909	30760,3	1,10413	,881442	,879533	1471,23	268,448	9,78289	CRS
16:26:02,908	30877,8	1,10873	,881584	,879675	1476,89	269,572	9,79838	CRS
16:27:12,907	30995,2	1,11333	,881255	,87935	1482,54	270,695	9,76249	CRS
16:28:22,907	31112,7	1,11807	,881028	,879129	1488,19	271,852	9,73775	CRS
16:29:32,906	31230,2	1,12213	,880384	,878487	1493,87	272,843	9,66755	CRS
16:30:42,906	31347,7	1,12744	,881671	,879758	1499,5	274,14	9,80783	CRS
16:31:52,905	31465	1,13255	,882571	,880656	1505,13	275,389	9,90589	CRS
16:33:02,904	31582,5	1,13769	,883768	,881868	1510,77	276,644	10,0364	CRS
16:34:12,904	31700	1,14285	,884969	,883075	1516,41	277,904	10,1673	CRS
16:35:22,903	31817,3	1,14889	,88692	,885013	1522,01	279,378	10,3799	CRS
16:36:32,902	31934,8	1,15349	,886991	,885082	1527,66	280,501	10,3877	CRS
16:37:42,902	32052,3	1,1585	,887535	,88562	1533,31	281,723	10,447	CRS
16:38:52,901	32169,7	1,16341	,888278	,886356	1538,95	282,923	10,5279	CRS
16:40:02,901	32287,2	1,16768	,887872	,885956	1544,62	283,965	10,4837	CRS
16:41:12,900	32404,7	1,17196	,887688	,885783	1550,29	285,009	10,4637	CRS
16:42:22,899	32522,1	1,17593	,887177	,885277	1555,97	285,978	10,4079	CRS
16:43:32,899	32639,5	1,18125	,888541	,886629	1561,6	287,279	10,5567	CRS
16:44:42,898	32757	1,18543	,887653	,885749	1567,28	288,3	10,4599	CRS
16:45:52,897	32874,5	1,18958	,886894	,885003	1572,95	289,312	10,3772	CRS
16:47:02,897	32991,8	1,19314	,88548	,883603	1578,65	290,182	10,223	CRS
16:48:12,896	33109,3	1,19734	,885726	,883848	1584,32	291,207	10,2498	CRS
16:49:22,896	33226,8	1,20178	,885743	,883868	1589,99	292,292	10,2517	CRS
16:50:32,895	33344,2	1,20556	,88488	,883004	1595,67	293,214	10,1576	CRS
16:51:42,894	33461,7	1,209	,884479	,882609	1601,38	294,053	10,1139	CRS
16:52:52,894	33579,2	1,2122	,883443	,881558	1607,09	294,836	10,0009	CRS
16:54:02,893	33696,6	1,21633	,884005	,882129	1612,76	295,844	10,0623	CRS
16:55:12,893	33814	1,22158	,885411	,883543	1618,4	297,124	10,2155	CRS
16:56:22,892	33931,5	1,22597	,885213	,883349	1624,07	298,197	10,1938	CRS
16:57:32,891	34048,9	1,2306	,88552	,883657	1629,72	299,326	10,2274	CRS
16:58:42,891	34166,3	1,23453	,88509	,883221	1635,41	300,288	10,1805	CRS
16:59:52,890	34283,8	1,23859	,885594	,883731	1641,09	301,277	10,2354	CRS
17:01:02,889	34401,3	1,24219	,885082	,883222	1646,79	302,158	10,1796	CRS
17:02:12,889	34518,7	1,24749	,886952	,885076	1652,42	303,451	10,3835	CRS
17:03:22,888	34636,2	1,25146	,886675	,884812	1658,1	304,42	10,3532	CRS
17:04:32,887	34753,7	1,25683	,888285	,886401	1663,74	305,73	10,5288	CRS
17:05:42,888	34871	1,26109	,88766	,885789	1669,41	306,77	10,4606	CRS
17:06:52,886	34988,5	1,26611	,888243	,886345	1675,05	307,996	10,5242	CRS
17:08:02,886	35106	1,27181	,890088	,888236	1680,68	309,388	10,7253	CRS
17:09:12,885	35223,4	1,27739	,890873	,889033	1686,3	310,751	10,8109	CRS
17:10:22,884	35340,8	1,28343	,892381	,890534	1691,91	312,226	10,9752	CRS
17:11:32,884	35458,3	1,28895	,893566	,891708	1697,54	313,574	11,1043	CRS
17:12:42,883	35575,8	1,29384	,893698	,891853	1703,19	314,766	11,1188	CRS
17:13:52,883	35693,2	1,29816	,893571	,891722	1708,86	315,821	11,1049	CRS
17:15:02,883	35810,7	1,30219	,893134	,89129	1714,55	316,806	11,0573	CRS
17:16:12,881	35928,1	1,30635	,893358	,891523	1720,22	317,822	11,0817	CRS
17:17:22,881	36045,5	1,31058	,893458	,891613	1725,89	318,854	11,0925	CRS
17:18:32,880	36163	1,31409	,892543	,890708	1731,6	319,711	10,9929	CRS
17:19:42,880	36280,5	1,31771	,891956	,890126	1737,3	320,594	10,9289	CRS
17:20:52,879	36397,8	1,3216	,891229	,8894	1742,98	321,546	10,8496	CRS
17:22:02,878	36515,3	1,32636	,892155	,890334	1748,64	322,706	10,9506	CRS
17:23:12,878	36632,8	1,33132	,892477	,89065	1754,29	323,917	10,9857	CRS
17:24:22,877	36750,2	1,33544	,89193	,890105	1759,97	324,924	10,926	CRS
17:25:32,876	36867,7	1,34009	,892278	,890454	1765,63	326,058	10,9639	CRS
17:26:42,876	36985,2	1,34467	,892432	,890614	1771,3	327,178	10,9807	CRS
17:27:52,875	37102,6	1,3492	,892301	,890484	1776,96	328,284	10,9665	CRS
17:29:02,875	37220	1,35476	,894102	,892269	1782,59	329,641	11,1628	CRS
17:30:12,874	37337,5	1,35968	,894612	,892769	1788,25	330,841	11,2184	CRS
17:31:22,873	37455	1,36533	,896085	,894242	1793,87	332,222	11,3789	CRS
17:32:32,873	37572,3	1,37089	,897697	,895869	1799,5	333,578	11,5546	CRS
17:33:42,872	37689,8	1,3753	,897298	,895472	1805,17	334,656	11,5112	CRS
17:34:52,871	37807,3	1,37993	,897627	,895807	1810,84	335,785	11,547	CRS
17:36:02,871	37924,7	1,38427	,897554	,895732	1816,51	336,845	11,539	CRS
17:37:12,870	38042,2	1,38913	,898085	,896269	1822,16	338,032	11,5969	CRS
17:38:22,870	38159,7	1,39409	,89836	,896548	1827,82	339,242	11,627	CRS
17:39:32,869	38277	1,39897	,898585	,89676	1833,47	340,435	11,6514	CRS
17:40:42,868	38394,5	1,4033	,897542	,895728	1839,15	341,491	11,5377	CRS
17:41:52,868	38512	1,40775	,897014	,895196	1844,82	342,577	11,4802	CRS
17:43:02,867	38629,4	1,41168	,896036	,894209	1850,51	343,538	11,3735	CRS
17:44:12,867	38746,8	1,41627	,896294	,894469	1856,17	344,658	11,4018	CRS
17:45:22,866	38864,3	1,41991	,894942	,893121	1861,87	345,548	11,2544	CRS
17:46:32,865	38981,8	1,42511	,896231	,894408	1867,52	346,818	11,3948	CRS
17:47:42,865	39099,2	1,43074	,897949	,896147	1873,14	348,191	11,5821	CRS
17:48:52,864	39216,7	1,43605	,898399	,896598	1878,79	349,487	11,6312	CRS
17:50:02,863	39334,1	1,44095	,898708	,89691	1884,44	350,683	11,6649	CRS
17:51:12,863	39451,5	1,44593	,899052	,897259	1890,09	351,901	11,7023	CRS
17:52:22,862	39569	1,45093	,899508	,897712	1895,75	353,121	11,752	CRS
17:53:32,862	39686,5	1,45672	,90101	,899245	1901,37	354,535	11,9158	CRS
17:54:42,862	39803,9	1,46353	,903477	,901814	1906,96	356,196	12,1847	CRS
17:55:52,861	39921,3	1,47109	,906413	,904602	1912,52	358,042	12,5047	CRS
17:57:02,860	40038,8	1,4783	,907432	,905634	1918,1	359,803	12,6158	CRS
17:58:12,859	40156,2	1,48342	,906416	,904612	1923,75	361,053	12,505	CRS
17:59:22,858	40273,7	1,48899	,906305	,904508	1929,38	362,413	12,4929	CRS
18:00:32,858	40391,2	1,49312	,904059	,902352	1935,07	363,42	12,2481	CRS
18:01:42,858	40508,6	1,49726	,902544	,900908	1940,75	364,433	12,0829	CRS
18:02:52,857	40626	1,50211	,902616	,900983	1946,41	365,616	12,0908	CRS
18:04:02,856	40743,5	1,50732	,902615	,90098	1952,06	366,889	12,0907	CRS
18:05:12,855	40861	1,51266	,902958	,901327	1957,7	368,192	12,1281	CRS
18:06:22,856	40978,3	1,51757	,902677	,901042	1963,35	369,39	12,0974	CRS
18:07:32,854	41095,8	1,52251	,902351	,900704	1969,01	370,596	12,0619	CRS
18:08:42,853	41213,3	1,52844	,903559	,901893	1974,64	372,044	12,1936	CRS
18:09:52,853	41330,7	1,53418	,904214	,902514	1980,26	373,445	12,265	CRS
18:11:02,852	41448,2	1,54019	,905172	,903411	1985,88	374,912	12,3694	CRS
18:12:12,852	41565,7	1,54627	,90603	,904239	1991,5	376,399	12,4629	CRS
18:13:22,852	41683,1	1,55126	,905384	,903614	1997,16	377,617	12,3926	CRS
18:14:32,850	41800,5	1,55617	,904849	,903101	2002,81	378,815	12,3342	CRS
18:15:42,850	41918	1,56122	,904858	,903123	2008,47	380,047	12,3352	CRS
18:16:52,849	42035,4	1,56646	,904742	,903021	2014,12	381,328	12,3225	CRS
18:18:02,848	42152,8	1,57262	,905124	,903386	2019,73	382,831	12,3642	CRS
18:19:12,849	42270,3	1,57793	,904794	,903063	2025,38	384,127	12,3282	CRS
18:20:22,847	42387,8	1,58442	,905764	,903991	2030,99	385,711	12,4339	CRS
18:21:32,847	42505,2	1,59026	,905695	,903935	2036,61	387,139	12,4264	CRS
18:22:42,847	42622,7	1,59571	,905067	,903328	2042,25	388,468	12,3579	CRS
18:23:52,845	42740,2	1,60104	,90459	,90288	2047,9	389,771	12,3059	CRS
18:25:02,845	42857,5	1,6074	,906156	,904396	2053,51	391,324	12,4766	CRS
18:26:12,844	42975	1,61579	,909991	,908257	2059,05	393,37	12,8947	CRS
18:27:22,843	43092,5	1,62296	,911016	,909284	2064,63	395,123	13,0065	CRS
18:28:32,843	43209,9	1,62926	,911561	,909836	2070,24	396,659	13,0658	CRS
18:29:42,842	43327,3	1,63574	,91252	,910791	2075,85	398,241	13,1704	CRS
18:30:52,842	43444,8	1,64188	,912437	,91071	2081,47	399,741	13,1613	CRS
18:32:02,841	43562,3	1,64879	,913347	,911609	2087,06	401,429	13,2605	CRS
18:33:12,840	43679,7	1,65601	,913854	,912111	2092,64	403,191	13,3157	CRS
18:34:22,840	43797,2	1,6611	,911818	,910101	2098,3	404,432	13,0939	CRS
18:35:32,839	43914,7	1,66689	,911276	,909555	2103,93	405,848	13,0348	CRS
18:36:42,838	44032	1,67228	,910189	,908469	2109,57	407,164	12,9162	CRS
18:37:52,838	44149,5	1,67748	,908979	,907268	2115,23	408,432	12,7843	CRS
18:39:02,837	44267	1,68344	,909306	,907596	2120,86	409,887	12,82	CRS
18:40:12,837	44384,3	1,68926	,909171	,907458	2126,48	411,308	12,8053	CRS
18:41:22,836	44501,8	1,6946	,908257	,906549	2132,13	412,612	12,7056	CRS
18:42:32,836	44619,3	1,70019	,908347	,906649	2137,77	413,978	12,7155	CRS
18:43:42,836	44736,7	1,70565	,907833	,906124	2143,42	415,31	12,6595	CRS
18:44:52,834	44854,2	1,71198	,90895	,90725	2149,03	416,856	12,7812	CRS
18:46:02,834	44971,7	1,7181	,909315	,907613	2154,66	418,349	12,8211	CRS
18:47:12,833	45089,1	1,72454	,909622	,907933	2160,26	419,922	12,8545	CRS
18:48:22,832	45206,5	1,73328	,913636	,911923	2165,8	422,056	13,2919	CRS
18:49:32,832	45324	1,74176	,916196	,9145	2171,34	424,127	13,571	CRS
18:50:42,832	45441,5	1,74966	,916776	,915089	2176,91	426,054	13,6343	CRS
18:51:52,831	45558,8	1,7571	,91732	,915644	2182,48	427,872	13,6936	CRS
18:53:02,831	45676,3	1,76228	,914044	,912335	2188,14	429,136	13,3364	CRS
18:54:12,829	45793,8	1,76845	,913262	,911571	2193,76	430,644	13,2512	CRS
18:55:22,828	45911,2	1,77443	,912419	,910742	2199,38	432,104	13,1593	CRS
18:56:32,828	46028,7	1,78137	,912898	,911219	2204,98	433,798	13,2116	CRS
18:57:42,828	46146,2	1,789	,913652	,91196	2210,56	435,659	13,2938	CRS
18:58:52,827	46263,6	1,79545	,91305	,911376	2216,17	437,236	13,2282	CRS
19:00:02,826	46381	1,80281	,914009	,912314	2221,75	439,032	13,3326	CRS
19:01:12,826	46498,5	1,81054	,915337	,913654	2227,33	440,919	13,4774	CRS
19:02:22,825	46615,9	1,81761	,915752	,914077	2232,92	442,645	13,5227	CRS
19:03:32,824	46733,3	1,8244	,915502	,913825	2238,52	444,302	13,4954	CRS
19:04:42,824	46850,8	1,83203	,916777	,915121	2244,1	446,167	13,6344	CRS
19:05:52,824	46968,3	1,83949	,917441	,915791	2249,68	447,987	13,7067	CRS
19:07:02,822	47085,7	1,84628	,917141	,915494	2255,28	449,646	13,674	CRS
19:08:12,822	47203,2	1,8533	,9174	,915761	2260,88	451,359	13,7022	CRS
19:09:22,821	47320,7	1,86084	,918117	,916474	2266,46	453,201	13,7804	CRS
19:10:32,820	47438	1,8688	,919154	,917508	2272,02	455,145	13,8935	CRS
19:11:42,820	47555,5	1,87697	,919858	,918201	2277,58	457,139	13,9702	CRS
19:12:52,820	47673	1,88453	,919478	,917826	2283,16	458,983	13,9287	CRS
19:14:02,819	47790,4	1,89322	,920881	,91922	2288,7	461,105	14,0817	CRS
19:15:12,818	47907,8	1,90069	,92036	,9187	2294,28	462,93	14,0249	CRS
19:16:22,817	48025,3	1,90862	,920701	,91904	2299,85	464,865	14,062	CRS
19:17:32,817	48142,8	1,91626	,920322	,918669	2305,43	466,73	14,0207	CRS
19:18:42,817	48260,2	1,92382	,920354	,918711	2311,01	468,576	14,0242	CRS
19:19:52,815	48377,7	1,93127	,920546	,918892	2316,59	470,396	14,0452	CRS
19:21:02,815	48495,1	1,93867	,920806	,919164	2322,18	472,202	14,0735	CRS
19:22:12,815	48612,5	1,94739	,922761	,921132	2327,72	474,332	14,2866	CRS
19:23:22,813	48730	1,95571	,923215	,921589	2333,28	476,362	14,3361	CRS
19:24:32,814	48847,5	1,9644	,924424	,922802	2338,83	478,484	14,4679	CRS
19:25:42,812	48964,8	1,97149	,922893	,921274	2344,42	480,215	14,301	CRS
19:26:52,812	49082,3	1,97824	,921928	,920302	2350,03	481,864	14,1958	CRS
19:28:02,812	49199,8	1,98652	,922536	,920915	2355,59	483,886	14,2621	CRS
19:29:12,811	49317,2	1,99318	,920792	,919161	2361,2	485,512	14,072	CRS
19:30:22,810	49434,7	1,9996	,91915	,917553	2366,82	487,079	13,8931	CRS
19:31:32,810	49552,2	2,00576	,917424	,915835	2372,45	488,583	13,7049	CRS
19:32:42,808	49669,6	2,01266	,91668	,915098	2378,05	490,266	13,6237	CRS
19:33:52,808	49787	2,0206	,917583	,916009	2383,62	492,206	13,7222	CRS
19:35:02,808	49904,5	2,02843	,917993	,916412	2389,2	494,117	13,7669	CRS
19:36:12,806	50022	2,03571	,917507	,915933	2394,79	495,894	13,7139	CRS
19:37:22,807	50139,3	2,04337	,917745	,916168	2400,37	497,764	13,7398	CRS
19:38:32,806	50256,8	2,05056	,917522	,915951	2405,97	499,521	13,7156	CRS
19:39:42,805	50374,3	2,05871	,918736	,917165	2411,54	501,51	13,8478	CRS
19:40:52,804	50491,7	2,06792	,920743	,919148	2417,06	503,759	14,0666	CRS
19:42:02,804	50609,2	2,07706	,922082	,920498	2422,6	505,989	14,2127	CRS
19:43:12,803	50726,7	2,08632	,923478	,92191	2428,13	508,252	14,3648	CRS
19:44:22,803	50844	2,09509	,92409	,922524	2433,68	510,393	14,4315	CRS
19:45:32,802	50961,5	2,10477	,925869	,924297	2439,19	512,755	14,6253	CRS
19:46:42,802	51079	2,11457	,926988	,92543	2444,71	515,148	14,7474	CRS
19:47:52,800	51196,4	2,12398	,926936	,92538	2450,24	517,446	14,7417	CRS
19:49:02,800	51313,8	2,1338	,928239	,926683	2455,75	519,842	14,8837	CRS
19:50:12,800	51431,3	2,14287	,928236	,926685	2461,29	522,058	14,8834	CRS
19:51:22,798	51548,8	2,15265	,92854	,926992	2466,81	524,444	14,9166	CRS
19:52:32,798	51666,2	2,16117	,92785	,926307	2472,36	526,525	14,8413	CRS
19:53:42,798	51783,7	2,16963	,927436	,925895	2477,92	528,592	14,7962	CRS
19:54:52,797	51901,2	2,17877	,927619	,926083	2483,46	530,822	14,8161	CRS
19:56:02,796	52018,5	2,1875	,927459	,925928	2489,01	532,953	14,7987	CRS
19:57:12,796	52136	2,19569	,926584	,925052	2494,58	534,953	14,7033	CRS
19:58:22,794	52253,5	2,20501	,927887	,926359	2500,11	537,228	14,8453	CRS
19:59:32,794	52370,9	2,21447	,928552	,927032	2505,64	539,539	14,9179	CRS
20:00:42,794	52488,3	2,22325	,928522	,927005	2511,19	541,682	14,9146	CRS
20:01:52,793	52605,8	2,23405	,930655	,929117	2516,68	544,319	15,1471	CRS
20:03:02,792	52723,2	2,24323	,930172	,928642	2522,22	546,56	15,0944	CRS
20:04:12,792	52840,7	2,25254	,930383	,92886	2527,75	548,833	15,1174	CRS
20:05:22,791	52958,2	2,26104	,928613	,927112	2533,31	550,91	14,9245	CRS
20:06:32,791	53075,6	2,26973	,927705	,926201	2538,87	553,032	14,8255	CRS
20:07:42,790	53193	2,27993	,929096	,927589	2544,37	555,521	14,9771	CRS
20:08:52,790	53310,5	2,28997	,929775	,928277	2549,89	557,972	15,0511	CRS
20:10:02,789	53428	2,30145	,932127	,930607	2555,36	560,776	15,3075	CRS
20:11:12,788	53545,3	2,311	,931123	,929604	2560,88	563,107	15,1981	CRS
20:12:22,788	53662,8	2,32097	,931402	,929888	2566,4	565,541	15,2285	CRS
20:13:32,786	53780,3	2,3311	,932168	,930667	2571,92	568,014	15,3119	CRS
20:14:42,786	53897,7	2,3405	,931778	,93028	2577,45	570,31	15,2695	CRS
20:15:52,786	54015,2	2,35133	,933358	,931882	2582,94	572,953	15,4417	CRS
20:17:02,785	54132,7	2,36216	,93462	,933157	2588,43	575,598	15,5793	CRS
20:18:12,784	54250,1	2,37239	,935041	,933579	2593,94	578,094	15,6251	CRS
20:19:22,784	54367,5	2,38292	,935607	,934142	2599,44	580,666	15,6868	CRS
20:20:32,783	54485	2,39258	,935086	,933634	2604,97	583,024	15,63	CRS
20:21:42,783	54602,4	2,4025	,934634	,933186	2610,49	585,447	15,5808	CRS
20:22:52,782	54719,8	2,41256	,934799	,933355	2616	587,903	15,5987	CRS
20:24:02,781	54837,3	2,4215	,932814	,931352	2621,56	590,084	15,3823	CRS
20:25:12,781	54954,8	2,43194	,933637	,932189	2627,07	592,633	15,4721	CRS
20:26:22,780	55072,2	2,4424	,933426	,931982	2632,57	595,188	15,4491	CRS
20:27:32,779	55189,7	2,45282	,933483	,932046	2638,08	597,733	15,4553	CRS
20:28:42,779	55307,2	2,46262	,932383	,930936	2643,6	600,125	15,3354	CRS
20:29:52,778	55424,5	2,47258	,932262	,930812	2649,12	602,556	15,3222	CRS
20:31:02,777	55542	2,48309	,932723	,931289	2654,63	605,121	15,3725	CRS
20:32:12,777	55659,5	2,49498	,934997	,933578	2660,09	608,025	15,6204	CRS
20:33:22,776	55776,9	2,5074	,937214	,93578	2665,54	611,059	15,862	CRS
20:34:32,776	55894,3	2,52199	,941954	,940534	2670,92	614,62	16,3787	CRS
20:35:42,775	56011,8	2,53603	,94529	,943845	2676,32	618,047	16,7422	CRS
20:36:52,774	56129,3	2,54781	,944642	,943195	2681,79	620,923	16,6717	CRS
20:38:02,774	56246,7	2,56021	,945289	,943832	2687,23	623,951	16,7422	CRS
20:39:12,773	56364,2	2,57128	,944762	,943315	2692,73	626,653	16,6847	CRS
20:40:22,772	56481,7	2,58222	,943809	,942396	2698,22	629,325	16,5808	CRS
20:41:32,772	56599	2,59284	,942601	,941208	2703,72	631,917	16,4492	CRS
20:42:42,771	56716,5	2,60287	,940599	,939201	2709,25	634,368	16,231	CRS
20:43:52,770	56834	2,61366	,940105	,938719	2714,75	637,001	16,1771	CRS
20:45:02,770	56951,4	2,62387	,938905	,937513	2720,27	639,494	16,0463	CRS
20:46:12,769	57068,8	2,63482	,938831	,937439	2725,76	642,168	16,0382	CRS
20:47:22,769	57186,3	2,64633	,9397	,938318	2731,25	644,976	16,1329	CRS
20:48:32,768	57303,7	2,65702	,938461	,937078	2736,75	647,586	15,9979	CRS
20:49:42,767	57421,2	2,66845	,938863	,937484	2742,23	650,379	16,0417	CRS
20:50:52,767	57538,7	2,68021	,939638	,938268	2747,71	653,249	16,1262	CRS
20:52:02,766	57656,1	2,69124	,939259	,93789	2753,2	655,942	16,0849	CRS
20:53:12,765	57773,5	2,70311	,940253	,938898	2758,67	658,84	16,1932	CRS
20:54:22,765	57891	2,71515	,941513	,940162	2764,14	661,781	16,3305	CRS
20:55:32,764	58008,5	2,72733	,942596	,941259	2769,6	664,754	16,4486	CRS
20:56:42,764	58125,8	2,74049	,94429	,94292	2775,03	667,966	16,6333	CRS
20:57:52,763	58243,3	2,75233	,944032	,942673	2780,51	670,856	16,6051	CRS
20:59:02,762	58360,8	2,76482	,944745	,943377	2785,96	673,906	16,6828	CRS
21:00:12,762	58478,2	2,77687	,94401	,942667	2791,43	676,848	16,6028	CRS
21:01:22,761	58595,7	2,78834	,943	,941679	2796,92	679,648	16,4926	CRS
21:02:32,760	58713,2	2,79963	,941763	,940448	2802,41	682,405	16,3578	CRS
21:03:42,760	58830,6	2,81224	,942804	,941489	2807,86	685,484	16,4713	CRS
21:04:52,759	58948	2,82723	,946205	,944861	2813,24	689,145	16,842	CRS
21:06:02,758	59065,5	2,84145	,947123	,945802	2818,65	692,617	16,942	CRS
21:07:12,758	59182,9	2,85392	,946364	,945045	2824,1	695,661	16,8594	CRS
21:08:22,757	59300,3	2,86715	,947236	,945932	2829,54	698,891	16,9544	CRS
21:09:32,757	59417,8	2,8806	,948204	,946901	2834,97	702,175	17,0599	CRS
21:10:42,756	59535,3	2,89443	,94993	,948637	2840,39	705,551	17,2481	CRS
21:11:52,755	59652,7	2,90913	,952005	,950725	2845,78	709,141	17,4742	CRS
21:13:02,755	59770,2	2,92114	,950444	,949171	2851,25	712,072	17,3041	CRS
21:14:12,754	59887,7	2,93472	,95129	,950019	2856,69	715,387	17,3963	CRS
21:15:22,753	60005	2,94723	,950544	,949273	2862,14	718,443	17,3149	CRS
21:16:32,753	60122,5	2,95826	,948248	,946966	2867,64	721,136	17,0647	CRS
21:17:42,752	60240	2,97122	,94858	,947307	2873,09	724,298	17,1009	CRS
21:18:52,751	60357,4	2,98399	,94836	,947094	2878,54	727,417	17,0769	CRS
21:20:02,751	60474,8	2,99625	,947189	,945921	2884,01	730,412	16,9493	CRS
21:21:12,750	60592,3	3,00711	,944483	,943211	2889,52	733,062	16,6543	CRS
21:22:22,750	60709,8	3,01944	,944308	,943049	2894,99	736,073	16,6352	CRS
21:23:32,749	60827,2	3,03276	,945319	,944042	2900,43	739,324	16,7455	CRS
21:24:42,748	60944,7	3,04445	,943183	,941956	2905,92	742,18	16,5126	CRS
21:25:52,748	61062,1	3,05861	,945127	,943856	2911,33	745,636	16,7245	CRS
21:27:02,747	61179,5	3,07423	,948941	,947709	2916,7	749,449	17,1402	CRS
21:28:12,746	61297	3,08841	,949384	,948161	2922,12	752,912	17,1886	CRS
21:29:22,746	61414,5	3,1052	,953937	,952728	2927,46	757,011	17,6848	CRS
21:30:32,745	61531,9	3,11948	,953178	,951982	2932,87	760,497	17,6021	CRS
21:31:42,745	61649,3	3,13421	,954256	,953052	2938,27	764,094	17,7196	CRS
21:32:52,744	61766,8	3,14916	,955827	,954612	2943,67	767,743	17,8908	CRS
21:34:02,743	61884,2	3,16231	,954069	,952876	2949,11	770,955	17,6991	CRS
21:35:12,742	62001,7	3,17639	,953523	,952349	2954,53	774,392	17,6396	CRS
21:36:22,742	62119,2	3,19104	,954711	,953525	2959,94	777,968	17,7692	CRS
21:37:32,741	62236,6	3,20429	,952791	,951623	2965,39	781,203	17,5599	CRS
21:38:42,741	62354	3,21854	,953003	,951837	2970,8	784,684	17,583	CRS
21:39:52,740	62471,5	3,23346	,953893	,952737	2976,2	788,324	17,68	CRS
21:41:02,739	62589	3,24774	,953514	,952364	2981,62	791,812	17,6387	CRS
21:42:12,739	62706,3	3,26336	,955035	,953873	2987	795,626	17,8045	CRS
21:43:22,738	62823,8	3,27773	,953719	,952577	2992,42	799,134	17,6611	CRS
21:44:32,738	62941,3	3,29267	,955077	,953921	2997,82	802,781	17,8091	CRS
21:45:42,737	63058,7	3,3077	,955691	,954541	3003,21	806,45	17,876	CRS
21:46:52,736	63176,2	3,32224	,955343	,954205	3008,62	810,001	17,8381	CRS
21:48:02,736	63293,7	3,33847	,957449	,956313	3013,99	813,963	18,0676	CRS
21:49:12,735	63411	3,35512	,960371	,959254	3019,34	818,028	18,3861	CRS
21:50:22,734	63528,5	3,37224	,962057	,96093	3024,68	822,208	18,5699	CRS
21:51:32,734	63646	3,38755	,961657	,960538	3030,08	825,946	18,5263	CRS
21:52:42,733	63763,4	3,40504	,963039	,961911	3035,41	830,217	18,6769	CRS
21:53:52,732	63880,8	3,42196	,964476	,963376	3040,75	834,347	18,8335	CRS
21:55:02,732	63998,3	3,43683	,962915	,961805	3046,16	837,978	18,6634	CRS
21:56:12,731	64115,8	3,45222	,962788	,961688	3051,56	841,735	18,6495	CRS
21:57:22,731	64233,2	3,46792	,96249	,961398	3056,93	845,568	18,617	CRS
21:58:32,730	64350,7	3,48251	,96078	,959704	3062,35	849,13	18,4307	CRS
21:59:42,729	64468,2	3,49885	,960647	,959585	3067,72	853,119	18,4162	CRS
22:00:52,729	64585,5	3,51483	,961773	,960697	3073,09	857,021	18,5389	CRS
22:02:02,728	64703	3,53154	,961455	,960396	3078,45	861,102	18,5043	CRS
22:03:12,727	64820,5	3,54836	,962575	,961507	3083,81	865,208	18,6264	CRS
22:04:22,727	64937,9	3,56412	,962441	,961374	3089,19	869,057	18,6117	CRS
22:05:32,726	65055,3	3,58031	,963443	,962386	3094,57	873,009	18,721	CRS
22:06:42,725	65172,8	3,59655	,963111	,962057	3099,94	876,973	18,6848	CRS
22:07:52,725	65290,2	3,61161	,962267	,961219	3105,35	880,65	18,5928	CRS
22:09:02,724	65407,7	3,62714	,962631	,961584	3110,74	884,442	18,6325	CRS
22:10:12,723	65525,2	3,64208	,961245	,960225	3116,15	888,089	18,4814	CRS
22:11:22,723	65642,6	3,6576	,960676	,959666	3121,55	891,88	18,4193	CRS
22:12:32,722	65760	3,67316	,959801	,958801	3126,94	895,677	18,324	CRS
22:13:42,722	65877,5	3,68865	,958799	,95781	3132,34	899,459	18,2148	CRS
22:14:52,721	65995	3,70375	,958608	,957621	3137,75	903,147	18,1939	CRS
22:16:02,720	66112,3	3,7186	,95707	,956074	3143,16	906,772	18,0263	CRS
22:17:12,720	66229,8	3,73351	,955508	,954512	3148,58	910,411	17,856	CRS
22:18:22,719	66347,3	3,75132	,958046	,957067	3153,91	914,76	18,1327	CRS
22:19:32,718	66464,7	3,76822	,95883	,957862	3159,27	918,887	18,2181	CRS
22:20:42,718	66582,2	3,78584	,960533	,959568	3164,61	923,19	18,4037	CRS
22:21:52,717	66699,7	3,80397	,961856	,960882	3169,94	927,614	18,5479	CRS
22:23:02,717	66817,1	3,82147	,962694	,961721	3175,28	931,888	18,6393	CRS
22:24:12,716	66934,5	3,84119	,966305	,965358	3180,57	936,702	19,0329	CRS
22:25:22,715	67052	3,86032	,968521	,967578	3185,87	941,373	19,2744	CRS
22:26:32,715	67169,4	3,88022	,970749	,969812	3191,15	946,232	19,5173	CRS
22:27:42,714	67286,8	3,89893	,971428	,970496	3196,46	950,801	19,5913	CRS
22:28:52,713	67404,3	3,91745	,97189	,970965	3201,78	955,32	19,6417	CRS
22:30:02,713	67521,8	3,93684	,973375	,972442	3207,08	960,055	19,8036	CRS
22:31:12,712	67639,2	3,95471	,972205	,971284	3212,42	964,418	19,676	CRS
22:32:22,711	67756,7	3,97289	,971526	,970616	3217,75	968,857	19,602	CRS
22:33:32,711	67874,2	3,9912	,971154	,970247	3223,08	973,328	19,5614	CRS
22:34:42,710	67991,5	4,00982	,971438	,970548	3228,4	977,874	19,5924	CRS
22:35:52,709	68109	4,02821	,971522	,970637	3233,72	982,362	19,6015	CRS
22:37:02,709	68226,5	4,04674	,971592	,970709	3239,05	986,888	19,6091	CRS
22:38:12,708	68343,9	4,06515	,971237	,970368	3244,37	991,383	19,5705	CRS
22:39:22,708	68461,3	4,08382	,971523	,970659	3249,69	995,941	19,6017	CRS
22:40:32,707	68578,8	4,10361	,973114	,972244	3254,99	1000,77	19,7751	CRS
22:41:42,706	68696,3	4,12288	,973881	,973017	3260,29	1005,48	19,8587	CRS
22:42:52,706	68813,7	4,14322	,97618	,975336	3265,57	1010,44	20,1093	CRS
22:44:02,705	68931,2	4,16227	,975349	,974506	3270,89	1015,1	20,0187	CRS
22:45:12,704	69048,7	4,18245	,977162	,976326	3276,17	1020,02	20,2164	CRS
22:46:22,704	69166	4,20132	,976413	,975592	3281,48	1024,63	20,1347	CRS
22:47:32,703	69283,5	4,22086	,976166	,975347	3286,79	1029,4	20,1078	CRS
22:48:42,702	69401	4,24165	,977846	,977016	3292,06	1034,48	20,2909	CRS
22:49:52,702	69518,4	4,26165	,977939	,977107	3297,35	1039,36	20,301	CRS
22:51:02,701	69635,8	4,28207	,978057	,977236	3302,63	1044,34	20,3138	CRS
22:52:12,700	69753,3	4,30189	,978029	,977213	3307,93	1049,18	20,3108	CRS
22:53:22,700	69870,7	4,32099	,976683	,975906	3313,24	1053,85	20,1642	CRS
22:54:32,699	69988,2	4,34159	,977703	,976916	3318,52	1058,87	20,2753	CRS
22:55:42,699	70105,7	4,36206	,978121	,977321	3323,8	1063,87	20,3209	CRS
22:56:52,698	70223,1	4,38184	,97748	,97671	3329,1	1068,7	20,251	CRS
22:58:02,698	70340,5	4,40348	,979474	,978681	3334,35	1073,99	20,4684	CRS
22:59:12,697	70458	4,4229	,978814	,978026	3339,66	1078,73	20,3964	CRS
23:00:22,696	70575,5	4,44413	,980124	,979374	3344,93	1083,91	20,5392	CRS
23:01:32,695	70692,8	4,46403	,979728	,978964	3350,22	1088,77	20,496	CRS
23:02:42,695	70810,3	4,48475	,980105	,979368	3355,5	1093,83	20,5371	CRS
23:03:52,694	70927,8	4,50491	,980364	,979649	3360,8	1098,75	20,5653	CRS
23:05:02,694	71045,2	4,52662	,982102	,9814	3366,05	1104,05	20,7548	CRS
23:06:12,693	71162,7	4,54758	,981772	,981082	3371,33	1109,17	20,7188	CRS
23:07:22,692	71280,2	4,56729	,980021	,979306	3376,64	1113,98	20,5279	CRS
23:08:32,692	71397,6	4,58644	,978024	,977304	3381,96	1118,66	20,3102	CRS
23:09:42,692	71515	4,60668	,977967	,977261	3387,25	1123,6	20,3041	CRS
23:10:52,690	71632,5	4,62814	,978714	,978004	3392,52	1128,84	20,3855	CRS
23:12:02,690	71749,9	4,65076	,980294	,979629	3397,75	1134,36	20,5577	CRS
23:13:12,689	71867,3	4,67522	,984276	,98362	3402,93	1140,33	20,9917	CRS
23:14:22,688	71984,8	4,69941	,986652	,986003	3408,13	1146,24	21,2507	CRS
23:15:32,688	72102,3	4,72328	,987956	,987306	3413,33	1152,06	21,3929	CRS
23:16:42,687	72219,7	4,74696	,989163	,988521	3418,54	1157,85	21,5245	CRS
23:17:52,686	72337,2	4,77002	,989597	,988962	3423,77	1163,48	21,5718	CRS
23:19:02,686	72454,7	4,79357	,990489	,989864	3428,98	1169,23	21,669	CRS
23:20:12,685	72572	4,81724	,992204	,991576	3434,19	1175	21,8559	CRS
23:21:22,685	72689,5	4,84058	,992594	,991979	3439,41	1180,7	21,8984	CRS
23:22:32,684	72807	4,86428	,99343	,992828	3444,63	1186,49	21,9896	CRS
23:23:42,684	72924,4	4,88646	,991971	,991365	3449,87	1191,9	21,8305	CRS
23:24:52,683	73041,8	4,90986	,992419	,991823	3455,1	1197,62	21,8793	CRS
23:26:02,682	73159,3	4,93207	,991325	,990733	3460,35	1203,04	21,7601	CRS
23:27:12,681	73276,8	4,95388	,98975	,98919	3465,61	1208,37	21,5884	CRS
23:28:22,681	73394,2	4,97682	,990009	,989445	3470,85	1213,97	21,6166	CRS
23:29:32,680	73511,7	4,99989	,990219	,989666	3476,08	1219,6	21,6396	CRS
23:30:42,679	73629,1	5,0231	,990017	,989469	3481,31	1225,27	21,6176	CRS
23:31:52,679	73746,5	5,04664	,990388	,989846	3486,53	1231,01	21,6579	CRS
23:33:02,678	73864	5,06946	,989478	,988952	3491,77	1236,58	21,5587	CRS
23:34:12,678	73981,5	5,09287	,989985	,989469	3497	1242,3	21,614	CRS
23:35:22,678	74098,9	5,1175	,991638	,991123	3502,19	1248,31	21,7943	CRS
23:36:32,676	74216,3	5,14177	,992523	,992013	3507,4	1254,24	21,8906	CRS
23:37:42,676	74333,8	5,16808	,995464	,994968	3512,56	1260,66	22,2113	CRS
23:38:52,676	74451,2	5,19261	,995974	,995489	3517,75	1266,65	22,2668	CRS
23:40:02,674	74568,7	5,21795	,996817	,996339	3522,94	1272,84	22,3587	CRS
23:41:12,674	74686,2	5,2414	,99564	,995173	3528,17	1278,56	22,2304	CRS
23:42:22,674	74803,6	5,26522	,995062	,994603	3533,39	1284,38	22,1675	CRS
23:43:32,672	74921	5,29162	,997529	,997066	3538,54	1290,82	22,4363	CRS
23:44:42,672	75038,5	5,3198	1,00095	1,0005	3543,66	1297,7	22,8089	CRS
23:45:52,672	75156	5,34466	,999287	,998841	3548,85	1303,77	22,628	CRS
23:47:02,671	75273,3	5,36957	,998747	,998316	3554,05	1309,86	22,5691	CRS
23:48:12,670	75390,8	5,39429	,998194	,997768	3559,25	1315,89	22,5089	CRS
23:49:22,670	75508,3	5,42071	,999366	,998953	3564,41	1322,34	22,6365	CRS
23:50:32,669	75625,7	5,44654	1,00012	,999722	3569,58	1328,65	22,7187	CRS
23:51:42,668	75743,2	5,47105	,998498	,998097	3574,79	1334,63	22,542	CRS
23:52:52,667	75860,7	5,49711	,999484	,999101	3579,97	1340,99	22,6494	CRS
23:54:02,667	75978	5,52238	,999762	,999388	3585,16	1347,16	22,6797	CRS
23:55:12,666	76095,5	5,54685	,99826	,997886	3590,37	1353,14	22,516	CRS
23:56:22,665	76213	5,57299	,999788	,99943	3595,54	1359,52	22,6826	CRS
23:57:32,665	76330,4	5,59835	,999685	,999341	3600,73	1365,71	22,6713	CRS
23:58:42,664	76447,8	5,62378	,999676	,999339	3605,92	1371,92	22,6704	CRS
23:59:52,664	76565,3	5,64836	,998832	,998497	3611,14	1377,92	22,5783	CRS
00:01:02,663	76682,8	5,6729	,997391	,997069	3616,35	1383,92	22,4213	CRS
00:02:12,662	76800,2	5,69784	,997016	,996695	3621,55	1390	22,3804	CRS
00:03:22,662	76917,7	5,72167	,99512	,994817	3626,79	1395,82	22,1738	CRS
00:04:32,661	77035,2	5,74768	,99626	,99597	3631,97	1402,17	22,298	CRS
00:05:42,660	77152,5	5,7745	,997115	,996828	3637,13	1408,72	22,3912	CRS
00:06:52,660	77270	5,80139	,997934	,99765	3642,29	1415,28	22,4804	CRS
00:08:02,659	77387,5	5,83009	1,00045	1,00019	3647,41	1422,29	22,7549	CRS
00:09:12,658	77504,9	5,85778	1,00097	1,00071	3652,54	1429,05	22,8111	CRS
00:10:22,658	77622,3	5,88599	1,00255	1,00229	3657,67	1435,94	22,9834	CRS
00:11:32,658	77739,8	5,91433	1,00412	1,00387	3662,8	1442,86	23,1543	CRS
00:12:42,657	77857,2	5,94227	1,00461	1,00438	3667,94	1449,68	23,2084	CRS
00:13:52,656	77974,7	5,97131	1,00668	1,00645	3673,05	1456,77	23,4334	CRS
00:15:02,656	78092,2	6,00015	1,00816	1,00795	3678,17	1463,81	23,5954	CRS
00:16:12,654	78209,6	6,02927	1,00916	1,00896	3683,28	1470,92	23,7041	CRS
00:17:22,654	78327	6,05849	1,01077	1,01058	3688,38	1478,06	23,8799	CRS
00:18:32,654	78444,5	6,08625	1,0091	1,00892	3693,53	1484,83	23,6978	CRS
00:19:42,653	78562	6,11505	1,00996	1,00979	3698,65	1491,87	23,7912	CRS
00:20:52,652	78679,3	6,14397	1,01056	1,01039	3703,77	1498,93	23,8565	CRS
00:22:02,652	78796,8	6,17209	1,0097	1,00955	3708,91	1505,79	23,7631	CRS
00:23:12,651	78914,3	6,20044	1,00913	1,00898	3714,05	1512,71	23,7013	CRS
00:24:22,650	79031,7	6,22877	1,009	1,00887	3719,18	1519,63	23,6869	CRS
00:24:57,650	79090,5	6,24491	1,01256	1,01243	3721,7	1523,57	24,0745	CRS