File: Example - Raw files/Ødo 2015/G2-2_CRS_D9-4m.lvm
Oedometer-1	12.10.2015
*Header*
Operator	G2-2_2015
Site	Stjørdal
Hole
Depth [m]	9,4
Comment
Sample area [cm2]	20
Sample height [mm]	20
*Calibration data *
Motor [steps/rev]	2000
Jack [µm/rev]	217
Load cell fact. [N/V]	490
Pore sens. fact. [kPa/V]	109,3
LVDT fact. [µm/V]	0
SelfDeform factor	3,43129
SelfDeform exp	,534907
Slack [steps]	50

        		Load	Pore			Vertica	Pore
Mean        	Deform.	cell	sens.	LVDT.	Deforma	stress	pressur
time        	[steps]	[V]	[V]	[V]	[µm]	[kPa]	[kPa]	MODE
------------	-------	-------	-------	-------	-------	-------	-------	-------
11:08:04,317	0	-,00179	1,4683	0	-0	0	0	ZERO
11:09:54,317	83,64	,011083	1,5105	1,50913	-,11664	3,15492	4,61233	CRS
11:11:49,317	171,96	,013568	1,51292	1,51155	8,55639	3,76367	4,87747	CRS
11:13:44,316	260,28	,016038	1,51573	1,51436	17,3002	4,36896	5,18429	CRS
11:15:39,316	348,6	,017758	1,51715	1,51578	26,3307	4,79031	5,33915	CRS
11:17:34,315	436,96	,019223	1,51797	1,5166	35,4649	5,14924	5,42937	CRS
11:19:29,315	525,28	,020577	1,5188	1,51743	44,6419	5,48101	5,52005	CRS
11:21:24,314	613,56	,021883	1,52008	1,51872	53,8397	5,801	5,65977	CRS
11:23:19,314	701,88	,02313	1,52163	1,52028	63,0682	6,10633	5,8296	CRS
11:25:14,313	790,28	,024154	1,52281	1,52146	72,3747	6,35724	5,95879	CRS
11:27:09,313	878,56	,02497	1,5234	1,52205	81,7296	6,55727	6,02331	CRS
11:29:04,313	966,88	,025675	1,52365	1,5223	91,122	6,72999	6,05024	CRS
11:30:59,312	1055,2	,026608	1,52433	1,52296	100,456	6,95864	6,12485	CRS
11:32:54,311	1143,56	,027569	1,525	1,52365	109,791	7,19388	6,19814	CRS
11:34:49,311	1231,88	,028094	1,52464	1,52327	119,238	7,32266	6,15791	CRS
11:36:44,311	1320,2	,028711	1,52409	1,52273	128,662	7,47367	6,09774	CRS
11:38:39,311	1408,5	,029302	1,52321	1,52185	138,092	7,61847	6,0022	CRS
11:40:34,310	1496,8	,030487	1,52325	1,52189	147,375	7,90899	6,00657	CRS
11:42:29,309	1585,2	,03171	1,52315	1,52179	156,665	8,20857	5,99568	CRS
11:44:24,309	1673,5	,032492	1,52181	1,52045	166,055	8,40009	5,84867	CRS
11:46:19,309	1761,8	,033629	1,52103	1,51968	175,362	8,67871	5,76326	CRS
11:48:14,308	1850,12	,034846	1,51978	1,51841	184,657	8,97698	5,62736	CRS
11:50:09,307	1938,5	,036896	1,51973	1,51838	193,771	9,47904	5,62178	CRS
11:52:04,307	2026,8	,038649	1,51855	1,5172	202,954	9,90867	5,49264	CRS
11:53:59,306	2115,12	,040299	1,51675	1,51539	212,171	10,3129	5,2955	CRS
11:55:54,306	2203,44	,042323	1,51508	1,51373	221,313	10,8087	5,11327	CRS
11:57:49,305	2291,78	,044571	1,51361	1,51225	230,419	11,3595	4,95324	CRS
11:59:44,305	2380,12	,047465	1,51289	1,51153	239,404	12,0685	4,87355	CRS
12:01:39,305	2468,44	,050317	1,51149	1,51014	248,411	12,7673	4,72062	CRS
12:03:34,304	2556,72	,053097	1,50912	1,50776	257,442	13,4483	4,46149	CRS
12:05:29,303	2645,04	,056145	1,50691	1,50556	266,439	14,1951	4,22053	CRS
12:07:24,303	2733,44	,059797	1,50564	1,50429	275,347	15,0899	4,08129	CRS
12:09:19,303	2821,72	,063624	1,50463	1,50329	284,23	16,0275	3,97139	CRS
12:11:14,302	2910,04	,067744	1,50389	1,50253	293,085	17,0368	3,89038	CRS
12:13:09,302	2998,38	,0717	1,50284	1,50147	301,989	18,0061	3,77547	CRS
12:15:04,301	3086,72	,075678	1,5018	1,50044	310,906	18,9808	3,66243	CRS
12:16:59,301	3175,04	,080415	1,50159	1,50024	319,715	20,1412	3,63859	CRS
12:18:54,301	3263,36	,085307	1,50167	1,50033	328,52	21,3398	3,64792	CRS
12:20:49,300	3351,64	,089929	1,50123	1,49987	337,381	22,4722	3,59929	CRS
12:22:44,299	3440	,09463	1,50064	1,49931	346,257	23,624	3,53566	CRS
12:24:39,298	3528,36	,099478	1,50006	1,49874	355,126	24,8116	3,47167	CRS
12:26:34,298	3616,64	,105455	1,50088	1,49954	363,842	26,2761	3,56124	CRS
12:28:29,297	3704,96	,111263	1,50162	1,50026	372,607	27,699	3,64172	CRS
12:30:24,297	3793,28	,116424	1,50105	1,49972	381,48	28,9634	3,57965	CRS
12:32:19,297	3881,64	,122188	1,501	1,49966	390,291	30,3756	3,57455	CRS
12:34:14,296	3969,96	,128241	1,50083	1,49951	399,077	31,8586	3,55614	CRS
12:36:09,295	4058,28	,135196	1,50202	1,50068	407,764	33,5627	3,68608	CRS
12:38:04,295	4146,56	,141695	1,50249	1,50117	416,525	35,1549	3,73749	CRS
12:39:59,295	4234,96	,147877	1,50176	1,50043	425,355	36,6694	3,65747	CRS
12:41:54,295	4323,28	,154318	1,50118	1,49985	434,16	38,2475	3,59422	CRS
12:43:49,294	4411,56	,161549	1,50144	1,50012	442,882	40,0191	3,62271	CRS
12:45:44,293	4499,88	,16897	1,50221	1,50087	451,604	41,8373	3,7064	CRS
12:47:39,293	4588,22	,175849	1,50199	1,50067	460,407	43,5225	3,68222	CRS
12:49:34,293	4676,56	,182781	1,50139	1,50008	469,218	45,221	3,6168	CRS
12:51:29,293	4764,88	,190173	1,50133	1,50002	477,99	47,0319	3,6109	CRS
12:53:24,292	4853,2	,19756	1,50108	1,49977	486,777	48,8419	3,58333	CRS
12:55:19,291	4941,5	,205482	1,5016	1,50029	495,52	50,7828	3,63952	CRS
12:57:14,290	5029,88	,213345	1,50198	1,50067	504,292	52,7092	3,68156	CRS
12:59:09,290	5118,2	,221163	1,5017	1,5004	513,075	54,6245	3,65053	CRS
13:01:04,289	5206,5	,228837	1,50127	1,49996	521,884	56,5048	3,60352	CRS
13:02:59,289	5294,8	,237266	1,50158	1,50028	530,631	58,5697	3,63751	CRS
13:04:54,288	5383,2	,245981	1,50231	1,501	539,374	60,7049	3,71719	CRS
13:06:49,288	5471,5	,254456	1,50267	1,50138	548,143	62,7813	3,75726	CRS
13:08:44,287	5559,8	,262727	1,50224	1,50095	556,943	64,8078	3,71009	CRS
13:10:39,287	5648,12	,271007	1,50161	1,50033	565,757	66,8364	3,64148	CRS
13:12:34,287	5736,44	,280884	1,5027	1,50142	574,435	69,2563	3,76036	CRS
13:14:29,286	5824,8	,290417	1,50359	1,50232	583,164	71,5918	3,8578	CRS
13:16:24,286	5913,12	,299051	1,50325	1,50197	591,98	73,7072	3,82056	CRS
13:18:19,285	6001,44	,308154	1,50289	1,50162	600,766	75,9374	3,78078	CRS
13:20:14,285	6089,72	,31716	1,50214	1,50087	609,566	78,1438	3,69944	CRS
13:22:09,285	6178,12	,327777	1,50333	1,50207	618,253	80,7451	3,82924	CRS
13:24:04,284	6266,44	,337508	1,50396	1,50272	627,019	83,129	3,89827	CRS
13:25:59,283	6354,72	,346561	1,50336	1,50209	635,847	85,3471	3,83291	CRS
13:27:54,283	6443,04	,356393	1,5033	1,50204	644,625	87,756	3,8254	CRS
13:29:49,282	6531,42	,36644	1,50302	1,50178	653,403	90,2174	3,79483	CRS
13:31:44,282	6619,72	,377604	1,50455	1,50331	662,094	92,9525	3,96211	CRS
13:33:39,281	6708,04	,387928	1,50501	1,5038	670,864	95,482	4,01285	CRS
13:35:34,281	6796,36	,397801	1,5041	1,50288	679,68	97,9009	3,91308	CRS
13:37:29,280	6884,64	,408033	1,50382	1,50258	688,472	100,408	3,8827	CRS
13:39:24,279	6973,04	,418371	1,5036	1,50238	697,279	102,941	3,85842	CRS
13:41:19,279	7061,36	,42968	1,50499	1,50378	706,013	105,711	4,01043	CRS
13:43:14,279	7149,64	,440907	1,50578	1,50459	714,759	108,462	4,09728	CRS
13:45:09,279	7237,96	,451486	1,50511	1,50392	723,567	111,054	4,02403	CRS
13:47:04,278	7326,36	,461922	1,5047	1,50352	732,402	113,611	3,97925	CRS
13:48:59,277	7414,64	,47299	1,50458	1,5034	741,186	116,322	3,96551	CRS
13:50:54,277	7502,96	,484747	1,50583	1,50463	749,935	119,203	4,10186	CRS
13:52:49,277	7591,28	,495787	1,50603	1,50484	758,744	121,908	4,12377	CRS
13:54:44,277	7679,58	,506705	1,50565	1,50449	767,566	124,582	4,08247	CRS
13:56:39,276	7767,96	,517277	1,50525	1,50409	776,429	127,172	4,0395	CRS
13:58:34,275	7856,28	,529629	1,50596	1,50479	785,171	130,199	4,1161	CRS
14:00:29,275	7944,56	,541789	1,50705	1,50588	793,931	133,178	4,2355	CRS
14:02:24,274	8032,88	,553016	1,50708	1,50592	802,765	135,929	4,23914	CRS
14:04:19,273	8121,28	,564487	1,50695	1,50579	811,599	138,739	4,22508	CRS
14:06:14,273	8209,56	,575623	1,50596	1,50482	820,449	141,467	4,11698	CRS
14:08:09,273	8297,88	,588732	1,5074	1,50625	829,183	144,679	4,2736	CRS
14:10:04,272	8386,2	,600844	1,50842	1,50727	837,989	147,646	4,38493	CRS
14:11:59,271	8474,56	,612215	1,50802	1,50688	846,853	150,432	4,34204	CRS
14:13:54,271	8562,88	,623531	1,50694	1,50579	855,723	153,205	4,22421	CRS
14:15:49,271	8651,2	,635398	1,50662	1,50549	864,564	156,112	4,18917	CRS
14:17:44,270	8739,5	,648142	1,50804	1,5069	873,356	159,234	4,34443	CRS
14:19:39,269	8827,8	,659723	1,5083	1,50718	882,226	162,072	4,37258	CRS
14:21:34,269	8916,2	,671322	1,50785	1,50672	891,111	164,913	4,32365	CRS
14:23:29,269	9004,5	,683065	1,50738	1,50628	899,982	167,791	4,27143	CRS
14:25:24,269	9092,8	,694913	1,50721	1,50609	908,853	170,693	4,25317	CRS
14:27:19,267	9181,12	,707916	1,50874	1,50763	917,663	173,879	4,42057	CRS
14:29:14,267	9269,5	,719978	1,50903	1,50793	926,542	176,834	4,45244	CRS
14:31:09,267	9357,8	,73144	1,5083	1,5072	935,452	179,642	4,37255	CRS
14:33:04,265	9446,12	,74285	1,50782	1,50673	944,372	182,438	4,32022	CRS
14:34:59,265	9534,44	,754644	1,5076	1,50651	953,275	185,327	4,29626	CRS
14:36:54,265	9622,76	,76743	1,5087	1,50761	962,127	188,46	4,41627	CRS
14:38:49,265	9711,12	,779274	1,50923	1,50813	971,041	191,362	4,47354	CRS
14:40:44,264	9799,44	,791517	1,5093	1,50823	979,934	194,361	4,48124	CRS
14:42:39,264	9887,72	,803145	1,50875	1,50767	988,861	197,21	4,42151	CRS
14:44:34,263	9976,04	,817166	1,50997	1,50891	997,665	200,645	4,55516	CRS
14:46:29,263	10064,4	,831388	1,51139	1,51034	1006,47	204,13	4,70969	CRS
14:48:24,263	10152,7	,843238	1,51148	1,51043	1015,4	207,033	4,71992	CRS
14:50:19,262	10241	,854908	1,51057	1,50952	1024,35	209,892	4,61998	CRS
14:52:14,261	10329,4	,866785	1,5098	1,50876	1033,29	212,802	4,53661	CRS
14:54:09,261	10417,7	,881234	1,51127	1,51024	1042,1	216,342	4,6971	CRS
14:56:04,260	10506	,894724	1,51245	1,5114	1050,97	219,647	4,82548	CRS
14:57:59,259	10594,4	,906376	1,51176	1,51072	1059,93	222,502	4,75029	CRS
14:59:54,259	10682,6	,917996	1,51085	1,50983	1068,9	225,349	4,65105	CRS
15:01:49,259	10771	,930655	1,51057	1,50955	1077,82	228,45	4,61994	CRS
15:03:44,258	10859,4	,944897	1,51211	1,51109	1086,67	231,939	4,78841	CRS
15:05:39,257	10947,6	,958045	1,51323	1,51222	1095,57	235,161	4,91074	CRS
15:07:34,257	11036	,970051	1,5125	1,51148	1104,54	238,102	4,83113	CRS
15:09:29,257	11124,3	,983021	1,51203	1,51103	1113,46	241,28	4,78053	CRS
15:11:24,257	11212,6	,995984	1,5117	1,51069	1122,39	244,456	4,74373	CRS
15:13:19,256	11301	1,00989	1,51319	1,51219	1131,28	247,862	4,90675	CRS
15:15:14,255	11389,3	1,02277	1,51342	1,51244	1140,22	251,018	4,93211	CRS
15:17:09,255	11477,6	1,03555	1,51301	1,51202	1149,16	254,15	4,88697	CRS
15:19:04,255	11566	1,04773	1,51236	1,51138	1158,15	257,133	4,81594	CRS
15:20:59,254	11654,3	1,06101	1,5124	1,51143	1167,08	260,387	4,82059	CRS
15:22:54,253	11742,6	1,07587	1,51415	1,51318	1175,93	264,027	5,01218	CRS
15:24:49,253	11830,9	1,08976	1,51468	1,51371	1184,84	267,43	5,0697	CRS
15:26:44,252	11919,2	1,10296	1,51438	1,51342	1193,78	270,666	5,03728	CRS
15:28:39,252	12007,6	1,11544	1,5136	1,51265	1202,77	273,724	4,95126	CRS
15:30:34,251	12095,9	1,1301	1,51402	1,51307	1211,65	277,314	4,99733	CRS
15:32:29,251	12184,2	1,14511	1,51536	1,51442	1220,52	280,991	5,1437	CRS
15:34:24,251	12272,5	1,15839	1,51544	1,5145	1229,48	284,246	5,15268	CRS
15:36:19,250	12360,9	1,17153	1,51486	1,51393	1238,45	287,464	5,08919	CRS
15:38:14,249	12449,2	1,18457	1,51393	1,51299	1247,42	290,659	4,9872	CRS
15:40:09,249	12537,5	1,20057	1,51505	1,51412	1256,26	294,578	5,1098	CRS
15:42:04,249	12625,8	1,21561	1,51639	1,51546	1265,15	298,264	5,25605	CRS
15:43:59,248	12714,2	1,22864	1,51612	1,51521	1274,14	301,457	5,22705	CRS
15:45:54,248	12802,5	1,24225	1,51514	1,51424	1283,1	304,791	5,12003	CRS
15:47:49,247	12890,8	1,25633	1,51468	1,51378	1292,04	308,24	5,06952	CRS
15:49:44,246	12979,1	1,27277	1,51611	1,51522	1300,88	312,268	5,22607	CRS
15:51:39,245	13067,4	1,28752	1,51699	1,5161	1309,8	315,881	5,32258	CRS
15:53:34,245	13155,8	1,30095	1,51623	1,51535	1318,79	319,173	5,23936	CRS
15:55:29,245	13244,1	1,31515	1,5155	1,51463	1327,74	322,651	5,15967	CRS
15:57:24,245	13332,4	1,32982	1,51497	1,5141	1336,67	326,246	5,10186	CRS
15:59:19,244	13420,7	1,34604	1,51665	1,51578	1345,54	330,22	5,2851	CRS
16:01:14,243	13509,1	1,36181	1,51765	1,51678	1354,44	334,082	5,39449	CRS
16:03:09,243	13597,4	1,37662	1,51714	1,51629	1363,37	337,711	5,33808	CRS
16:05:04,243	13685,7	1,39139	1,51642	1,51557	1372,31	341,33	5,25998	CRS
16:06:59,242	13774	1,40741	1,51655	1,51569	1381,2	345,255	5,27422	CRS
16:08:54,242	13862,4	1,42421	1,51793	1,51708	1390,07	349,371	5,42501	CRS
16:10:49,241	13950,7	1,44102	1,51888	1,51806	1398,94	353,489	5,52918	CRS
16:12:44,241	14039	1,45692	1,51854	1,51772	1407,85	357,385	5,49199	CRS
16:14:39,240	14127,4	1,47222	1,51784	1,51703	1416,78	361,134	5,41554	CRS
16:16:34,239	14215,6	1,48932	1,51795	1,51713	1425,64	365,323	5,42732	CRS
16:18:29,239	14304	1,50746	1,51933	1,51853	1434,48	369,767	5,57834	CRS
16:20:24,238	14392,4	1,5239	1,51962	1,51881	1443,38	373,795	5,60919	CRS
16:22:19,238	14480,6	1,53975	1,51902	1,51822	1452,3	377,679	5,54382	CRS
16:24:14,237	14569	1,55504	1,51767	1,51688	1461,25	381,425	5,39701	CRS
16:26:09,237	14657,4	1,57421	1,51868	1,51791	1470,06	386,121	5,50647	CRS
16:28:04,237	14745,6	1,59268	1,5203	1,51954	1478,89	390,646	5,68448	CRS
16:29:59,236	14834	1,6086	1,51987	1,51911	1487,82	394,547	5,63655	CRS
16:31:54,236	14922,3	1,62539	1,51918	1,51841	1496,73	398,661	5,56133	CRS
16:33:49,235	15010,6	1,6422	1,51816	1,5174	1505,63	402,779	5,45009	CRS
16:35:44,235	15099	1,6621	1,5196	1,51884	1514,43	407,653	5,60719	CRS
16:37:39,235	15187,3	1,68101	1,5209	1,52017	1523,26	412,287	5,74996	CRS
16:39:34,234	15275,6	1,6972	1,51991	1,51918	1532,2	416,255	5,64113	CRS
16:41:29,233	15363,9	1,71483	1,5193	1,51859	1541,09	420,574	5,57484	CRS
16:43:24,233	15452,3	1,73318	1,51891	1,51819	1549,96	425,068	5,5322	CRS
16:45:19,232	15540,6	1,75339	1,52045	1,51975	1558,76	430,021	5,69993	CRS
16:47:14,231	15628,9	1,77296	1,52176	1,52104	1567,58	434,814	5,84356	CRS
16:49:09,231	15717,2	1,79127	1,52099	1,52029	1576,46	439,302	5,7591	CRS
16:51:04,231	15805,5	1,80976	1,52032	1,51962	1585,33	443,831	5,68561	CRS
16:52:59,230	15893,9	1,82919	1,51993	1,51925	1594,18	448,591	5,64385	CRS
16:54:54,229	15982,2	1,85077	1,52175	1,52109	1602,94	453,879	5,84298	CRS
16:56:49,229	16070,5	1,87167	1,52277	1,52209	1611,73	458,999	5,95372	CRS
16:58:44,229	16158,8	1,89156	1,52234	1,52167	1620,57	463,871	5,90655	CRS
17:00:39,228	16247,2	1,91059	1,52148	1,52083	1629,45	468,533	5,81347	CRS
17:02:34,228	16335,5	1,93178	1,52147	1,52081	1638,24	473,725	5,81146	CRS
17:04:29,227	16423,8	1,95392	1,52264	1,52199	1647	479,149	5,93994	CRS
17:06:24,227	16512,1	1,97528	1,52355	1,52293	1655,79	484,383	6,03911	CRS
17:08:19,226	16600,5	1,99488	1,52249	1,52186	1664,66	489,185	5,92375	CRS
17:10:14,226	16688,8	2,01431	1,52128	1,52068	1673,54	493,946	5,79156	CRS
17:12:09,225	16777,1	2,03743	1,5223	1,52169	1682,28	499,61	5,90221	CRS
17:14:04,225	16865,4	2,0609	1,52367	1,52306	1691,02	505,361	6,05204	CRS
17:15:59,224	16953,7	2,08187	1,52376	1,52317	1699,84	510,498	6,06227	CRS
17:17:54,223	17042,1	2,1026	1,52274	1,52215	1708,69	515,575	5,9505	CRS
17:19:49,223	17130,4	2,12328	1,52157	1,52099	1717,54	520,643	5,82223	CRS
17:21:44,223	17218,7	2,14775	1,52277	1,5222	1726,25	526,638	5,95421	CRS
17:23:39,223	17307	2,1712	1,52423	1,52366	1735	532,384	6,11365	CRS
17:25:34,222	17395,4	2,19208	1,52374	1,52318	1743,86	537,499	6,05948	CRS
17:27:29,221	17483,7	2,21429	1,52304	1,5225	1752,67	542,941	5,9831	CRS
17:29:24,221	17572	2,23671	1,5223	1,52175	1761,47	548,435	5,90205	CRS
17:31:19,220	17660,4	2,2622	1,52402	1,52349	1770,17	554,678	6,09005	CRS
17:33:14,220	17748,7	2,28648	1,5252	1,52468	1778,92	560,628	6,219	CRS
17:35:09,219	17837	2,30951	1,52485	1,52433	1787,72	566,269	6,18123	CRS
17:37:04,219	17925,4	2,33342	1,52423	1,52373	1796,48	572,127	6,11334	CRS
17:38:59,218	18013,6	2,35858	1,52403	1,52354	1805,21	578,291	6,09146	CRS
17:40:54,217	18102	2,38483	1,52561	1,52513	1813,91	584,723	6,26438	CRS
17:42:49,217	18190,4	2,41104	1,52656	1,52609	1822,62	591,146	6,36803	CRS
17:44:44,217	18278,6	2,43573	1,52589	1,52544	1831,37	597,193	6,29465	CRS
17:46:39,216	18367	2,46014	1,52512	1,52466	1840,14	603,173	6,21052	CRS
17:48:34,215	18455,3	2,48587	1,52483	1,52437	1848,87	609,479	6,17862	CRS
17:50:29,215	18543,6	2,51346	1,5261	1,52566	1857,55	616,238	6,31805	CRS
17:52:24,215	18632	2,5402	1,52707	1,52663	1866,26	622,788	6,42356	CRS
17:54:19,215	18720,3	2,5655	1,5265	1,52608	1875,02	628,987	6,36173	CRS
17:56:14,214	18808,6	2,58986	1,52528	1,52488	1883,81	634,955	6,22797	CRS
17:58:09,213	18896,9	2,61804	1,52576	1,52535	1892,48	641,859	6,2805	CRS
18:00:04,212	18985,3	2,64732	1,52723	1,52684	1901,13	649,033	6,44107	CRS
18:01:59,212	19073,6	2,67343	1,5273	1,52692	1909,87	655,429	6,44901	CRS
18:03:54,211	19161,9	2,6997	1,52671	1,52634	1918,62	661,865	6,38448	CRS
18:05:49,211	19250,2	2,72587	1,52577	1,52541	1927,37	668,277	6,282	CRS
18:07:44,211	19338,6	2,75618	1,52641	1,52607	1936	675,704	6,3514	CRS
18:09:39,210	19426,9	2,78554	1,5277	1,52734	1944,66	682,897	6,49228	CRS
18:11:34,210	19515,2	2,81236	1,52777	1,52742	1953,41	689,468	6,50036	CRS
18:13:29,209	19603,5	2,84003	1,527	1,52667	1962,13	696,247	6,41583	CRS
18:15:24,209	19691,9	2,86808	1,52582	1,52551	1970,85	703,119	6,2878	CRS
18:17:19,208	19780,2	2,90058	1,52787	1,52758	1979,43	711,081	6,5117	CRS
18:19:14,207	19868,5	2,93128	1,52931	1,52902	1988,07	718,602	6,6689	CRS
18:21:09,207	19956,8	2,96048	1,52885	1,52857	1996,76	725,758	6,61848	CRS
18:23:04,206	20045,1	2,99091	1,52853	1,52826	2005,42	733,212	6,58331	CRS
18:24:59,206	20133,5	3,02166	1,528	1,52775	2014,08	740,746	6,52592	CRS
18:26:54,205	20221,8	3,05508	1,52984	1,5296	2022,65	748,935	6,72648	CRS
18:28:49,205	20310,1	3,08741	1,5309	1,53067	2031,27	756,855	6,84256	CRS
18:30:44,205	20398,4	3,11843	1,53022	1,53001	2039,93	764,456	6,7677	CRS
18:32:39,204	20486,8	3,14893	1,52924	1,52904	2048,61	771,927	6,66146	CRS
18:34:34,204	20575,1	3,1812	1,52906	1,52887	2057,24	779,834	6,64132	CRS
18:36:29,203	20663,4	3,21539	1,53009	1,52991	2065,82	788,211	6,7538	CRS
18:38:24,203	20751,7	3,24915	1,53144	1,53128	2074,41	796,482	6,90201	CRS
18:40:19,202	20840,1	3,2805	1,53018	1,53002	2083,09	804,161	6,76367	CRS
18:42:14,201	20928,4	3,31154	1,52955	1,5294	2091,78	811,767	6,69507	CRS
18:44:09,201	21016,7	3,34614	1,52958	1,52945	2100,36	820,244	6,69856	CRS
18:46:04,200	21105	3,38231	1,53109	1,53097	2108,9	829,105	6,86321	CRS
18:47:59,199	21193,4	3,41624	1,53164	1,53154	2117,52	837,418	6,9234	CRS
18:49:54,199	21281,7	3,4489	1,53096	1,53087	2126,18	845,421	6,84944	CRS
18:51:49,199	21370	3,4813	1,52992	1,52983	2134,84	853,358	6,73522	CRS
18:53:44,199	21458,4	3,51821	1,53045	1,53038	2143,39	862,4	6,79322	CRS
18:55:39,198	21546,6	3,55605	1,53221	1,53215	2151,9	871,671	6,98549	CRS
18:57:34,198	21635	3,58956	1,53201	1,53197	2160,56	879,881	6,9644	CRS
18:59:29,197	21723,4	3,6243	1,53152	1,5315	2169,18	888,394	6,91042	CRS
19:01:24,196	21811,6	3,65913	1,5306	1,53058	2177,79	896,927	6,80953	CRS
19:03:19,195	21900	3,6997	1,5325	1,53248	2186,26	906,866	7,01701	CRS
19:05:14,195	21988,3	3,73933	1,5342	1,5342	2194,76	916,576	7,20272	CRS
19:07:09,195	22076,6	3,77591	1,53386	1,53388	2203,35	925,538	7,16567	CRS
19:09:04,194	22165	3,81348	1,53345	1,53348	2211,91	934,742	7,12073	CRS
19:10:59,193	22253,3	3,8513	1,53256	1,53261	2220,47	944,007	7,02425	CRS
19:12:54,193	22341,6	3,89258	1,53404	1,53412	2228,94	954,122	7,18591	CRS
19:14:49,193	22430	3,93252	1,53511	1,53519	2237,47	963,907	7,30322	CRS
19:16:44,193	22518,3	3,97096	1,53476	1,53486	2246,03	973,324	7,26475	CRS
19:18:39,192	22606,6	4,00854	1,53353	1,53364	2254,61	982,531	7,12991	CRS
19:20:34,191	22694,9	4,04859	1,5333	1,53342	2263,14	992,345	7,10492	CRS
19:22:29,191	22783,3	4,0909	1,53467	1,53481	2271,62	1002,71	7,2549	CRS
19:24:24,190	22871,6	4,13241	1,53552	1,53568	2280,11	1012,88	7,34779	CRS
19:26:19,190	22959,9	4,17272	1,53527	1,53545	2288,65	1022,76	7,32012	CRS
19:28:14,189	23048,2	4,21151	1,53427	1,53445	2297,22	1032,26	7,21087	CRS
19:30:09,189	23136,5	4,25344	1,53379	1,53398	2305,72	1042,53	7,1579	CRS
19:32:04,188	23224,9	4,29777	1,53556	1,53577	2314,18	1053,39	7,35148	CRS
19:33:59,188	23313,2	4,33981	1,53613	1,53636	2322,68	1063,69	7,41394	CRS
19:35:54,187	23401,5	4,38067	1,53555	1,53578	2331,23	1073,7	7,35024	CRS
19:37:49,187	23489,8	4,42089	1,53471	1,53498	2339,79	1083,56	7,25921	CRS
19:39:44,186	23578,2	4,46686	1,53516	1,53544	2348,22	1094,82	7,30813	CRS
19:41:39,185	23666,5	4,51325	1,53706	1,53735	2356,64	1106,19	7,51561	CRS
19:43:34,185	23754,8	4,55656	1,53725	1,53754	2365,14	1116,8	7,53709	CRS
19:45:29,184	23843,1	4,60033	1,53693	1,53725	2373,63	1127,52	7,50129	CRS
19:47:24,183	23931,5	4,64399	1,536	1,53634	2382,14	1138,22	7,40011	CRS
19:49:19,183	24019,8	4,69432	1,53741	1,53775	2390,48	1150,55	7,55435	CRS
19:51:14,183	24108,1	4,74256	1,53923	1,53961	2398,88	1162,37	7,75267	CRS
19:53:09,183	24196,4	4,78822	1,53915	1,53955	2407,35	1173,55	7,74428	CRS
19:55:04,182	24284,7	4,834	1,53846	1,53887	2415,82	1184,77	7,66922	CRS
19:56:59,181	24373,1	4,88081	1,53746	1,53787	2424,28	1196,24	7,55903	CRS
19:58:54,181	24461,4	4,93144	1,53884	1,53929	2432,64	1208,64	7,71009	CRS
20:00:49,180	24549,7	4,98037	1,5402	1,54066	2441,05	1220,63	7,85915	CRS
20:02:44,179	24638	5,02753	1,5396	1,54009	2449,51	1232,19	7,79358	CRS
20:04:39,179	24726,4	5,07498	1,53905	1,53953	2457,97	1243,81	7,73295	CRS
20:06:34,179	24814,7	5,12376	1,53803	1,53853	2466,4	1255,76	7,62162	CRS
20:08:29,178	24903	5,17521	1,53942	1,53995	2474,77	1268,37	7,77415	CRS
20:10:24,177	24991,4	5,22747	1,54113	1,54169	2483,13	1281,17	7,96092	CRS
20:12:19,177	25079,7	5,27649	1,54045	1,54103	2491,57	1293,18	7,88596	CRS
20:14:14,177	25168	5,32475	1,53968	1,54027	2500,03	1305	7,80245	CRS
20:16:09,176	25256,4	5,37601	1,53912	1,53973	2508,43	1317,56	7,74094	CRS
20:18:04,176	25344,6	5,42939	1,54043	1,54105	2516,78	1330,64	7,88399	CRS
20:19:59,175	25433	5,48178	1,54133	1,54196	2525,17	1343,48	7,98235	CRS
20:21:54,174	25521,4	5,5321	1,54079	1,54146	2533,61	1355,81	7,9237	CRS
20:23:49,173	25609,6	5,58104	1,5398	1,54048	2542,08	1367,79	7,81573	CRS
20:25:44,173	25698	5,63685	1,54002	1,54071	2550,4	1381,47	7,83946	CRS
20:27:39,173	25786,3	5,69435	1,54216	1,54287	2558,68	1395,55	8,07278	CRS
20:29:34,173	25874,6	5,74828	1,543	1,54372	2567,06	1408,77	8,16498	CRS
20:31:29,172	25963	5,80164	1,54247	1,54322	2575,46	1421,84	8,10702	CRS
20:33:24,171	26051,3	5,85532	1,54185	1,54261	2583,85	1434,99	8,03895	CRS
20:35:19,171	26139,6	5,91581	1,54257	1,54335	2592,09	1449,81	8,11777	CRS
20:37:14,170	26227,9	5,97581	1,54449	1,54528	2600,35	1464,51	8,32765	CRS
20:39:09,170	26316,3	6,03132	1,54466	1,54549	2608,72	1478,11	8,34655	CRS
20:41:04,169	26404,6	6,08774	1,54433	1,54516	2617,07	1491,94	8,31011	CRS
20:42:59,169	26492,9	6,14353	1,54293	1,54379	2625,44	1505,6	8,1574	CRS
20:44:54,168	26556,2	6,14572	1,52353	1,52441	2632,27	1506,14	6,03684	HOLD_1500
20:46:49,167	26601	6,14105	1,51297	1,51385	2637,23	1505	4,88315	HOLD_1500
20:48:44,167	26637,2	6,13849	1,50662	1,50754	2641,21	1504,37	4,18926	HOLD_1500
20:50:39,167	26667,3	6,1364	1,50243	1,50335	2644,52	1503,86	3,73084	HOLD_1500
20:52:34,166	26695,2	6,13517	1,4996	1,50048	2647,57	1503,56	3,42181	HOLD_1500
20:54:29,166	26718	6,13427	1,49694	1,49783	2650,07	1503,34	3,13077	HOLD_1500
20:56:24,165	26739,4	6,13327	1,49498	1,49587	2652,42	1503,09	2,91685	HOLD_1500
20:58:19,164	26758,4	6,13265	1,49376	1,49464	2654,49	1502,94	2,7833	HOLD_1500
21:00:14,163	26777	6,13218	1,49247	1,49335	2656,52	1502,82	2,64163	HOLD_1500
21:02:09,163	26793	6,13441	1,49185	1,49273	2658,2	1503,37	2,57428	HOLD_1500
21:04:04,163	26808,6	6,13078	1,49009	1,49097	2659,97	1502,48	2,38174	HOLD_1500
21:05:59,162	26822,6	6,13059	1,48925	1,49015	2661,5	1502,43	2,29001	HOLD_1500
21:07:54,162	26835,9	6,1306	1,48909	1,49001	2662,94	1502,44	2,27309	HOLD_1500
21:09:49,162	26849,2	6,12981	1,48815	1,48907	2664,41	1502,24	2,17043	HOLD_1500
21:11:44,161	26861	6,13032	1,48767	1,48858	2665,67	1502,37	2,11788	HOLD_1500
21:13:39,161	26871,8	6,12977	1,48696	1,48786	2666,85	1502,23	2,03948	HOLD_1500
21:15:34,160	26883	6,12933	1,48648	1,48736	2668,07	1502,13	1,98698	HOLD_1500
21:17:29,159	26894	6,12972	1,48612	1,48702	2669,26	1502,22	1,94825	HOLD_1500
21:19:24,159	26903,2	6,12885	1,48577	1,48666	2670,29	1502,01	1,91036	HOLD_1500
21:21:19,158	26912	6,12889	1,48564	1,48653	2671,23	1502,02	1,89559	HOLD_1500
21:23:14,157	26921,8	6,12869	1,48495	1,48582	2672,3	1501,97	1,81984	HOLD_1500
21:25:09,157	26931,5	6,12818	1,48444	1,48533	2673,36	1501,84	1,76498	HOLD_1500
21:27:04,157	26939,3	6,1283	1,48454	1,48542	2674,21	1501,87	1,77562	HOLD_1500
21:28:59,156	26947	6,12902	1,48428	1,48517	2675,03	1502,05	1,74691	HOLD_1500
21:30:54,156	26955	6,12832	1,48401	1,48491	2675,91	1501,88	1,71748	HOLD_1500
21:32:49,155	26963	6,12833	1,48388	1,48477	2676,78	1501,88	1,70296	HOLD_1500
21:34:44,155	26971	6,12833	1,48375	1,48464	2677,65	1501,88	1,68919	HOLD_1500
21:36:39,154	26978	6,12866	1,48347	1,48437	2678,4	1501,96	1,6587	HOLD_1500
21:38:34,153	26984,3	6,12782	1,48332	1,48421	2679,1	1501,76	1,64235	HOLD_1500
21:40:29,153	26991	6,1306	1,48349	1,48439	2679,77	1502,44	1,66102	HOLD_1500
21:42:24,152	26997	6,12736	1,48264	1,48352	2680,49	1501,64	1,56739	HOLD_1500
21:44:19,152	27004	6,12771	1,48281	1,48371	2681,24	1501,73	1,58608	HOLD_1500
21:46:14,151	27011	6,1283	1,48304	1,48394	2681,99	1501,87	1,61091	HOLD_1500
21:48:09,151	27017	6,1283	1,48267	1,48356	2682,64	1501,87	1,5711	HOLD_1500
21:50:04,150	27022	6,12746	1,48254	1,48343	2683,2	1501,67	1,55725	HOLD_1500
21:51:59,150	27027	6,12748	1,48213	1,48302	2683,74	1501,67	1,51194	HOLD_1500
21:53:54,149	27033	6,12755	1,4821	1,483	2684,39	1501,69	1,50851	HOLD_1500
21:55:49,148	27040	6,13018	1,48251	1,48341	2685,09	1502,33	1,55365	HOLD_1500
21:57:44,148	27046	6,13009	1,48254	1,48344	2685,75	1502,31	1,55635	HOLD_1500
21:59:39,147	27050,9	6,12723	1,48172	1,48261	2686,34	1501,61	1,46719	HOLD_1500
22:01:34,147	27055,7	6,12726	1,48171	1,4826	2686,86	1501,62	1,46588	HOLD_1500
22:03:29,147	27060	6,12759	1,48182	1,48272	2687,32	1501,7	1,47819	HOLD_1500
22:05:24,146	27065	6,12812	1,48152	1,48241	2687,85	1501,83	1,44566	HOLD_1500
22:07:19,146	27069	6,1269	1,48159	1,4825	2688,31	1501,53	1,45336	HOLD_1500
22:09:14,145	27075	6,12918	1,48165	1,48256	2688,91	1502,09	1,45948	HOLD_1500
22:11:09,145	27080	6,13112	1,48202	1,48292	2689,41	1502,56	1,50039	HOLD_1500
22:13:04,144	27084	6,12718	1,4814	1,4823	2689,93	1501,6	1,43228	HOLD_1500
22:14:59,143	27088,5	6,12666	1,48108	1,48197	2690,44	1501,47	1,39701	HOLD_1500
22:16:54,143	27093,6	6,12698	1,48105	1,48193	2690,98	1501,55	1,39394	HOLD_1500
22:18:49,142	27097,8	6,12677	1,48077	1,48168	2691,44	1501,5	1,36384	HOLD_1500
22:20:44,142	27101	6,12646	1,48053	1,48142	2691,79	1501,42	1,33713	HOLD_1500
22:22:39,141	27105	6,12685	1,48092	1,48181	2692,22	1501,52	1,3801	HOLD_1500
22:24:34,141	27109	6,12724	1,48077	1,48166	2692,64	1501,61	1,36371	HOLD_1500
22:26:29,140	27113	6,12855	1,48076	1,48166	2693,05	1501,93	1,36267	HOLD_1500
22:28:24,140	27118	6,1303	1,48126	1,48215	2693,56	1502,36	1,41722	HOLD_1500
22:30:19,139	27121,3	6,12639	1,48068	1,48158	2694	1501,41	1,35402	HOLD_1500
22:32:14,139	27126	6,12721	1,48069	1,48158	2694,49	1501,61	1,35448	HOLD_1500
22:34:09,138	27130	6,12707	1,48057	1,48145	2694,93	1501,57	1,34106	HOLD_1500
22:36:04,137	27134	6,1275	1,4807	1,4816	2695,35	1501,68	1,35556	HOLD_1500
22:37:59,137	27137	6,12628	1,48045	1,48133	2695,71	1501,38	1,32787	HOLD_1500
22:39:54,137	27140,6	6,1264	1,48027	1,48116	2696,09	1501,41	1,30843	HOLD_1500
22:41:49,136	27144	6,1272	1,48068	1,48158	2696,44	1501,6	1,35339	HOLD_1500
22:43:44,136	27147	6,12758	1,48061	1,4815	2696,76	1501,7	1,34606	HOLD_1500
22:45:39,135	27151,8	6,12808	1,48057	1,48145	2697,27	1501,82	1,34137	HOLD_1500
22:47:34,134	27154	6,12875	1,48051	1,4814	2697,49	1501,98	1,33545	HOLD_1500
22:49:29,134	27157,5	6,12629	1,48011	1,481	2697,93	1501,38	1,29084	HOLD_1500
22:51:24,133	27162	6,12767	1,4804	1,48129	2698,39	1501,72	1,32236	HOLD_1500
22:53:19,133	27165	6,12956	1,48067	1,48157	2698,67	1502,18	1,35281	HOLD_1500
22:55:14,132	27168	6,12695	1,48018	1,48106	2699,05	1501,54	1,2983	HOLD_1500
22:57:09,132	27172	6,12671	1,48019	1,48108	2699,49	1501,48	1,30019	HOLD_1500
22:59:04,131	27175	6,12751	1,4803	1,48119	2699,8	1501,68	1,3116	HOLD_1500
23:00:59,131	27178	6,12696	1,48012	1,48099	2700,14	1501,54	1,29243	HOLD_1500
23:02:54,130	27180	6,12679	1,48024	1,48114	2700,36	1501,5	1,30506	HOLD_1500
23:04:49,130	27183	6,12644	1,48023	1,48111	2700,69	1501,42	1,30459	HOLD_1500
23:06:44,129	27187	6,13175	1,48122	1,4821	2701,01	1502,72	1,4127	HOLD_1500
23:08:39,129	27188,6	6,12622	1,47999	1,48088	2701,3	1501,36	1,2779	HOLD_1500
23:10:34,128	27192	6,13033	1,4808	1,48169	2701,58	1502,37	1,36713	HOLD_1500
23:12:29,127	27195	6,12962	1,48042	1,48132	2701,92	1502,2	1,32545	HOLD_1500
23:14:24,127	27197	6,12611	1,48002	1,48091	2702,22	1501,34	1,28088	HOLD_1500
23:16:19,127	27200	6,12657	1,48002	1,48092	2702,53	1501,45	1,28107	HOLD_1500
23:18:14,126	27204	6,12851	1,48011	1,481	2702,92	1501,93	1,29083	HOLD_1500
23:20:09,126	27206	6,12643	1,4801	1,48099	2703,19	1501,42	1,29024	HOLD_1500
23:22:04,125	27210	6,12652	1,48011	1,48101	2703,62	1501,44	1,29142	HOLD_1500
23:23:59,124	27214	6,12818	1,48034	1,48123	2704,02	1501,84	1,31627	HOLD_1500
23:25:54,124	27215	6,12687	1,48009	1,48099	2704,15	1501,52	1,28916	HOLD_1500
23:27:49,123	27218	6,12966	1,48028	1,48119	2704,42	1502,21	1,30936	HOLD_1500
23:29:44,123	27220	6,1278	1,48014	1,48104	2704,68	1501,75	1,29428	HOLD_1500
23:31:39,122	27222	6,12672	1,47991	1,48081	2704,92	1501,49	1,26967	HOLD_1500
23:33:34,122	27225	6,12673	1,48014	1,48104	2705,24	1501,49	1,29468	HOLD_1500
23:35:29,121	27227	6,13001	1,48045	1,48134	2705,39	1502,29	1,3281	HOLD_1500
23:37:24,121	27229	6,12669	1,47976	1,48065	2705,68	1501,48	1,25287	HOLD_1500
23:39:19,121	27231	6,12655	1,4797	1,4806	2705,9	1501,45	1,24688	HOLD_1500
23:41:14,120	27234	6,12657	1,47996	1,48086	2706,22	1501,45	1,27431	HOLD_1500
23:43:09,119	27236	6,12619	1,47979	1,48069	2706,45	1501,36	1,25595	HOLD_1500
23:45:04,118	27239	6,12872	1,48001	1,4809	2706,72	1501,97	1,2803	HOLD_1500
23:46:59,118	27242	6,12898	1,48032	1,48123	2707,04	1502,04	1,31438	HOLD_1500
23:48:54,117	27245	6,12945	1,4806	1,48149	2707,35	1502,16	1,34449	HOLD_1500
23:50:49,117	27247	6,12901	1,48014	1,48103	2707,58	1502,05	1,29405	HOLD_1500
23:52:44,117	27249	6,12678	1,47999	1,48088	2707,84	1501,5	1,27861	HOLD_1500
23:54:39,116	27253	6,13154	1,48015	1,48104	2708,18	1502,67	1,29507	HOLD_1500
23:56:34,116	27254	6,12654	1,47983	1,48073	2708,39	1501,44	1,26059	HOLD_1500
23:58:29,115	27256	6,12648	1,48018	1,48109	2708,61	1501,43	1,29861	HOLD_1500
00:00:24,114	27258	6,12644	1,48008	1,48097	2708,83	1501,42	1,28822	HOLD_1500
00:02:19,113	27260	6,12709	1,48011	1,481	2709,03	1501,58	1,29147	HOLD_1500
00:04:14,113	27262	6,12693	1,48	1,4809	2709,25	1501,54	1,27918	HOLD_1500
00:06:09,113	27265	6,1309	1,48039	1,48129	2709,49	1502,51	1,32152	HOLD_1500
00:08:04,112	27267	6,13165	1,4804	1,48129	2709,69	1502,69	1,32305	HOLD_1500
00:09:59,112	27268	6,12678	1,47997	1,48087	2709,91	1501,5	1,27537	HOLD_1500
00:11:54,111	27271	6,13009	1,48061	1,48151	2710,16	1502,31	1,34594	HOLD_1500
00:13:49,111	27273	6,1308	1,48043	1,48133	2710,36	1502,49	1,32622	HOLD_1500
00:15:44,111	27274	6,12642	1,47995	1,48086	2710,57	1501,41	1,27395	HOLD_1500
00:17:39,110	27277	6,12667	1,48006	1,48096	2710,89	1501,47	1,28558	HOLD_1500
00:19:34,109	27279	6,12975	1,47994	1,48084	2711,04	1502,23	1,27284	HOLD_1500
00:21:29,109	27281	6,12955	1,47991	1,48082	2711,26	1502,18	1,26923	HOLD_1500
00:23:24,108	27284	6,1296	1,48006	1,48095	2711,58	1502,19	1,28564	HOLD_1500
00:25:19,107	27287	6,13373	1,48064	1,48155	2711,82	1503,2	1,34944	HOLD_1500
00:27:14,107	27287	6,12679	1,47957	1,48047	2711,97	1501,5	1,23215	HOLD_1500
00:29:09,107	27290	6,12825	1,47992	1,48081	2712,26	1501,86	1,27012	HOLD_1500
00:31:04,106	27292	6,12794	1,47979	1,48067	2712,49	1501,79	1,25595	HOLD_1500
00:32:59,105	27294	6,12931	1,48013	1,48102	2712,67	1502,12	1,29326	HOLD_1500
00:34:54,105	27295	6,12603	1,47967	1,48057	2712,85	1501,32	1,24317	HOLD_1500
00:36:49,104	27297	6,12736	1,47972	1,48061	2713,04	1501,64	1,24824	HOLD_1500
00:38:44,103	27299	6,12902	1,47982	1,48073	2713,22	1502,05	1,25953	HOLD_1500
00:40:39,103	27300	6,12644	1,4798	1,48071	2713,39	1501,42	1,25784	HOLD_1500
00:42:34,103	27302	6,12805	1,47984	1,48075	2713,57	1501,81	1,2621	HOLD_1500
00:44:29,102	27305	6,13157	1,48052	1,48143	2713,82	1502,67	1,33552	HOLD_1500
00:46:24,101	27305	6,12705	1,47977	1,48068	2713,91	1501,57	1,25418	HOLD_1500
00:48:19,101	27307	6,12948	1,47973	1,48063	2714,08	1502,16	1,24913	HOLD_1500
00:50:14,101	27310	6,12804	1,48008	1,48099	2714,44	1501,81	1,28818	HOLD_1500
00:52:09,100	27310	6,12668	1,4795	1,48041	2714,47	1501,48	1,22467	HOLD_1500
00:54:04,099	27312	6,12809	1,47973	1,48065	2714,65	1501,82	1,24954	HOLD_1500
00:55:59,099	27314	6,12852	1,4799	1,4808	2714,86	1501,93	1,26836	HOLD_1500
00:57:54,098	27317	6,13007	1,48	1,4809	2715,15	1502,31	1,27967	HOLD_1500
00:59:49,098	27320	6,13415	1,48061	1,48151	2715,39	1503,31	1,34603	HOLD_1500
01:01:44,097	27320	6,13044	1,47956	1,48046	2715,47	1502,4	1,23133	HOLD_1500
01:03:39,097	27321	6,12587	1,47932	1,48021	2715,68	1501,28	1,20446	HOLD_1500
01:05:34,096	27323	6,1264	1,47952	1,48041	2715,88	1501,41	1,22671	HOLD_1500
01:07:29,096	27325	6,127	1,47957	1,48047	2716,09	1501,55	1,23237	HOLD_1500
01:09:24,095	27328	6,13137	1,47963	1,48054	2716,32	1502,63	1,23878	HOLD_1500
01:11:19,094	27329	6,12666	1,47963	1,48053	2716,53	1501,47	1,23902	HOLD_1500
01:13:14,094	27333	6,13408	1,48051	1,48142	2716,8	1503,29	1,33472	HOLD_1500
01:15:09,093	27333	6,1291	1,47946	1,48038	2716,91	1502,07	1,22004	HOLD_1500
01:17:04,093	27334	6,12664	1,47948	1,48038	2717,07	1501,47	1,22206	HOLD_1500
01:18:59,093	27336	6,12909	1,47986	1,48076	2717,23	1502,07	1,26402	HOLD_1500
01:20:54,092	27337	6,12645	1,47963	1,48053	2717,4	1501,42	1,23897	HOLD_1500
01:22:49,091	27339	6,1299	1,47976	1,48066	2717,54	1502,27	1,2524	HOLD_1500
01:24:44,091	27340	6,12761	1,47964	1,48054	2717,7	1501,7	1,24007	HOLD_1500
01:26:39,090	27342	6,13014	1,4801	1,481	2717,86	1502,32	1,29007	HOLD_1500
01:28:34,089	27342,4	6,12594	1,47955	1,48046	2718	1501,29	1,23042	HOLD_1500
01:30:29,089	27345	6,13145	1,48006	1,48097	2718,16	1502,65	1,28554	HOLD_1500
01:32:24,089	27345	6,12664	1,47939	1,48028	2718,26	1501,47	1,21287	HOLD_1500
01:34:19,088	27347	6,13014	1,47958	1,48048	2718,4	1502,32	1,23333	HOLD_1500
01:36:14,087	27349	6,12921	1,47991	1,48081	2718,64	1502,1	1,26909	HOLD_1500
01:38:09,087	27350,3	6,12643	1,47951	1,48041	2718,85	1501,41	1,22559	HOLD_1500
01:40:04,087	27352	6,13179	1,47972	1,48062	2718,91	1502,73	1,24906	HOLD_1500
01:41:59,086	27352	6,12589	1,4794	1,4803	2719,04	1501,28	1,21324	HOLD_1500
01:43:54,085	27355	6,12968	1,47987	1,48078	2719,28	1502,21	1,26523	HOLD_1500
01:45:49,085	27358	6,13039	1,47994	1,48085	2719,59	1502,39	1,27284	HOLD_1500
01:47:44,084	27358	6,13023	1,47944	1,48035	2719,6	1502,35	1,2181	HOLD_1500
01:49:39,084	27360	6,13033	1,47996	1,48086	2719,81	1502,37	1,27476	HOLD_1500
01:51:34,083	27360	6,12655	1,47953	1,48043	2719,89	1501,44	1,22821	HOLD_1500
01:53:29,083	27363	6,12936	1,47986	1,48075	2720,16	1502,13	1,26368	HOLD_1500
01:55:24,083	27366	6,13282	1,48026	1,48116	2720,41	1502,98	1,30753	HOLD_1500
01:57:19,082	27366	6,1304	1,47962	1,48051	2720,46	1502,39	1,23773	HOLD_1500
01:59:14,081	27367	6,12685	1,47941	1,48032	2720,65	1501,52	1,21447	HOLD_1500
02:01:09,080	27368	6,1263	1,47963	1,48054	2720,77	1501,38	1,23833	HOLD_1500
02:03:04,080	27370	6,12635	1,47949	1,4804	2720,98	1501,39	1,22296	HOLD_1500
02:04:59,079	27372	6,12869	1,47957	1,48047	2721,15	1501,97	1,23223	HOLD_1500
02:06:54,079	27374	6,13175	1,47995	1,48084	2721,3	1502,72	1,27331	HOLD_1500
02:08:49,079	27374	6,12761	1,47957	1,48049	2721,39	1501,7	1,23198	HOLD_1500
02:10:44,078	27375	6,12623	1,47929	1,48019	2721,53	1501,37	1,20188	HOLD_1500
02:12:39,077	27376	6,12597	1,47961	1,48052	2721,64	1501,3	1,23619	HOLD_1500
02:14:34,077	27378	6,12721	1,47958	1,48047	2721,83	1501,6	1,23356	HOLD_1500
02:16:29,076	27380	6,13101	1,48003	1,48095	2721,97	1502,54	1,28281	HOLD_1500
02:18:24,076	27380	6,12794	1,4795	1,4804	2722,03	1501,79	1,22474	HOLD_1500
02:20:19,075	27381	6,12734	1,47948	1,48039	2722,15	1501,64	1,2228	HOLD_1500
02:22:14,074	27382	6,12644	1,47979	1,48068	2722,28	1501,42	1,2561	HOLD_1500
02:24:09,074	27383	6,12593	1,47942	1,48031	2722,4	1501,29	1,21555	HOLD_1500
02:26:04,074	27385	6,1296	1,47946	1,48036	2722,54	1502,19	1,22055	HOLD_1500
02:27:59,073	27387	6,13095	1,4798	1,48071	2722,73	1502,52	1,25706	HOLD_1500
02:29:54,073	27387	6,12977	1,47952	1,48042	2722,75	1502,23	1,22668	HOLD_1500
02:31:49,072	27388	6,12665	1,47955	1,48046	2722,93	1501,47	1,22964	HOLD_1500
02:33:44,071	27390	6,12977	1,47989	1,48079	2723,08	1502,23	1,26726	HOLD_1500
02:35:39,071	27390	6,1262	1,47939	1,48029	2723,16	1501,36	1,21209	HOLD_1500
02:37:34,070	27393	6,13386	1,47971	1,48062	2723,32	1503,24	1,2476	HOLD_1500
02:39:29,070	27393	6,12878	1,47937	1,48028	2723,43	1501,99	1,21004	HOLD_1500
02:41:24,069	27394	6,12628	1,4794	1,48032	2723,59	1501,38	1,2134	HOLD_1500
02:43:19,069	27396	6,12884	1,47958	1,48049	2723,75	1502,01	1,23377	HOLD_1500
02:45:14,068	27398	6,13009	1,4797	1,4806	2723,94	1502,31	1,24588	HOLD_1500
02:47:09,068	27398	6,1264	1,47938	1,48028	2724,02	1501,41	1,21125	HOLD_1500
02:49:04,067	27401	6,1337	1,47996	1,48086	2724,19	1503,2	1,27427	HOLD_1500
02:50:59,067	27401	6,12851	1,47918	1,48011	2724,3	1501,92	1,18937	HOLD_1500
02:52:54,066	27402	6,12588	1,47927	1,48017	2724,46	1501,28	1,19889	HOLD_1500
02:54:49,066	27405	6,13117	1,47961	1,48052	2724,68	1502,58	1,23657	HOLD_1500
02:56:44,065	27405	6,12653	1,47944	1,48035	2724,78	1501,44	1,21785	HOLD_1500
02:58:39,065	27407	6,12902	1,47951	1,48042	2724,94	1502,05	1,22539	HOLD_1500
03:00:34,064	27408	6,12641	1,47959	1,48049	2725,1	1501,41	1,23389	HOLD_1500
03:02:29,064	27410	6,12894	1,47949	1,4804	2725,27	1502,03	1,22343	HOLD_1500
03:04:24,063	27413	6,12885	1,47967	1,48058	2725,59	1502,01	1,24292	HOLD_1500
03:06:19,063	27413	6,1319	1,47978	1,48069	2725,53	1502,76	1,25558	HOLD_1500
03:08:14,061	27413	6,12768	1,47942	1,48033	2725,62	1501,72	1,21611	HOLD_1500
03:10:09,061	27414	6,12712	1,47954	1,48045	2725,74	1501,58	1,22939	HOLD_1500
03:12:04,061	27415	6,1276	1,47953	1,48043	2725,84	1501,7	1,22736	HOLD_1500
03:13:59,060	27416	6,12715	1,47969	1,48061	2725,96	1501,59	1,24569	HOLD_1500
03:15:54,060	27418	6,13017	1,47971	1,48062	2726,11	1502,33	1,24696	HOLD_1500
03:17:49,059	27418	6,12773	1,47953	1,48043	2726,16	1501,73	1,2283	HOLD_1500
03:19:44,059	27420	6,13148	1,4798	1,48072	2726,3	1502,65	1,25779	HOLD_1500
03:21:39,059	27420	6,12892	1,47934	1,48025	2726,35	1502,02	1,20756	HOLD_1500
03:23:34,057	27421	6,1276	1,47975	1,48067	2726,49	1501,7	1,25186	HOLD_1500
03:25:29,057	27422	6,12737	1,47966	1,48057	2726,6	1501,64	1,24154	HOLD_1500
03:27:24,056	27423	6,12679	1,47974	1,48066	2726,72	1501,5	1,25075	HOLD_1500
03:29:19,056	27425	6,12991	1,47996	1,48087	2726,87	1502,27	1,27497	HOLD_1500
03:31:14,055	27425	6,12947	1,47976	1,48065	2726,88	1502,16	1,2524	HOLD_1500
03:33:09,055	27427	6,12912	1,47973	1,48063	2727,11	1502,07	1,25003	HOLD_1500
03:35:04,055	27427	6,13085	1,47963	1,48053	2727,07	1502,5	1,23849	HOLD_1500
03:36:59,054	27427	6,12661	1,47933	1,48024	2727,16	1501,46	1,20598	HOLD_1500
03:38:54,053	27428	6,12586	1,47947	1,48038	2727,29	1501,27	1,22121	HOLD_1500
03:40:49,052	27429	6,12588	1,4794	1,48031	2727,39	1501,28	1,21388	HOLD_1500
03:42:44,051	27432	6,13317	1,47986	1,48077	2727,56	1503,07	1,2642	HOLD_1500
03:44:39,051	27432	6,12897	1,47936	1,48027	2727,65	1502,04	1,20972	HOLD_1500
03:46:34,051	27434	6,12944	1,47979	1,48071	2727,86	1502,15	1,25667	HOLD_1500
03:48:29,051	27434	6,12796	1,4795	1,48041	2727,89	1501,79	1,22443	HOLD_1500
03:50:24,050	27436	6,12903	1,47962	1,48054	2728,09	1502,05	1,2377	HOLD_1500
03:52:19,050	27436	6,12624	1,47925	1,48017	2728,15	1501,37	1,19753	HOLD_1500
03:54:14,049	27439	6,13445	1,47963	1,48054	2728,29	1503,38	1,23828	HOLD_1500
03:56:09,048	27439	6,13003	1,47919	1,48011	2728,39	1502,3	1,19098	HOLD_1500
03:58:04,047	27440	6,12719	1,47942	1,48032	2728,56	1501,6	1,21618	HOLD_1500
03:59:59,047	27441	6,12687	1,47947	1,48037	2728,68	1501,52	1,22075	HOLD_1500
04:01:54,046	27443	6,12859	1,47954	1,48045	2728,85	1501,94	1,22852	HOLD_1500
04:03:49,046	27443	6,12684	1,47941	1,48031	2728,89	1501,52	1,21488	HOLD_1500
04:05:44,046	27446	6,13356	1,47968	1,48059	2729,07	1503,16	1,24374	HOLD_1500
04:07:39,045	27446	6,1303	1,47932	1,48023	2729,14	1502,36	1,20451	HOLD_1500
04:09:34,045	27446	6,12583	1,47923	1,48014	2729,24	1501,27	1,19499	HOLD_1500
04:11:29,044	27449	6,12725	1,47939	1,48029	2729,53	1501,62	1,21203	HOLD_1500
04:13:24,043	27449	6,12825	1,47936	1,48026	2729,51	1501,86	1,20929	HOLD_1500
04:15:19,043	27450	6,12659	1,47907	1,47998	2729,66	1501,46	1,17707	HOLD_1500
04:17:14,043	27453	6,13449	1,48005	1,48096	2729,81	1503,39	1,28469	HOLD_1500
04:19:09,042	27453	6,13194	1,47923	1,48015	2729,87	1502,77	1,19539	HOLD_1500
04:21:04,041	27453	6,12824	1,47902	1,47993	2729,95	1501,86	1,17224	HOLD_1500
04:22:59,041	27454	6,12712	1,47933	1,48024	2730,08	1501,58	1,2063	HOLD_1500
04:24:54,040	27455	6,12673	1,47937	1,48028	2730,2	1501,49	1,21003	HOLD_1500
04:26:49,040	27455	6,12689	1,4792	1,48011	2730,19	1501,53	1,1917	HOLD_1500
04:28:44,039	27456	6,12695	1,47925	1,48015	2730,3	1501,54	1,19666	HOLD_1500
04:30:39,038	27457	6,12675	1,47938	1,48029	2730,41	1501,49	1,21127	HOLD_1500
04:32:34,038	27459	6,12952	1,47953	1,48045	2730,57	1502,17	1,22759	HOLD_1500
04:34:29,037	27459	6,1296	1,47924	1,48015	2730,57	1502,19	1,19656	HOLD_1500
04:36:24,037	27459	6,12646	1,47908	1,47998	2730,64	1501,42	1,17832	HOLD_1500
04:38:19,037	27461	6,13164	1,47923	1,48013	2730,74	1502,69	1,19529	HOLD_1500
04:40:14,036	27461	6,1293	1,47923	1,48014	2730,79	1502,12	1,19515	HOLD_1500
04:42:09,035	27461	6,12584	1,47915	1,48007	2730,87	1501,27	1,18666	HOLD_1500
04:44:04,035	27462	6,12593	1,47892	1,47982	2730,97	1501,29	1,16122	HOLD_1500
04:45:59,034	27463	6,12662	1,47931	1,48022	2731,07	1501,46	1,20409	HOLD_1500
04:47:54,033	27464	6,12693	1,47916	1,48006	2731,17	1501,54	1,18759	HOLD_1500
04:49:49,033	27466	6,13222	1,47956	1,48047	2731,27	1502,83	1,23143	HOLD_1500
04:51:44,033	27466	6,13055	1,47906	1,47997	2731,31	1502,43	1,17637	HOLD_1500
04:53:39,032	27466	6,12748	1,47899	1,47991	2731,37	1501,67	1,16861	HOLD_1500
04:55:34,032	27467	6,12716	1,47909	1,47998	2731,49	1501,59	1,17953	HOLD_1500
04:57:29,031	27468	6,12673	1,47933	1,48023	2731,61	1501,49	1,20637	HOLD_1500
04:59:24,031	27470	6,12828	1,47927	1,48018	2731,79	1501,87	1,19968	HOLD_1500
05:01:19,030	27470	6,1283	1,47921	1,48012	2731,79	1501,87	1,19253	HOLD_1500
05:03:14,029	27473	6,13373	1,47993	1,48083	2732	1503,2	1,27147	HOLD_1500
05:05:09,029	27473	6,13399	1,47935	1,48026	2731,99	1503,27	1,20796	HOLD_1500
05:07:04,028	27473	6,13	1,47908	1,47998	2732,08	1502,29	1,17896	HOLD_1500
05:08:59,028	27473	6,12603	1,47897	1,47987	2732,17	1501,32	1,16629	HOLD_1500
05:10:54,027	27475,8	6,12632	1,4792	1,48011	2732,46	1501,39	1,19164	HOLD_1500
05:12:49,027	27476	6,12909	1,47912	1,48002	2732,42	1502,07	1,18263	HOLD_1500
05:14:44,027	27476	6,1258	1,47869	1,4796	2732,5	1501,26	1,13551	HOLD_1500
05:16:39,026	27479	6,13405	1,47952	1,48041	2732,64	1503,28	1,22628	HOLD_1500
05:18:34,025	27479	6,13041	1,47901	1,47991	2732,72	1502,39	1,17073	HOLD_1500
05:20:29,025	27479	6,12654	1,47889	1,47979	2732,81	1501,44	1,15828	HOLD_1500
05:22:24,024	27480	6,1265	1,47902	1,47993	2732,91	1501,43	1,17236	HOLD_1500
05:24:19,023	27482	6,12965	1,47932	1,48021	2733,06	1502,2	1,20538	HOLD_1500
05:26:14,023	27482	6,12674	1,47906	1,47996	2733,13	1501,49	1,17668	HOLD_1500
05:28:09,023	27485	6,13231	1,47952	1,48043	2733,33	1502,85	1,22651	HOLD_1500
05:30:04,022	27485	6,12965	1,47918	1,48009	2733,39	1502,2	1,18993	HOLD_1500
05:31:59,022	27485	6,12594	1,47883	1,47974	2733,47	1501,3	1,1508	HOLD_1500
05:33:54,021	27487	6,12964	1,47932	1,48022	2733,61	1502,2	1,20439	HOLD_1500
05:35:49,020	27487	6,12687	1,47915	1,48006	2733,67	1501,52	1,18651	HOLD_1500
05:37:44,020	27489	6,12878	1,47933	1,48025	2733,84	1501,99	1,20541	HOLD_1500
05:39:39,019	27489	6,12676	1,47922	1,48012	2733,89	1501,5	1,19364	HOLD_1500
05:41:34,019	27490	6,12649	1,47904	1,47995	2734	1501,43	1,17394	HOLD_1500
05:43:29,018	27493	6,13421	1,47981	1,48073	2734,16	1503,32	1,25838	HOLD_1500
05:45:24,017	27493	6,13248	1,47927	1,48018	2734,2	1502,9	1,19898	HOLD_1500
05:47:19,018	27493	6,12974	1,47903	1,47994	2734,25	1502,23	1,17298	HOLD_1500
05:49:14,017	27493	6,12674	1,47911	1,48001	2734,32	1501,49	1,18197	HOLD_1500
05:51:09,016	27494	6,12792	1,47925	1,48016	2734,4	1501,78	1,19671	HOLD_1500
05:53:04,015	27494	6,12609	1,47897	1,47988	2734,44	1501,33	1,16659	HOLD_1500
05:54:59,015	27495	6,12692	1,47906	1,47996	2734,53	1501,53	1,17606	HOLD_1500
05:56:54,015	27496	6,12612	1,47908	1,47999	2734,66	1501,34	1,1791	HOLD_1500
05:58:49,014	27496	6,12683	1,47911	1,48001	2734,64	1501,51	1,18224	HOLD_1500
06:00:44,013	27497	6,12692	1,47941	1,48031	2734,75	1501,53	1,21491	HOLD_1500
06:02:39,013	27497	6,12677	1,47937	1,48027	2734,75	1501,5	1,21025	HOLD_1500
06:04:34,013	27498	6,12727	1,47962	1,48053	2734,85	1501,62	1,23731	HOLD_1500
06:06:29,011	27498	6,12665	1,47932	1,48023	2734,86	1501,47	1,205	HOLD_1500
06:08:24,011	27500	6,13105	1,47962	1,48054	2734,99	1502,55	1,238	HOLD_1500
06:10:19,010	27500	6,13014	1,47917	1,48008	2735,01	1502,32	1,18863	HOLD_1500
06:12:14,010	27500	6,12772	1,47899	1,47989	2735,06	1501,73	1,16902	HOLD_1500
06:14:09,009	27501	6,12713	1,47914	1,48006	2735,18	1501,59	1,18553	HOLD_1500
06:16:04,009	27501	6,12668	1,47894	1,47982	2735,19	1501,48	1,1628	HOLD_1500
06:17:59,008	27502	6,12697	1,47913	1,48002	2735,29	1501,55	1,18394	HOLD_1500
06:19:54,008	27502	6,1258	1,47895	1,47985	2735,32	1501,26	1,16486	HOLD_1500
06:21:49,008	27503	6,12624	1,47904	1,47993	2735,42	1501,37	1,17423	HOLD_1500
06:23:44,007	27505	6,13044	1,47914	1,48003	2735,54	1502,4	1,18519	HOLD_1500
06:25:39,006	27505	6,12919	1,47875	1,47964	2735,57	1502,09	1,14289	HOLD_1500
06:27:34,006	27505	6,12676	1,47875	1,47965	2735,62	1501,49	1,14272	HOLD_1500
06:29:29,005	27507	6,13199	1,47934	1,48022	2735,72	1502,78	1,20722	HOLD_1500
06:31:24,005	27507	6,13047	1,47899	1,4799	2735,76	1502,4	1,16869	HOLD_1500
06:33:19,004	27507	6,12734	1,47862	1,47952	2735,83	1501,64	1,12819	HOLD_1500
06:35:14,004	27508	6,12712	1,47893	1,47982	2735,94	1501,58	1,16264	HOLD_1500
06:37:09,003	27508	6,12562	1,4786	1,47949	2735,97	1501,22	1,12665	HOLD_1500
06:39:04,003	27509	6,12611	1,47877	1,47965	2736,07	1501,34	1,14495	HOLD_1500
06:40:59,002	27510	6,12637	1,47861	1,4795	2736,17	1501,4	1,12754	HOLD_1500
06:42:54,001	27513	6,13538	1,47946	1,48035	2736,3	1503,61	1,21986	HOLD_1500
06:44:49,001	27513	6,1336	1,47874	1,47963	2736,34	1503,17	1,1417	HOLD_1500
06:46:44,000	27513	6,13014	1,47845	1,47934	2736,42	1502,32	1,1099	HOLD_1500
06:48:39,000	27513	6,12676	1,47828	1,47918	2736,49	1501,5	1,09074	HOLD_1500
06:50:34,000	27514	6,12521	1,47811	1,479	2736,63	1501,12	1,07246	HOLD_1500
06:52:28,999	27516	6,12853	1,47817	1,47907	2736,78	1501,93	1,07909	HOLD_1500
06:54:23,999	27517	6,12549	1,47801	1,47891	2736,95	1501,18	1,06189	HOLD_1500
06:56:18,998	27519	6,13081	1,47858	1,47948	2737,05	1502,49	1,12448	HOLD_1500
06:58:13,998	27519	6,12979	1,4782	1,4791	2737,07	1502,24	1,08223	HOLD_1500
07:00:08,997	27519	6,12643	1,47807	1,47896	2737,15	1501,41	1,06819	HOLD_1500
07:02:03,996	27521	6,13031	1,47831	1,47921	2737,28	1502,36	1,09462	HOLD_1500
07:03:58,995	27521	6,12801	1,478	1,4789	2737,33	1501,8	1,06037	HOLD_1500
07:05:53,995	27522	6,12592	1,47804	1,47895	2737,48	1501,29	1,06493	HOLD_1500
07:07:48,995	27524	6,12789	1,47814	1,47903	2737,66	1501,77	1,07586	HOLD_1500
07:09:43,994	27524	6,12774	1,47799	1,47888	2737,66	1501,74	1,05939	HOLD_1500
07:11:38,994	27524,2	6,12509	1,47781	1,4787	2737,74	1501,09	1,03984	HOLD_1500
07:13:33,993	27527	6,13363	1,47797	1,47886	2737,86	1503,18	1,05708	HOLD_1500
07:15:28,993	27527	6,13192	1,47778	1,47868	2737,9	1502,76	1,03701	HOLD_1500
07:17:23,993	27527	6,12984	1,47778	1,47869	2737,94	1502,25	1,03614	HOLD_1500
07:19:18,992	27527	6,12717	1,4776	1,4785	2738	1501,6	1,01701	HOLD_1500
07:21:13,991	27528	6,12625	1,47745	1,47835	2738,13	1501,37	1,00021	HOLD_1500
07:23:08,991	27529	6,1257	1,47756	1,47845	2738,25	1501,24	1,01257	HOLD_1500
07:25:03,990	27529	6,12509	1,47773	1,47863	2738,26	1501,09	1,03159	HOLD_1500
07:26:58,989	27533	6,13285	1,47823	1,47912	2738,53	1502,99	1,08616	HOLD_1500
07:28:53,989	27533	6,13284	1,47769	1,4786	2738,53	1502,99	1,02702	HOLD_1500
07:30:48,989	27533	6,13075	1,47753	1,47842	2738,57	1502,47	1,00892	HOLD_1500
07:32:43,988	27533	6,12782	1,47736	1,47825	2738,64	1501,76	,990831	HOLD_1500
07:34:38,988	27533	6,12562	1,47728	1,47818	2738,68	1501,22	,981551	HOLD_1500
07:36:33,987	27534	6,12671	1,47734	1,47821	2738,77	1501,48	,988011	HOLD_1500
07:38:28,987	27534	6,12482	1,47726	1,47814	2738,81	1501,02	,979379	HOLD_1500
07:40:23,986	27535	6,12661	1,47738	1,47826	2738,88	1501,46	,993122	HOLD_1500
07:42:18,986	27535	6,12476	1,47717	1,47805	2738,92	1501	,969859	HOLD_1500
07:44:13,985	27536	6,12633	1,4773	1,47819	2738,99	1501,39	,98378	HOLD_1500
07:46:08,984	27537	6,12573	1,47724	1,47812	2739,12	1501,24	,977565	HOLD_1500
07:48:03,984	27537	6,12531	1,47722	1,47811	2739,12	1501,14	,975328	HOLD_1500
07:49:58,984	27538	6,12643	1,47714	1,47802	2739,21	1501,41	,966056	HOLD_1500
07:51:53,983	27538	6,12489	1,47703	1,47792	2739,24	1501,04	,954751	HOLD_1500
07:53:48,983	27539	6,1266	1,47701	1,47789	2739,31	1501,46	,952674	HOLD_1500
07:55:43,982	27539	6,12488	1,4769	1,47778	2739,35	1501,04	,940209	HOLD_1500
07:57:38,981	27540	6,12717	1,47708	1,47795	2739,41	1501,6	,960008	HOLD_1500
07:59:33,981	27540	6,12502	1,47686	1,47774	2739,46	1501,07	,936272	HOLD_1500
08:01:28,981	27541	6,12591	1,47688	1,47777	2739,55	1501,29	,938143	HOLD_1500
08:03:23,980	27541	6,12471	1,47674	1,47762	2739,57	1500,99	,922629	HOLD_1500
08:05:18,979	27542	6,12604	1,47678	1,47767	2739,65	1501,32	,927323	HOLD_1500
08:07:13,979	27545	6,13223	1,47729	1,47818	2739,84	1502,84	,983238	HOLD_1500
08:08:08,979	27545	6,1332	1,47721	1,47809	2739,82	1503,07	,974043	HOLD_1500