File: Example - Raw files/Ødo 2015/G6-1_CRS_D8-55.lvm
Oedometer-2	08.10.2015
*Header*
Operator	G6.1_2015
Site	Stjørdal
Hole
Depth [m]	8,55
Comment
Sample area [cm2]	20
Sample height [mm]	20
*Calibration data *
Motor [steps/rev]	16000
Jack [µm/rev]	794
Load cell fact. [N/V]	488,3
Pore sens. fact. [kPa/V]	109
LVDT fact. [µm/V]	-1050
SelfDeform factor	,495368
SelfDeform exp	,75
Slack [steps]	0

        		Load	Pore			Vertica	Pore
Mean        	Deform.	cell	sens.	LVDT.	Deforma	stress	pressur
time        	[steps]	[V]	[V]	[V]	[µm]	[kPa]	[kPa]	MODE
------------	-------	-------	-------	-------	-------	-------	-------	-------
09:45:05,805	0	,004249	,772952	0	-0	0	0	ZERO
09:46:00,804	92,16	,010396	,778636	,776338	3,4437	1,50098	,619533	CRS
09:47:00,804	192,84	,012911	,782268	,779995	8,10865	2,11487	1,01551	CRS
09:48:00,803	293,5	,014821	,784797	,782505	12,8684	2,5812	1,29113	CRS
09:49:00,803	394,16	,016708	,787159	,784879	17,6413	3,04187	1,54853	CRS
09:50:00,803	494,84	,018227	,788562	,786294	22,4646	3,41275	1,70153	CRS
09:51:00,802	595,5	,01975	,789895	,787617	27,2911	3,7846	1,84686	CRS
09:52:00,801	696,16	,021181	,79108	,788814	32,1316	4,13408	1,97598	CRS
09:53:00,801	796,84	,022584	,792196	,789913	36,9792	4,47658	2,09766	CRS
09:54:00,800	897,5	,023862	,793086	,790776	41,8416	4,78861	2,19458	CRS
09:55:00,800	998,16	,025236	,794211	,791896	46,6963	5,12414	2,31728	CRS
09:56:00,799	1098,84	,026552	,795027	,792737	51,5602	5,4454	2,40619	CRS
09:57:00,799	1199,5	,027907	,795938	,793671	56,4211	5,77626	2,50546	CRS
09:58:00,798	1300,16	,029224	,796734	,794475	61,2877	6,09772	2,59231	CRS
09:59:00,798	1400,84	,030564	,797639	,795368	66,1547	6,42485	2,69094	CRS
10:00:00,797	1501,5	,032096	,798898	,796611	71,0042	6,79889	2,82811	CRS
10:01:00,797	1602,16	,033645	,800231	,797951	75,8541	7,1771	2,97338	CRS
10:02:00,796	1702,84	,035312	,801627	,799351	80,696	7,58419	3,12557	CRS
10:03:00,795	1803,54	,036873	,8028	,800511	85,5506	7,96529	3,25346	CRS
10:04:00,795	1904,18	,038602	,804367	,802055	90,3889	8,38741	3,42427	CRS
10:05:00,794	2004,88	,040134	,805441	,803153	95,2496	8,76145	3,54133	CRS
10:06:00,794	2105,56	,042048	,807077	,80482	100,077	9,22881	3,71963	CRS
10:07:00,793	2206,22	,043712	,808379	,806121	104,928	9,63489	3,86152	CRS
10:08:00,793	2306,92	,045765	,810138	,807848	109,748	10,1363	4,05325	CRS
10:09:00,792	2407,62	,047532	,811432	,809126	114,595	10,5675	4,19436	CRS
10:10:00,792	2508,26	,049318	,812732	,810453	119,439	11,0036	4,33604	CRS
10:11:00,792	2608,94	,051245	,814347	,812075	124,275	11,4741	4,51208	CRS
10:12:00,791	2709,64	,052974	,815415	,813131	129,129	11,8962	4,6285	CRS
10:13:00,790	2810,28	,054871	,816647	,814355	133,969	12,3595	4,76277	CRS
10:14:00,790	2910,98	,056767	,817903	,815612	138,812	12,8223	4,89963	CRS
10:15:00,790	3011,68	,058598	,818729	,816454	143,662	13,2695	4,98968	CRS
10:16:00,789	3112,32	,060747	,820248	,817999	148,486	13,794	5,15529	CRS
10:17:00,789	3213	,062695	,821115	,818837	153,329	14,2697	5,24983	CRS
10:18:00,788	3313,68	,06493	,82261	,820304	158,15	14,8153	5,41279	CRS
10:19:00,788	3414,32	,066931	,823669	,82138	162,989	15,3038	5,52816	CRS
10:20:00,787	3515	,069435	,825586	,823311	167,793	15,9154	5,73711	CRS
10:21:00,786	3615,68	,069008	,821864	,819561	172,822	15,8109	5,33145	CRS
10:22:00,786	3716,32	,071235	,822645	,82034	177,647	16,3548	5,41652	CRS
10:23:00,785	3817	,072912	,822116	,819809	182,516	16,7642	5,35894	CRS
10:24:00,785	3917,68	,075015	,822497	,820193	187,355	17,2777	5,40045	CRS
10:25:00,784	4018,32	,076759	,822135	,819837	192,219	17,7035	5,36096	CRS
10:26:00,783	4119	,079658	,823982	,821707	197,001	18,4111	5,56228	CRS
10:27:00,783	4219,68	,081643	,823952	,821668	201,851	18,8957	5,559	CRS
10:28:00,782	4320,32	,084084	,824881	,822615	206,667	19,4918	5,66025	CRS
10:29:00,782	4421	,086654	,825974	,823703	211,478	20,1194	5,7794	CRS
10:30:00,781	4521,68	,089362	,827233	,824972	216,28	20,7804	5,91663	CRS
10:31:00,781	4622,32	,091354	,826889	,824626	221,132	21,2668	5,8792	CRS
10:32:00,780	4723	,093603	,827075	,824811	225,969	21,8158	5,89939	CRS
10:33:00,780	4823,68	,096731	,828817	,826537	230,746	22,5797	6,08926	CRS
10:34:00,780	4924,32	,098929	,828692	,826412	235,586	23,1162	6,07572	CRS
10:35:00,779	5025	,101233	,828553	,826282	240,423	23,6788	6,06051	CRS
10:36:00,778	5125,68	,104311	,829656	,827362	245,207	24,4301	6,18076	CRS
10:37:00,778	5226,32	,107509	,831158	,828887	249,983	25,2109	6,34446	CRS
10:38:00,778	5327	,11053	,832244	,829988	254,774	25,9487	6,46283	CRS
10:39:00,777	5427,68	,113587	,833304	,831058	259,564	26,695	6,57838	CRS
10:40:00,776	5528,32	,117142	,835512	,833225	264,321	27,5629	6,81905	CRS
10:41:00,776	5629	,120431	,836712	,834409	269,099	28,366	6,94984	CRS
10:42:00,775	5729,68	,122348	,835517	,833237	273,969	28,8341	6,81956	CRS
10:43:00,775	5830,32	,126355	,837637	,835368	278,701	29,8122	7,05063	CRS
10:44:00,774	5931	,129338	,837995	,835742	283,503	30,5406	7,08967	CRS
10:45:00,773	6031,68	,133645	,841091	,838831	288,221	31,5922	7,42712	CRS
10:46:00,773	6132,32	,137008	,84211	,839858	292,999	32,4133	7,53829	CRS
10:47:00,772	6233	,139892	,841756	,839503	297,811	33,1174	7,49961	CRS
10:48:00,772	6333,7	,144097	,843803	,841561	302,542	34,1439	7,7228	CRS
10:49:00,771	6434,36	,147174	,843488	,841237	307,344	34,8952	7,68847	CRS
10:50:00,771	6535,02	,150989	,845068	,842816	312,1	35,8268	7,86062	CRS
10:51:00,770	6635,72	,155191	,847225	,844935	316,837	36,8527	8,09581	CRS
10:52:00,769	6736,38	,158728	,847874	,845599	321,614	37,7162	8,16657	CRS
10:53:00,769	6837,06	,163275	,850309	,848063	326,331	38,8264	8,4319	CRS
10:54:00,769	6937,76	,16766	,852208	,849935	331,061	39,8969	8,63895	CRS
10:55:00,768	7038,4	,172097	,854038	,851747	335,787	40,9801	8,8384	CRS
10:56:00,768	7139,1	,174901	,851789	,849526	340,615	41,6649	8,59321	CRS
10:57:00,767	7239,8	,179195	,852676	,850393	345,356	42,7132	8,6899	CRS
10:58:00,767	7340,44	,183396	,853213	,850923	350,1	43,7388	8,74844	CRS
10:59:00,766	7441,12	,18784	,854106	,851828	354,833	44,8237	8,84581	CRS
11:00:00,766	7541,82	,185536	,841427	,839189	359,967	44,2613	7,46378	CRS
11:01:00,766	7642,48	,192645	,84616	,84389	364,543	45,997	7,97973	CRS
11:02:00,765	7743,16	,197746	,847914	,845654	369,242	47,2424	8,17088	CRS
11:03:00,764	7843,84	,200191	,843717	,841488	374,096	47,8394	7,71345	CRS
11:04:00,764	7944,5	,205149	,844613	,842383	378,805	49,0497	7,81106	CRS
11:05:00,763	8045,16	,209268	,844255	,842028	383,563	50,0554	7,772	CRS
11:06:00,762	8145,84	,214721	,846824	,844557	388,248	51,3869	8,05206	CRS
11:07:00,762	8246,5	,219487	,847688	,845436	392,972	52,5505	8,1463	CRS
11:08:00,762	8347,16	,225345	,849746	,847533	397,637	53,9806	8,37052	CRS
11:09:00,761	8447,84	,229799	,849583	,847373	402,383	55,0681	8,35278	CRS
11:10:00,760	8548,5	,235545	,851144	,848918	407,057	56,4709	8,52297	CRS
11:11:00,760	8649,16	,239612	,849811	,847602	411,827	57,4641	8,37767	CRS
11:12:00,759	8749,84	,24506	,851196	,848973	416,522	58,7941	8,52863	CRS
11:13:00,759	8850,5	,249934	,851243	,84903	421,249	59,984	8,53376	CRS
11:14:00,758	8951,16	,254952	,851558	,849333	425,97	61,2093	8,56806	CRS
11:15:00,758	9051,84	,260503	,852354	,850114	430,665	62,5644	8,65478	CRS
11:16:00,757	9152,5	,266615	,854174	,851932	435,329	64,0567	8,85326	CRS
11:17:00,757	9253,16	,272062	,854775	,852557	440,032	65,3866	8,91873	CRS
11:18:00,756	9353,84	,278363	,856668	,854463	444,691	66,925	9,12504	CRS
11:19:00,755	9454,5	,283612	,856088	,853889	449,407	68,2066	9,06187	CRS
11:20:00,755	9555,16	,290091	,858359	,856156	454,059	69,7885	9,30934	CRS
11:21:00,755	9655,84	,296294	,859682	,857476	458,729	71,3028	9,45359	CRS
11:22:00,754	9756,5	,302813	,861703	,859454	463,383	72,8946	9,67386	CRS
11:23:00,753	9857,16	,3083	,860836	,858599	468,092	74,2341	9,57941	CRS
11:24:00,753	9957,84	,313908	,859896	,857692	472,798	75,6034	9,47697	CRS
11:25:00,753	10058,5	,321526	,863373	,861144	477,4	77,4633	9,85593	CRS
11:26:00,752	10159,2	,329208	,866875	,864677	482,001	79,3388	10,2376	CRS
11:27:00,752	10259,8	,334155	,863902	,861675	486,745	80,5467	9,91356	CRS
11:28:00,751	10360,5	,340723	,863898	,861674	491,407	82,1502	9,91318	CRS
11:29:00,750	10461,2	,348203	,865579	,863374	496,024	83,9765	10,0964	CRS
11:30:00,750	10561,8	,354011	,864388	,862166	500,728	85,3946	9,96657	CRS
11:31:00,749	10662,5	,36191	,866933	,864752	505,328	87,3229	10,2439	CRS
11:32:00,749	10763,2	,369117	,868329	,866141	509,965	89,0825	10,3961	CRS
11:33:00,749	10863,8	,376163	,868151	,865971	514,612	90,8028	10,3767	CRS
11:34:00,748	10964,5	,381956	,866295	,864116	519,322	92,2173	10,1745	CRS
11:35:00,747	11065,2	,389584	,867753	,865576	523,942	94,0797	10,3334	CRS
11:36:00,747	11165,9	,396207	,867548	,865376	528,616	95,6967	10,311	CRS
11:37:00,746	11266,5	,403268	,867437	,865268	533,268	97,4206	10,2988	CRS
11:38:00,745	11367,2	,409952	,867228	,86506	537,94	99,0524	10,2761	CRS
11:39:00,745	11467,9	,416908	,867245	,865078	542,601	100,751	10,278	CRS
11:40:00,744	11568,6	,423991	,867299	,86514	547,257	102,48	10,2838	CRS
11:41:00,744	11669,2	,430674	,866409	,864244	551,932	104,112	10,1868	CRS
11:42:00,743	11769,9	,437738	,866547	,864389	556,592	105,836	10,2018	CRS
11:43:00,742	11870,6	,445112	,866959	,864807	561,238	107,637	10,2468	CRS
11:44:00,742	11971,3	,452092	,866961	,864815	565,904	109,341	10,247	CRS
11:45:00,742	12072	,459835	,867911	,86576	570,536	111,231	10,3505	CRS
11:46:00,741	12172,7	,466551	,867068	,864931	575,219	112,871	10,2586	CRS
11:47:00,741	12273,3	,474172	,867941	,865797	579,857	114,732	10,3538	CRS
11:48:00,741	12374	,481801	,868729	,86659	584,499	116,594	10,4397	CRS
11:49:00,740	12474,7	,490221	,870831	,868681	589,106	118,65	10,6689	CRS
11:50:00,740	12575,3	,497575	,870301	,868166	593,761	120,446	10,611	CRS
11:51:00,739	12676	,505297	,870669	,868528	598,402	122,331	10,6512	CRS
11:52:00,738	12776,7	,511941	,868941	,866814	603,094	123,953	10,4628	CRS
11:53:00,738	12877,3	,519616	,869661	,86753	607,738	125,827	10,5413	CRS
11:54:00,737	12978	,526852	,869162	,867038	612,405	127,594	10,4869	CRS
11:55:00,737	13078,7	,53522	,871063	,868928	617,022	129,637	10,6941	CRS
11:56:00,736	13179,3	,542744	,870829	,868702	621,677	131,474	10,6686	CRS
11:57:00,736	13280	,551514	,87331	,871191	626,279	133,615	10,939	CRS
11:58:00,735	13380,7	,559082	,87275	,870615	630,936	135,463	10,878	CRS
11:59:00,734	13481,3	,567553	,874647	,872542	635,552	137,531	11,0847	CRS
12:00:00,734	13582	,57553	,874413	,872305	640,194	139,478	11,0593	CRS
12:01:00,734	13682,7	,582996	,874048	,871947	644,859	141,301	11,0195	CRS
12:02:00,733	13783,3	,591691	,875362	,873269	649,47	143,424	11,1627	CRS
12:03:00,732	13884	,598652	,874032	,871929	654,159	145,124	11,0177	CRS
12:04:00,732	13984,7	,607091	,875102	,873019	658,785	147,184	11,1344	CRS
12:05:00,731	14085,3	,614235	,874629	,872541	663,467	148,928	11,0828	CRS
12:06:00,730	14186	,622678	,875597	,873513	668,095	150,99	11,1883	CRS
12:07:00,730	14286,7	,629323	,874086	,872	672,803	152,612	11,0236	CRS
12:08:00,730	14387,3	,637628	,875467	,873391	677,437	154,64	11,1742	CRS
12:09:00,729	14488	,644881	,87523	,873155	682,12	156,41	11,1483	CRS
12:10:00,729	14588,7	,653612	,877104	,875006	686,74	158,542	11,3526	CRS
12:11:00,728	14689,3	,660944	,876936	,874844	691,42	160,332	11,3343	CRS
12:12:00,728	14790	,669473	,878607	,876498	696,051	162,414	11,5164	CRS
12:13:00,728	14890,7	,67652	,877626	,875527	700,747	164,135	11,4095	CRS
12:14:00,727	14991,3	,685464	,880079	,878011	705,36	166,319	11,6769	CRS
12:15:00,726	15092	,691837	,877926	,875822	710,086	167,875	11,4422	CRS
12:16:00,726	15192,7	,700419	,879908	,877853	714,719	169,97	11,6582	CRS
12:17:00,725	15293,3	,706964	,878598	,876502	719,437	171,568	11,5155	CRS
12:18:00,725	15394	,715114	,880229	,878179	724,091	173,558	11,6932	CRS
12:19:00,724	15494,7	,721119	,877874	,875785	728,835	175,024	11,4365	CRS
12:20:00,723	15595,3	,729081	,87984	,877792	733,495	176,968	11,6508	CRS
12:21:00,723	15696	,735676	,878828	,876749	738,216	178,578	11,5405	CRS
12:22:00,722	15796,7	,743617	,880671	,878629	742,882	180,517	11,7414	CRS
12:23:00,722	15897,4	,749958	,879217	,877159	747,614	182,065	11,583	CRS
12:24:00,721	15998	,757369	,880489	,878456	752,303	183,874	11,7216	CRS
12:25:00,720	16098,7	,763526	,878829	,876761	757,044	185,378	11,5406	CRS
12:26:00,720	16199,4	,770142	,879269	,877211	761,767	186,993	11,5885	CRS
12:27:00,720	16300,1	,77697	,879272	,87722	766,482	188,66	11,5889	CRS
12:28:00,719	16400,8	,783448	,879622	,877582	771,212	190,242	11,6271	CRS
12:29:00,718	16501,4	,789406	,878264	,876199	775,963	191,696	11,4791	CRS
12:30:00,718	16602,1	,795173	,877657	,875598	780,723	193,104	11,4128	CRS
12:31:00,718	16702,8	,80169	,877594	,875541	785,454	194,695	11,406	CRS
12:32:00,717	16803,5	,806705	,876267	,874239	790,244	195,92	11,2614	CRS
12:33:00,717	16904,1	,81335	,877131	,875094	794,97	197,542	11,3556	CRS
12:34:00,716	17004,8	,819161	,877239	,875197	799,731	198,961	11,3673	CRS
12:35:00,716	17105,5	,825519	,877598	,875553	804,468	200,513	11,4065	CRS
12:36:00,716	17206,2	,83082	,876857	,874829	809,249	201,808	11,3256	CRS
12:37:00,715	17306,8	,837118	,877668	,875621	813,99	203,345	11,414	CRS
12:38:00,714	17407,5	,842138	,876743	,87472	818,783	204,571	11,3132	CRS
12:39:00,714	17508,2	,849013	,878988	,876956	823,501	206,249	11,5579	CRS
12:40:00,713	17608,8	,854217	,878246	,876201	828,288	207,52	11,477	CRS
12:41:00,713	17709,5	,861499	,880878	,878879	832,991	209,298	11,7639	CRS
12:42:00,712	17810,2	,866948	,880419	,878425	837,768	210,628	11,714	CRS
12:43:00,712	17910,8	,874182	,883053	,881036	842,475	212,394	12,001	CRS
12:44:00,711	18011,5	,879215	,882057	,880044	847,269	213,623	11,8925	CRS
12:45:00,710	18112,2	,886713	,885469	,883473	851,965	215,454	12,2643	CRS
12:46:00,710	18212,8	,89173	,884199	,882203	856,762	216,679	12,1259	CRS
12:47:00,709	18313,5	,898457	,886254	,884262	861,49	218,321	12,35	CRS
12:48:00,709	18414,2	,903301	,88542	,883427	866,293	219,504	12,2591	CRS
12:49:00,708	18514,8	,910004	,887542	,885532	871,024	221,14	12,4903	CRS
12:50:00,708	18615,5	,914656	,886119	,884132	875,835	222,276	12,3352	CRS
12:51:00,707	18716,2	,921118	,888219	,886211	880,575	223,854	12,5641	CRS
12:52:00,706	18816,8	,926016	,88745	,88545	885,379	225,049	12,4803	CRS
12:53:00,706	18917,5	,931577	,888092	,886076	890,155	226,407	12,5503	CRS
12:54:00,705	19018,2	,936091	,886569	,884588	894,973	227,509	12,3843	CRS
12:55:00,705	19118,8	,942069	,88866	,886651	899,734	228,969	12,6122	CRS
12:56:00,705	19219,5	,946711	,887293	,885299	904,548	230,102	12,4632	CRS
12:57:00,704	19320,2	,951635	,88774	,885743	909,35	231,304	12,5119	CRS
12:58:00,704	19420,8	,956572	,887434	,885443	914,154	232,51	12,4786	CRS
12:59:00,704	19521,5	,96113	,88754	,885548	918,971	233,623	12,4901	CRS
13:00:00,703	19622,2	,966327	,887823	,885826	923,763	234,891	12,5209	CRS
13:01:00,702	19722,8	,970953	,888072	,886082	928,58	236,021	12,5481	CRS
13:02:00,702	19823,5	,976585	,88902	,887021	933,356	237,396	12,6515	CRS
13:03:00,701	19924,2	,980867	,888462	,88646	938,185	238,441	12,5906	CRS
13:04:00,700	20024,8	,986473	,889698	,887719	942,963	239,81	12,7253	CRS
13:05:00,700	20125,5	,990191	,888613	,886608	947,815	240,718	12,607	CRS
13:06:00,700	20226,2	,995719	,889974	,888003	952,596	242,068	12,7554	CRS
13:07:00,699	20326,8	,999824	,88958	,887602	957,433	243,07	12,7125	CRS
13:08:00,698	20427,5	1,00559	,891298	,889353	962,207	244,478	12,8997	CRS
13:09:00,698	20528,2	1,00968	,890737	,888792	967,045	245,477	12,8386	CRS
13:10:00,697	20628,9	1,01545	,892796	,890846	971,82	246,885	13,063	CRS
13:11:00,697	20729,6	1,01927	,891968	,890025	976,669	247,817	12,9728	CRS
13:12:00,696	20830,2	1,02427	,892953	,891008	981,472	249,039	13,0801	CRS
13:13:00,695	20930,9	1,02778	,891344	,88941	986,334	249,895	12,9048	CRS
13:14:00,695	21031,6	1,03266	,892335	,890399	991,143	251,087	13,0128	CRS
13:15:00,694	21132,2	1,03653	,891693	,889756	995,99	252,031	12,9428	CRS
13:16:00,694	21232,9	1,04224	,894216	,892261	1000,77	253,426	13,2178	CRS
13:17:00,694	21333,6	1,04596	,893517	,891581	1005,62	254,333	13,1416	CRS
13:18:00,693	21434,3	1,05141	,895719	,893756	1010,41	255,664	13,3816	CRS
13:19:00,693	21535	1,05418	,892813	,89088	1015,3	256,341	13,0649	CRS
13:20:00,692	21635,7	1,05887	,894117	,892173	1020,12	257,487	13,207	CRS
13:21:00,692	21736,3	1,06135	,891148	,889223	1025,02	258,091	12,8834	CRS
13:22:00,691	21837	1,06585	,892308	,890384	1029,84	259,189	13,0098	CRS
13:23:00,691	21937,7	1,06894	,890658	,888731	1034,72	259,945	12,83	CRS
13:24:00,690	22038,3	1,07363	,892395	,890475	1039,54	261,089	13,0193	CRS
13:25:00,690	22139	1,07713	,891003	,889078	1044,4	261,943	12,8676	CRS
13:26:00,689	22239,7	1,08209	,893485	,891558	1049,21	263,156	13,1381	CRS
13:27:00,688	22340,3	1,08604	,892798	,890875	1054,06	264,119	13,0633	CRS
13:28:00,688	22441	1,08999	,893641	,891709	1058,9	265,083	13,1551	CRS
13:29:00,687	22541,7	1,09347	,892437	,890521	1063,77	265,934	13,0239	CRS
13:30:00,687	22642,3	1,09703	,892553	,890632	1068,63	266,803	13,0365	CRS
13:31:00,686	22743	1,10148	,893179	,891256	1073,46	267,889	13,1047	CRS
13:32:00,686	22843,7	1,10589	,894685	,892747	1078,29	268,965	13,2689	CRS
13:33:00,685	22944,3	1,11159	,897234	,895307	1083,07	270,358	13,5468	CRS
13:34:00,684	23045	1,11604	,897956	,896037	1087,89	271,445	13,6255	CRS
13:35:00,684	23145,7	1,1215	,899861	,897944	1092,69	272,778	13,8331	CRS
13:36:00,684	23246,3	1,12453	,898463	,896545	1097,57	273,516	13,6807	CRS
13:37:00,683	23347	1,1291	,899359	,897438	1102,39	274,633	13,7784	CRS
13:38:00,683	23447,7	1,13189	,897678	,895758	1107,28	275,313	13,5951	CRS
13:39:00,682	23548,3	1,1365	,898895	,896983	1112,1	276,44	13,7278	CRS
13:40:00,682	23649	1,13921	,897366	,895441	1117	277,1	13,5611	CRS
13:41:00,681	23749,7	1,14437	,899795	,89788	1121,8	278,36	13,8259	CRS
13:42:00,681	23850,3	1,14666	,897325	,895407	1126,71	278,921	13,5567	CRS
13:43:00,680	23951	1,15184	,899224	,89731	1131,51	280,183	13,7637	CRS
13:44:00,680	24051,7	1,15381	,896472	,894554	1136,44	280,666	13,4637	CRS
13:45:00,679	24152,3	1,15907	,899511	,897604	1141,24	281,949	13,795	CRS
13:46:00,679	24253	1,16136	,896943	,895032	1146,15	282,51	13,515	CRS
13:47:00,678	24353,7	1,16647	,899512	,897608	1150,95	283,758	13,7951	CRS
13:48:00,678	24454,3	1,16892	,89721	,895303	1155,86	284,353	13,5442	CRS
13:49:00,677	24555	1,17391	,89965	,897749	1160,67	285,572	13,8102	CRS
13:50:00,676	24655,7	1,17659	,89782	,895921	1165,56	286,228	13,6107	CRS
13:51:00,676	24756,3	1,1813	,899706	,89781	1170,38	287,377	13,8162	CRS
13:52:00,675	24857	1,18395	,897697	,895803	1175,28	288,024	13,5972	CRS
13:53:00,675	24957,7	1,18865	,899897	,898015	1180,1	289,173	13,837	CRS
13:54:00,674	25058,3	1,19156	,898248	,896352	1184,99	289,881	13,6573	CRS
13:55:00,673	25159	1,19567	,899621	,897735	1189,84	290,886	13,8069	CRS
13:56:00,673	25259,7	1,19964	,899379	,897491	1194,69	291,856	13,7806	CRS
13:57:00,672	25360,4	1,2037	,90048	,898608	1199,53	292,847	13,9006	CRS
13:58:00,672	25461	1,20807	,900891	,89905	1204,37	293,913	13,9454	CRS
13:59:00,671	25561,8	1,21148	,900851	,898999	1209,24	294,745	13,941	CRS
14:00:00,671	25662,4	1,21592	,901393	,899579	1214,07	295,829	14,0001	CRS
14:01:00,670	25763,1	1,21872	,900447	,898581	1218,96	296,513	13,897	CRS
14:02:00,670	25863,8	1,22297	,900757	,898911	1223,8	297,551	13,9308	CRS
14:03:00,670	25964,4	1,22587	,900348	,898484	1228,69	298,26	13,8862	CRS
14:04:00,670	26065,1	1,23149	,902828	,901084	1233,48	299,63	14,1565	CRS
14:05:00,669	26165,8	1,23601	,904202	,902393	1238,31	300,735	14,3063	CRS
14:06:00,668	26266,5	1,24057	,904497	,902667	1243,14	301,847	14,3384	CRS
14:07:00,668	26367,1	1,24294	,902425	,900689	1248,05	302,427	14,1125	CRS
14:08:00,667	26467,8	1,24806	,904668	,902823	1252,86	303,676	14,3571	CRS
14:09:00,667	26568,5	1,2502	,902166	,900422	1257,78	304,199	14,0844	CRS
14:10:00,666	26669,2	1,25514	,904081	,902283	1262,59	305,406	14,2931	CRS
14:11:00,666	26769,8	1,25894	,904181	,902378	1267,45	306,333	14,304	CRS
14:12:00,665	26870,5	1,26382	,905145	,903276	1272,27	307,523	14,4091	CRS
14:13:00,664	26971,2	1,26564	,902888	,901174	1277,2	307,969	14,1631	CRS
14:14:00,664	27071,8	1,27079	,905601	,903719	1282,01	309,227	14,4588	CRS
14:15:00,663	27172,5	1,27288	,902757	,901043	1286,93	309,736	14,1488	CRS
14:16:00,663	27273,2	1,27739	,90428	,902472	1291,76	310,839	14,3147	CRS
14:17:00,662	27373,8	1,28005	,902394	,900668	1296,66	311,486	14,1092	CRS
14:18:00,662	27474,5	1,28503	,904647	,90281	1301,47	312,704	14,3547	CRS
14:19:00,661	27575,2	1,28774	,90271	,901002	1306,37	313,364	14,1436	CRS
14:20:00,660	27675,8	1,29127	,902584	,900868	1311,24	314,227	14,1299	CRS
14:21:00,660	27776,5	1,29382	,901005	,899182	1316,14	314,849	13,9578	CRS
14:22:00,660	27877,2	1,29769	,90186	,900104	1320,99	315,795	14,0509	CRS
14:23:00,658	27977,8	1,301	,900988	,899175	1325,87	316,601	13,9559	CRS
14:24:00,658	28078,5	1,30487	,90192	,900176	1330,73	317,547	14,0576	CRS
14:25:00,658	28179,2	1,30847	,901305	,899514	1335,59	318,427	13,9905	CRS
14:26:00,657	28279,8	1,31235	,902335	,900607	1340,45	319,374	14,1028	CRS
14:27:00,657	28380,5	1,31805	,904932	,903115	1345,24	320,764	14,3859	CRS
14:28:00,657	28481,2	1,32306	,907242	,905373	1350,05	321,988	14,6376	CRS
14:29:00,656	28581,8	1,32891	,90924	,907389	1354,84	323,416	14,8554	CRS
14:30:00,656	28682,5	1,33221	,908412	,906558	1359,71	324,222	14,7651	CRS
14:31:00,655	28783,2	1,33632	,907622	,905768	1364,56	325,225	14,6791	CRS
14:32:00,654	28883,8	1,33935	,90673	,904866	1369,45	325,965	14,5819	CRS
14:33:00,654	28984,5	1,34412	,907622	,905766	1374,27	327,13	14,6791	CRS
14:34:00,654	29085,2	1,3478	,907682	,905837	1379,14	328,028	14,6856	CRS
14:35:00,653	29185,8	1,353	,909378	,90754	1383,95	329,297	14,8704	CRS
14:36:00,652	29286,5	1,35665	,909244	,907412	1388,81	330,188	14,8558	CRS
14:37:00,652	29387,2	1,36114	,909581	,907742	1393,65	331,286	14,8926	CRS
14:38:00,651	29487,8	1,36453	,909126	,907295	1398,52	332,114	14,8429	CRS
14:39:00,650	29588,5	1,36958	,910627	,908797	1403,34	333,347	15,0066	CRS
14:40:00,650	29689,2	1,37241	,908894	,907061	1408,23	334,038	14,8177	CRS
14:41:00,650	29789,9	1,37778	,911086	,909263	1413,04	335,348	15,0567	CRS
14:42:00,649	29890,5	1,37953	,90723	,905387	1417,97	335,775	14,6364	CRS
14:43:00,649	29991,2	1,38526	,910405	,908577	1422,76	337,173	14,9824	CRS
14:44:00,648	30091,9	1,38782	,908047	,906223	1427,67	337,798	14,7254	CRS
14:45:00,647	30192,6	1,39335	,910821	,908995	1432,47	339,148	15,0277	CRS
14:46:00,647	30293,2	1,39568	,907951	,906119	1437,38	339,717	14,7149	CRS
14:47:00,646	30393,9	1,40126	,910925	,909106	1442,18	341,08	15,0391	CRS
14:48:00,646	30494,6	1,40497	,910199	,908373	1447,04	341,985	14,9599	CRS
14:49:00,645	30595,3	1,41164	,914368	,912523	1451,8	343,615	15,4144	CRS
14:50:00,645	30696	1,41549	,913268	,91144	1456,66	344,554	15,2944	CRS
14:51:00,644	30796,7	1,42134	,915987	,914163	1461,45	345,984	15,5908	CRS
14:52:00,644	30897,3	1,42557	,915459	,913631	1466,3	347,017	15,5333	CRS
14:53:00,643	30998	1,43223	,919341	,917524	1471,06	348,641	15,9564	CRS
14:54:00,643	31098,7	1,43568	,916632	,91482	1475,93	349,484	15,6611	CRS
14:55:00,642	31199,3	1,44061	,918238	,916436	1480,75	350,687	15,8362	CRS
14:56:00,642	31300	1,44418	,916362	,914554	1485,62	351,56	15,6318	CRS
14:57:00,642	31400,7	1,44868	,917422	,915629	1490,46	352,657	15,7473	CRS
14:58:00,641	31501,3	1,45232	,91574	,913916	1495,33	353,546	15,5639	CRS
14:59:00,640	31602	1,45669	,916474	,914665	1500,17	354,614	15,644	CRS
15:00:00,640	31702,7	1,46158	,916698	,914894	1504,99	355,807	15,6683	CRS
15:01:00,639	31803,3	1,46694	,919275	,917466	1509,8	357,115	15,9493	CRS
15:02:00,639	31904	1,4724	,920064	,918244	1514,61	358,448	16,0352	CRS
15:03:00,638	32004,7	1,47649	,919602	,917792	1519,46	359,449	15,9849	CRS
15:04:00,638	32105,3	1,48095	,918963	,917164	1524,3	360,536	15,9152	CRS
15:05:00,637	32206	1,4842	,917759	,915975	1529,18	361,329	15,784	CRS
15:06:00,636	32306,7	1,48998	,919639	,917834	1533,97	362,742	15,9889	CRS
15:07:00,636	32407,3	1,49246	,916796	,915013	1538,88	363,347	15,679	CRS
15:08:00,635	32508	1,49723	,917386	,915605	1543,71	364,512	15,7433	CRS
15:09:00,634	32608,7	1,50016	,915412	,913604	1548,6	365,226	15,5282	CRS
15:10:00,634	32709,3	1,50512	,916435	,914649	1553,42	366,439	15,6397	CRS
15:11:00,634	32810	1,50783	,913868	,912067	1558,33	367,1	15,3599	CRS
15:12:00,633	32910,7	1,51373	,91665	,914868	1563,12	368,539	15,6631	CRS
15:13:00,633	33011,3	1,51757	,915465	,913664	1567,98	369,478	15,534	CRS
15:14:00,632	33112	1,52317	,917622	,915851	1572,78	370,846	15,769	CRS
15:15:00,632	33212,7	1,52641	,915556	,913763	1577,66	371,634	15,5438	CRS
15:16:00,631	33313,3	1,53177	,917409	,915642	1582,47	372,944	15,7458	CRS
15:17:00,631	33414	1,53469	,914907	,913109	1587,37	373,656	15,4731	CRS
15:18:00,630	33514,7	1,54126	,918655	,916883	1592,13	375,261	15,8816	CRS
15:19:00,630	33615,3	1,5452	,917486	,915722	1596,99	376,223	15,7542	CRS
15:20:00,629	33716	1,55147	,920415	,918623	1601,77	377,754	16,0735	CRS
15:21:00,629	33816,7	1,55517	,918283	,916518	1606,64	378,658	15,8411	CRS
15:22:00,628	33917,3	1,56161	,921547	,919748	1611,41	380,229	16,1969	CRS
15:23:00,627	34018	1,56655	,921264	,919467	1616,24	381,437	16,166	CRS
15:24:00,627	34118,7	1,57378	,925453	,923677	1620,98	383,201	16,6226	CRS
15:25:00,626	34219,3	1,57968	,926332	,924559	1625,77	384,642	16,7184	CRS
15:26:00,626	34320	1,58777	,931818	,930041	1630,49	386,618	17,3165	CRS
15:27:00,625	34420,7	1,59351	,931091	,929316	1635,29	388,019	17,2372	CRS
15:28:00,625	34521,4	1,59913	,932082	,930301	1640,09	389,389	17,3452	CRS
15:29:00,624	34622	1,60538	,932755	,930981	1644,88	390,917	17,4185	CRS
15:30:00,623	34722,7	1,61063	,933147	,931383	1649,69	392,198	17,4613	CRS
15:31:00,623	34823,4	1,61572	,932209	,930435	1654,51	393,44	17,3591	CRS
15:32:00,622	34924,1	1,6196	,930407	,928642	1659,38	394,387	17,1626	CRS
15:33:00,622	35024,8	1,62568	,931529	,929762	1664,17	395,872	17,2849	CRS
15:34:00,621	35125,4	1,63021	,930963	,929196	1669,01	396,978	17,2233	CRS
15:35:00,621	35226,1	1,6363	,932257	,930488	1673,79	398,465	17,3642	CRS
15:36:00,621	35326,8	1,64009	,930465	,928706	1678,66	399,391	17,1689	CRS
15:37:00,620	35427,4	1,64615	,931742	,929976	1683,45	400,871	17,3081	CRS
15:38:00,619	35528,1	1,6502	,930087	,92834	1688,31	401,859	17,1278	CRS
15:39:00,619	35628,8	1,65679	,932216	,930457	1693,08	403,467	17,3598	CRS
15:40:00,619	35729,5	1,66078	,930223	,928479	1697,94	404,442	17,1426	CRS
15:41:00,618	35830,2	1,66796	,933193	,931451	1702,69	406,195	17,4663	CRS
15:42:00,618	35930,8	1,67205	,931189	,929432	1707,55	407,193	17,2479	CRS
15:43:00,617	36031,5	1,67905	,933951	,932224	1712,31	408,902	17,5489	CRS
15:44:00,617	36132,2	1,68326	,931907	,930147	1717,16	409,932	17,3261	CRS
15:45:00,616	36232,8	1,68989	,934151	,932429	1721,93	411,55	17,5707	CRS
15:46:00,615	36333,5	1,69517	,9338	,932078	1726,75	412,839	17,5325	CRS
15:47:00,615	36434,2	1,70285	,937464	,935727	1731,48	414,714	17,9318	CRS
15:48:00,615	36534,8	1,70832	,936801	,935076	1736,29	416,05	17,8596	CRS
15:49:00,614	36635,5	1,7159	,939987	,938261	1741,03	417,901	18,2069	CRS
15:50:00,613	36736,2	1,72122	,93875	,937007	1745,85	419,198	18,072	CRS
15:51:00,613	36836,8	1,72835	,941188	,939463	1750,61	420,94	18,3377	CRS
15:52:00,612	36937,5	1,73341	,939544	,937814	1755,43	422,174	18,1585	CRS
15:53:00,612	37038,2	1,73921	,940099	,938372	1760,23	423,591	18,219	CRS
15:54:00,611	37138,8	1,74587	,941164	,939452	1765	425,218	18,3352	CRS
15:55:00,611	37239,5	1,75201	,942004	,940292	1769,79	426,716	18,4267	CRS
15:56:00,610	37340,2	1,75829	,941891	,940177	1774,58	428,25	18,4143	CRS
15:57:00,609	37440,8	1,76449	,94312	,941408	1779,37	429,763	18,5483	CRS
15:58:00,609	37541,5	1,77018	,941864	,940165	1784,17	431,151	18,4115	CRS
15:59:00,608	37642,2	1,77546	,941757	,940054	1788,99	432,442	18,3997	CRS
16:00:00,608	37742,8	1,78185	,941783	,940082	1793,77	434,001	18,4026	CRS
16:01:00,607	37843,5	1,78643	,940414	,938704	1798,61	435,119	18,2534	CRS
16:02:00,607	37944,2	1,79305	,941323	,939617	1803,39	436,736	18,3525	CRS
16:03:00,606	38044,8	1,79827	,940558	,938856	1808,21	438,01	18,269	CRS
16:04:00,606	38145,5	1,80549	,942172	,940477	1812,96	439,774	18,445	CRS
16:05:00,606	38246,2	1,81156	,94279	,941094	1817,76	441,255	18,5124	CRS
16:06:00,605	38346,8	1,81966	,94536	,943619	1822,48	443,233	18,7925	CRS
16:07:00,604	38447,5	1,82418	,942905	,941221	1827,33	444,335	18,5249	CRS
16:08:00,604	38548,2	1,83102	,944115	,94241	1832,1	446,006	18,6568	CRS
16:09:00,603	38648,8	1,83603	,942484	,94081	1836,93	447,23	18,4791	CRS
16:10:00,603	38749,5	1,84375	,945203	,943476	1841,67	449,114	18,7754	CRS
16:11:00,602	38850,2	1,84977	,944849	,943121	1846,46	450,583	18,7368	CRS
16:12:00,602	38950,8	1,85991	,951026	,949349	1851,12	453,06	19,4101	CRS
16:13:00,601	39051,5	1,86771	,952563	,95089	1855,86	454,964	19,5776	CRS
16:14:00,601	39152,2	1,87852	,958616	,956956	1860,5	457,603	20,2374	CRS
16:15:00,600	39252,9	1,88428	,955937	,95425	1865,31	459,009	19,9453	CRS
16:16:00,600	39353,6	1,89291	,958457	,956793	1870,02	461,116	20,22	CRS
16:17:00,599	39454,2	1,89793	,954854	,953185	1874,85	462,342	19,8274	CRS
16:18:00,598	39554,9	1,90602	,957448	,955782	1879,58	464,318	20,1101	CRS
16:19:00,598	39655,6	1,91042	,953398	,951748	1884,43	465,392	19,6686	CRS
16:20:00,597	39756,2	1,91808	,955798	,954122	1889,18	467,261	19,9302	CRS
16:21:00,596	39856,9	1,92261	,951645	,949985	1894,02	468,369	19,4775	CRS
16:22:00,596	39957,6	1,93079	,954959	,953299	1898,75	470,366	19,8388	CRS
16:23:00,596	40058,3	1,93618	,951826	,950176	1903,57	471,681	19,4973	CRS
16:24:00,595	40159	1,94384	,954364	,952711	1908,32	473,552	19,774	CRS
16:25:00,595	40259,7	1,94989	,952339	,950696	1913,12	475,029	19,5532	CRS
16:26:00,594	40360,3	1,95741	,954593	,952937	1917,86	476,864	19,7989	CRS
16:27:00,594	40461	1,96353	,952474	,950833	1922,66	478,36	19,5679	CRS
16:28:00,594	40561,7	1,97079	,954064	,952426	1927,42	480,131	19,7413	CRS
16:29:00,593	40662,3	1,97797	,953695	,952064	1932,18	481,885	19,701	CRS
16:30:00,592	40763	1,98492	,954569	,952925	1936,95	483,582	19,7962	CRS
16:31:00,592	40863,7	1,99246	,954748	,953109	1941,7	485,423	19,8158	CRS
16:32:00,591	40964,3	1,99871	,95441	,952788	1946,49	486,947	19,779	CRS
16:33:00,591	41065	2,00674	,955417	,953775	1951,23	488,909	19,8887	CRS
16:34:00,590	41165,7	2,01345	,955465	,953833	1956,01	490,548	19,8939	CRS
16:35:00,590	41266,3	2,0226	,958367	,956755	1960,71	492,779	20,2102	CRS
16:36:00,589	41367	2,02869	,956552	,954919	1965,51	494,268	20,0124	CRS
16:37:00,588	41467,7	2,03831	,960141	,958535	1970,19	496,616	20,4036	CRS
16:38:00,588	41568,3	2,04409	,957531	,955911	1975	498,028	20,1191	CRS
16:39:00,587	41669	2,05346	,960703	,959092	1979,69	500,315	20,4649	CRS
16:40:00,587	41769,7	2,05926	,958027	,956417	1984,5	501,731	20,1732	CRS
16:41:00,586	41870,3	2,06741	,959381	,957783	1989,23	503,72	20,3208	CRS
16:42:00,586	41971	2,07361	,957911	,956296	1994,03	505,234	20,1605	CRS
16:43:00,585	42071,7	2,0848	,964368	,962752	1998,67	507,967	20,8643	CRS
16:44:00,585	42172,3	2,09354	,965874	,964292	2003,38	510,1	21,0285	CRS
16:45:00,584	42273	2,10294	,968102	,966499	2008,07	512,395	21,2714	CRS
16:46:00,584	42373,7	2,10893	,964947	,963352	2012,88	513,859	20,9275	CRS
16:47:00,584	42474,3	2,11883	,968749	,967154	2017,56	516,275	21,3418	CRS
16:48:00,583	42575	2,12476	,964891	,9633	2022,36	517,724	20,9214	CRS
16:49:00,582	42675,7	2,13484	,968719	,967124	2027,04	520,184	21,3386	CRS
16:50:00,582	42776,3	2,14197	,967099	,965509	2031,8	521,925	21,1621	CRS
16:51:00,582	42877	2,15042	,968185	,966602	2036,53	523,989	21,2804	CRS
16:52:00,581	42977,7	2,15692	,965054	,963475	2041,32	525,576	20,9391	CRS
16:53:00,580	43078,3	2,16583	,967756	,966183	2046,03	527,751	21,2337	CRS
16:54:00,580	43179	2,17198	,964101	,962518	2050,83	529,252	20,8353	CRS
16:55:00,579	43279,7	2,17982	,965022	,963453	2055,58	531,166	20,9356	CRS
16:56:00,579	43380,3	2,18779	,964575	,962997	2060,32	533,112	20,8869	CRS
16:57:00,578	43481	2,19591	,96576	,964201	2065,06	535,095	21,016	CRS
16:58:00,577	43581,7	2,20419	,9653	,963738	2069,79	537,117	20,966	CRS
16:59:00,577	43682,3	2,21102	,964007	,962435	2074,57	538,783	20,825	CRS
17:00:00,576	43783	2,21891	,963506	,961942	2079,32	540,711	20,7704	CRS
17:01:00,576	43883,7	2,22587	,962512	,96094	2084,09	542,409	20,662	CRS
17:02:00,575	43984,4	2,235	,964303	,962747	2088,8	544,638	20,8573	CRS
17:03:00,575	44085	2,24134	,96195	,960396	2093,6	546,185	20,6008	CRS
17:04:00,574	44185,7	2,25077	,964284	,96273	2098,29	548,489	20,8552	CRS
17:05:00,574	44286,4	2,2584	,964198	,962642	2103,05	550,35	20,8458	CRS
17:06:00,574	44387,1	2,27066	,969887	,968347	2107,66	553,344	21,4659	CRS
17:07:00,573	44487,8	2,27963	,970545	,969001	2112,38	555,535	21,5377	CRS
17:08:00,573	44588,4	2,29167	,975404	,973862	2116,99	558,473	22,0672	CRS
17:09:00,572	44689,1	2,29886	,9728	,971253	2121,76	560,228	21,7835	CRS
17:10:00,572	44789,8	2,30908	,97478	,973239	2126,44	562,725	21,9993	CRS
17:11:00,571	44890,5	2,31632	,97245	,970913	2131,21	564,493	21,7453	CRS
17:12:00,571	44991,1	2,32596	,974082	,972538	2135,9	566,846	21,9232	CRS
17:13:00,570	45091,8	2,33368	,972746	,971213	2140,66	568,732	21,7776	CRS
17:14:00,570	45192,5	2,34378	,974972	,973448	2145,34	571,197	22,0202	CRS
17:15:00,569	45293,2	2,35219	,97411	,97258	2150,07	573,251	21,9262	CRS
17:16:00,568	45393,8	2,36218	,975906	,974392	2154,76	575,689	22,122	CRS
17:17:00,568	45494,5	2,36922	,972919	,971393	2159,53	577,409	21,7964	CRS
17:18:00,567	45595,2	2,38005	,976601	,975103	2164,19	580,051	22,1978	CRS
17:19:00,567	45695,8	2,38763	,973616	,972093	2168,95	581,903	21,8724	CRS
17:20:00,566	45796,5	2,39872	,977792	,976272	2173,6	584,611	22,3276	CRS
17:21:00,566	45897,2	2,40629	,974488	,972982	2178,36	586,458	21,9675	CRS
17:22:00,565	45997,8	2,41734	,978261	,97673	2183,02	589,156	22,3787	CRS
17:23:00,564	46098,5	2,4256	,975915	,974419	2187,76	591,172	22,123	CRS
17:24:00,564	46199,2	2,43603	,978825	,977284	2192,43	593,719	22,4402	CRS
17:25:00,564	46299,8	2,44448	,97643	,974946	2197,16	595,783	22,1791	CRS
17:26:00,564	46400,5	2,45492	,979419	,977874	2201,84	598,331	22,5049	CRS
17:27:00,563	46501,2	2,46452	,978809	,977286	2206,54	600,676	22,4385	CRS
17:28:00,562	46601,8	2,47585	,982763	,981312	2211,18	603,441	22,8694	CRS
17:29:00,562	46702,5	2,48701	,983792	,982336	2215,84	606,167	22,9816	CRS
17:30:00,562	46803,2	2,49638	,98383	,982368	2220,54	608,455	22,9858	CRS
17:31:00,561	46903,8	2,50862	,986582	,985128	2225,16	611,441	23,2857	CRS
17:32:00,560	47004,5	2,51875	,987082	,985635	2229,85	613,915	23,3402	CRS
17:33:00,560	47105,2	2,5291	,986525	,985079	2234,53	616,443	23,2795	CRS
17:34:00,559	47205,8	2,53842	,986393	,984959	2239,24	618,717	23,2651	CRS
17:35:00,558	47306,5	2,54947	,987399	,985962	2243,89	621,417	23,3747	CRS
17:36:00,558	47407,2	2,55773	,985545	,98412	2248,64	623,431	23,1727	CRS
17:37:00,557	47507,8	2,56887	,987059	,985627	2253,29	626,153	23,3377	CRS
17:38:00,557	47608,5	2,57793	,985945	,984524	2258,01	628,363	23,2163	CRS
17:39:00,556	47709,2	2,58953	,988628	,9872	2262,66	631,197	23,5087	CRS
17:40:00,556	47809,8	2,59894	,987362	,985938	2267,37	633,494	23,3707	CRS
17:41:00,555	47910,5	2,61049	,989407	,987973	2272,01	636,314	23,5937	CRS
17:42:00,554	48011,2	2,61931	,98716	,985737	2276,74	638,468	23,3487	CRS
17:43:00,554	48111,8	2,63039	,98865	,987234	2281,4	641,172	23,5111	CRS
17:44:00,554	48212,5	2,63813	,985004	,983598	2286,16	643,062	23,1137	CRS
17:45:00,554	48313,2	2,65003	,988271	,986866	2290,79	645,968	23,4697	CRS
17:46:00,553	48413,9	2,6576	,983976	,982563	2295,56	647,816	23,0016	CRS
17:47:00,552	48514,5	2,6684	,985707	,984321	2300,23	650,452	23,1904	CRS
17:48:00,552	48615,2	2,67577	,981418	,98007	2305	652,253	22,7228	CRS
17:49:00,552	48715,9	2,68688	,983857	,982453	2309,67	654,965	22,9887	CRS
17:50:00,551	48816,6	2,69434	,979796	,978323	2314,44	656,786	22,546	CRS
17:51:00,550	48917,2	2,70614	,983431	,982047	2319,08	659,666	22,9422	CRS
17:52:00,550	49017,9	2,71552	,981624	,980293	2323,79	661,956	22,7453	CRS
17:53:00,549	49118,6	2,72626	,98323	,98186	2328,46	664,579	22,9203	CRS
17:54:00,549	49219,3	2,73535	,981348	,980001	2333,19	666,799	22,7152	CRS
17:55:00,548	49320	2,74606	,982916	,981553	2337,86	669,412	22,8861	CRS
17:56:00,548	49420,7	2,75547	,980783	,979397	2342,58	671,71	22,6536	CRS
17:57:00,547	49521,3	2,76693	,983906	,982529	2347,23	674,508	22,994	CRS
17:58:00,546	49622	2,77797	,98402	,982662	2351,89	677,204	23,0064	CRS
17:59:00,546	49722,7	2,78927	,985801	,984456	2356,55	679,964	23,2006	CRS
18:00:00,546	49823,3	2,8014	,986632	,985287	2361,19	682,925	23,2912	CRS
18:01:00,545	49924	2,8125	,987893	,986544	2365,85	685,634	23,4286	CRS
18:02:00,544	50024,7	2,82572	,990537	,989173	2370,45	688,863	23,7168	CRS
18:03:00,544	50125,3	2,83728	,992067	,990697	2375,1	691,684	23,8836	CRS
18:04:00,544	50226	2,85158	,99586	,994519	2379,67	695,176	24,2969	CRS
18:05:00,544	50326,7	2,86298	,995922	,994589	2384,33	697,958	24,3037	CRS
18:06:00,543	50427,3	2,87649	,998754	,997396	2388,93	701,258	24,6124	CRS
18:07:00,542	50528	2,88716	,997402	,996065	2393,61	703,862	24,465	CRS
18:08:00,542	50628,7	2,90075	1,00047	,999135	2398,2	707,181	24,7992	CRS
18:09:00,541	50729,3	2,91156	,998955	,997602	2402,88	709,819	24,6344	CRS
18:10:00,541	50830	2,92517	1,00184	1,00053	2407,47	713,144	24,9493	CRS
18:11:00,540	50930,7	2,9348	,998642	,997299	2412,18	715,494	24,6003	CRS
18:12:00,539	51031,3	2,94783	1,0009	,999587	2416,79	718,675	24,8462	CRS
18:13:00,539	51132	2,95795	,998314	,996981	2421,49	721,146	24,5644	CRS
18:14:00,538	51232,7	2,97193	1,00197	1,00067	2426,07	724,56	24,9634	CRS
18:15:00,538	51333,3	2,98136	,997939	,996629	2430,79	726,863	24,5236	CRS
18:16:00,537	51434	2,99556	1,00216	1,00087	2435,37	730,328	24,9834	CRS
18:17:00,537	51534,7	3,00508	,99824	,996933	2440,09	732,652	24,5565	CRS
18:18:00,536	51635,3	3,01853	1,0014	1,00012	2444,69	735,937	24,9006	CRS
18:19:00,536	51736	3,02945	,999321	,998016	2449,36	738,603	24,6742	CRS
18:20:00,535	51836,7	3,04307	1,00241	1,00113	2453,96	741,929	25,0107	CRS
18:21:00,535	51937,3	3,05382	,999705	,998418	2458,64	744,552	24,7161	CRS
18:22:00,535	52038	3,06786	1,00313	1,00186	2463,23	747,98	25,0896	CRS
18:23:00,534	52138,7	3,07912	1,00072	,999463	2467,9	750,729	24,8271	CRS
18:24:00,534	52239,3	3,09245	1,00336	1,0021	2472,5	753,983	25,1145	CRS
18:25:00,533	52340	3,10489	1,003	1,00174	2477,14	757,022	25,0753	CRS
18:26:00,533	52440,7	3,11863	1,00581	1,00455	2481,73	760,377	25,382	CRS
18:27:00,532	52541,3	3,13197	1,00608	1,00482	2486,34	763,634	25,4109	CRS
18:28:00,531	52642	3,14585	1,00888	1,00762	2490,93	767,021	25,716	CRS
18:29:00,531	52742,7	3,15959	1,00925	1,00801	2495,53	770,378	25,7569	CRS
18:30:00,530	52843,3	3,17108	1,00826	1,00702	2500,19	773,183	25,6491	CRS
18:31:00,530	52944	3,18467	1,00866	1,00741	2504,8	776,501	25,6925	CRS
18:32:00,529	53044,7	3,19576	1,00693	1,00569	2509,47	779,207	25,5039	CRS
18:33:00,529	53145,4	3,21047	1,00938	1,00815	2514,05	782,798	25,7705	CRS
18:34:00,528	53246	3,22248	1,00891	1,00769	2518,69	785,73	25,7197	CRS
18:35:00,527	53346,7	3,23762	1,01152	1,01031	2523,26	789,428	26,0042	CRS
18:36:00,527	53447,4	3,24892	1,00961	1,00839	2527,93	792,186	25,7955	CRS
18:37:00,526	53548,1	3,26247	1,01007	1,00886	2532,53	795,495	25,8462	CRS
18:38:00,526	53648,8	3,27391	1,00815	1,00695	2537,2	798,287	25,6371	CRS
18:39:00,525	53749,4	3,28862	1,01059	1,00939	2541,78	801,879	25,9022	CRS
18:40:00,525	53850,1	3,2994	1,00729	1,00611	2546,46	804,512	25,5434	CRS
18:41:00,525	53950,8	3,31344	1,00871	1,00752	2551,06	807,938	25,6979	CRS
18:42:00,524	54051,5	3,32479	1,00687	1,00568	2555,73	810,71	25,4969	CRS
18:43:00,524	54152,1	3,34039	1,0109	1,00973	2560,28	814,519	25,9366	CRS
18:44:00,523	54252,8	3,35306	1,01011	1,00894	2564,91	817,612	25,8503	CRS
18:45:00,523	54353,5	3,36875	1,01328	1,01212	2569,46	821,443	26,1956	CRS
18:46:00,522	54454,2	3,37991	1,00974	1,00857	2574,14	824,169	25,8095	CRS
18:47:00,522	54554,8	3,39485	1,01246	1,01131	2578,71	827,815	26,1067	CRS
18:48:00,521	54655,5	3,40647	1,0096	1,00844	2583,38	830,651	25,7941	CRS
18:49:00,520	54756,2	3,42149	1,01223	1,01108	2587,94	834,318	26,0814	CRS
18:50:00,520	54856,8	3,43557	1,0126	1,01146	2592,54	837,757	26,1212	CRS
18:51:00,519	54957,5	3,45297	1,0185	1,01736	2597,04	842,005	26,7644	CRS
18:52:00,519	55058,2	3,46801	1,0187	1,01758	2601,61	845,678	26,787	CRS
18:53:00,518	55158,8	3,48629	1,02521	1,02407	2606,09	850,141	27,4964	CRS
18:54:00,518	55259,5	3,50052	1,02308	1,02195	2610,69	853,614	27,2637	CRS
18:55:00,517	55360,2	3,51646	1,02581	1,02469	2615,23	857,506	27,5612	CRS
18:56:00,516	55460,8	3,5306	1,02356	1,02243	2619,83	860,959	27,3159	CRS
18:57:00,516	55561,5	3,54608	1,02593	1,02482	2624,39	864,738	27,5748	CRS
18:58:00,515	55662,2	3,56023	1,0237	1,02259	2628,99	868,192	27,3319	CRS
18:59:00,515	55762,8	3,57558	1,02579	1,02469	2633,55	871,941	27,5593	CRS
19:00:00,514	55863,5	3,58987	1,02365	1,02255	2638,15	875,429	27,3258	CRS
19:01:00,514	55964,2	3,60393	1,02439	1,02329	2642,75	878,863	27,4071	CRS
19:02:00,514	56064,8	3,61921	1,02397	1,02287	2647,32	882,592	27,3614	CRS
19:03:00,513	56165,5	3,63312	1,02372	1,02263	2651,92	885,988	27,3333	CRS
19:04:00,513	56266,2	3,64863	1,02379	1,02271	2656,48	889,776	27,3418	CRS
19:05:00,512	56366,8	3,66295	1,02402	1,02294	2661,08	893,272	27,3668	CRS
19:06:00,512	56467,5	3,67935	1,02551	1,02445	2665,62	897,276	27,5293	CRS
19:07:00,511	56568,2	3,69329	1,02465	1,02359	2670,22	900,678	27,4355	CRS
19:08:00,511	56668,8	3,70955	1,02607	1,02502	2674,77	904,651	27,59	CRS
19:09:00,511	56769,5	3,72315	1,02416	1,0231	2679,38	907,97	27,3816	CRS
19:10:00,510	56870,2	3,73972	1,02617	1,02514	2683,92	912,014	27,6012	CRS
19:11:00,509	56970,8	3,7532	1,02385	1,0228	2688,54	915,307	27,3481	CRS
19:12:00,509	57071,5	3,77038	1,02703	1,02601	2693,06	919,501	27,6949	CRS
19:13:00,508	57172,2	3,78366	1,02412	1,02309	2697,69	922,744	27,3777	CRS
19:14:00,507	57272,8	3,80202	1,02882	1,02778	2702,18	927,226	27,8902	CRS
19:15:00,507	57373,5	3,81566	1,02573	1,02472	2706,8	930,556	27,5533	CRS
19:16:00,506	57474,2	3,83455	1,03102	1,03001	2711,27	935,168	28,129	CRS
19:17:00,505	57574,8	3,84784	1,02643	1,02543	2715,9	938,413	27,6291	CRS
19:18:00,505	57675,5	3,86606	1,03096	1,02996	2720,39	942,86	28,1231	CRS
19:19:00,505	57776,2	3,87926	1,02674	1,02576	2725,03	946,083	27,6628	CRS
19:20:00,504	57876,9	3,89713	1,03081	1,02982	2729,53	950,447	28,1065	CRS
19:21:00,503	57977,5	3,91255	1,02923	1,02822	2734,1	954,212	27,9343	CRS
19:22:00,503	58078,2	3,93245	1,03588	1,03491	2738,55	959,07	28,6594	CRS
19:23:00,503	58178,9	3,9503	1,0367	1,03574	2743,06	963,427	28,7488	CRS
19:24:00,502	58279,6	3,9687	1,03959	1,03862	2747,55	967,921	29,0635	CRS
19:25:00,502	58380,2	3,98393	1,03655	1,0356	2752,13	971,64	28,7321	CRS
19:26:00,501	58480,9	4,0012	1,0391	1,03815	2756,66	975,857	29,01	CRS
19:27:00,501	58581,6	4,01726	1,03728	1,03634	2761,22	979,776	28,8116	CRS
19:28:00,500	58682,3	4,03468	1,03951	1,03857	2765,74	984,03	29,055	CRS
19:29:00,500	58783	4,0527	1,04015	1,03922	2770,24	988,43	29,1249	CRS
19:30:00,499	58883,7	4,06802	1,03892	1,03799	2774,82	992,169	28,9903	CRS
19:31:00,499	58984,3	4,08507	1,03819	1,03727	2779,35	996,332	28,911	CRS
19:32:00,498	59085	4,10122	1,03832	1,03742	2783,91	1000,28	28,9252	CRS
19:33:00,498	59185,7	4,11821	1,03743	1,03653	2788,45	1004,42	28,828	CRS
19:34:00,497	59286,3	4,13226	1,035	1,03409	2793,06	1007,85	28,5629	CRS
19:35:00,496	59387	4,15059	1,03693	1,03604	2797,56	1012,33	28,7736	CRS
19:36:00,496	59487,7	4,16605	1,03582	1,03493	2802,14	1016,1	28,6522	CRS
19:37:00,495	59588,3	4,18449	1,03791	1,03704	2806,64	1020,61	28,8807	CRS
19:38:00,495	59689	4,19817	1,03351	1,03261	2811,26	1023,94	28,4005	CRS
19:39:00,494	59789,7	4,21665	1,03613	1,03527	2815,76	1028,46	28,6867	CRS
19:40:00,494	59890,3	4,23026	1,03178	1,03091	2820,39	1031,78	28,2119	CRS
19:41:00,493	59991	4,25001	1,0366	1,03574	2824,86	1036,6	28,7376	CRS
19:42:00,492	60091,7	4,26319	1,03096	1,03011	2829,5	1039,82	28,1228	CRS
19:43:00,492	60192,3	4,28304	1,03614	1,03529	2833,96	1044,67	28,6871	CRS
19:44:00,491	60293	4,29832	1,03382	1,03296	2838,54	1048,4	28,4341	CRS
19:45:00,491	60393,7	4,31983	1,03996	1,03911	2842,96	1053,65	29,1034	CRS
19:46:00,490	60494,3	4,33535	1,03721	1,0364	2847,54	1057,44	28,8044	CRS
19:47:00,490	60595	4,35729	1,04341	1,04259	2851,95	1062,8	29,48	CRS
19:48:00,489	60695,7	4,37375	1,04108	1,04025	2856,51	1066,81	29,2255	CRS
19:49:00,489	60796,3	4,39371	1,04452	1,04372	2860,97	1071,69	29,6011	CRS
19:50:00,488	60897	4,41077	1,04216	1,04135	2865,51	1075,85	29,3432	CRS
19:51:00,488	60997,7	4,4305	1,04493	1,04414	2869,98	1080,67	29,6461	CRS
19:52:00,488	61098,3	4,44826	1,04359	1,0428	2874,51	1085	29,4993	CRS
19:53:00,487	61199	4,46787	1,04627	1,04547	2878,98	1089,79	29,7917	CRS
19:54:00,486	61299,7	4,48745	1,04686	1,04607	2883,46	1094,57	29,8565	CRS
19:55:00,486	61400,3	4,50679	1,04864	1,04787	2887,94	1099,3	30,0496	CRS
19:56:00,485	61501	4,52583	1,04803	1,04726	2892,43	1103,94	29,9833	CRS
19:57:00,485	61601,7	4,5452	1,04998	1,04923	2896,92	1108,67	30,1959	CRS
19:58:00,484	61702,3	4,56497	1,05003	1,04928	2901,39	1113,5	30,2019	CRS
19:59:00,484	61803	4,58439	1,05196	1,05121	2905,87	1118,24	30,4116	CRS
20:00:00,483	61903,7	4,60463	1,05198	1,05124	2910,33	1123,18	30,4145	CRS
20:01:00,483	62004,3	4,62318	1,05255	1,05181	2914,84	1127,71	30,4761	CRS
20:02:00,482	62105	4,64365	1,05279	1,05206	2919,3	1132,71	30,5027	CRS
20:03:00,482	62205,7	4,66176	1,05236	1,05164	2923,82	1137,13	30,456	CRS
20:04:00,481	62306,3	4,68202	1,05273	1,05201	2928,28	1142,08	30,4955	CRS
20:05:00,480	62407	4,70138	1,05381	1,0531	2932,77	1146,81	30,6134	CRS
20:06:00,480	62507,7	4,72371	1,05686	1,05615	2937,18	1152,26	30,9457	CRS
20:07:00,479	62608,4	4,74378	1,05822	1,05751	2941,65	1157,16	31,0939	CRS
20:08:00,478	62709	4,76537	1,05931	1,05862	2946,08	1162,43	31,2135	CRS
20:09:00,478	62809,7	4,78458	1,05896	1,05827	2950,58	1167,12	31,1748	CRS
20:10:00,478	62910,4	4,80756	1,06231	1,06163	2954,97	1172,73	31,54	CRS
20:11:00,477	63011,1	4,82818	1,06279	1,06212	2959,43	1177,76	31,5921	CRS
20:12:00,476	63111,8	4,85052	1,06495	1,06428	2963,85	1183,22	31,8273	CRS
20:13:00,476	63212,4	4,87017	1,06325	1,0626	2968,33	1188,02	31,6429	CRS
20:14:00,475	63313,1	4,89276	1,06644	1,06579	2972,74	1193,53	31,9903	CRS
20:15:00,475	63413,8	4,91168	1,06396	1,06332	2977,25	1198,15	31,7201	CRS
20:16:00,474	63514,5	4,93357	1,06567	1,06503	2981,68	1203,49	31,9064	CRS
20:17:00,474	63615,1	4,95297	1,06434	1,06371	2986,17	1208,23	31,7613	CRS
20:18:00,474	63715,8	4,97586	1,06796	1,06735	2990,58	1213,82	32,1564	CRS
20:19:00,473	63816,5	4,99548	1,06552	1,06491	2995,06	1218,61	31,8902	CRS
20:20:00,473	63917,2	5,01772	1,06763	1,06703	2999,49	1224,04	32,1197	CRS
20:21:00,472	64017,8	5,03702	1,06434	1,06375	3003,98	1228,75	31,761	CRS
20:22:00,472	64118,5	5,05848	1,06601	1,06542	3008,43	1233,99	31,9436	CRS
20:23:00,471	64219,2	5,07701	1,062	1,06142	3012,95	1238,51	31,5061	CRS
20:24:00,470	64319,8	5,09878	1,06414	1,06357	3017,38	1243,83	31,7394	CRS
20:25:00,470	64420,5	5,11724	1,06005	1,05949	3021,9	1248,34	31,2934	CRS
20:26:00,469	64521,2	5,13759	1,06104	1,06049	3026,38	1253,31	31,4016	CRS
20:27:00,469	64621,8	5,15637	1,05757	1,05701	3030,89	1257,89	31,0229	CRS
20:28:00,468	64722,5	5,17724	1,05952	1,05898	3035,35	1262,98	31,2364	CRS
20:29:00,468	64823,2	5,19727	1,05722	1,05668	3039,84	1267,88	30,9856	CRS
20:30:00,467	64923,8	5,21844	1,05943	1,0589	3044,29	1273,05	31,2258	CRS
20:31:00,466	65024,5	5,23975	1,0585	1,05798	3048,74	1278,25	31,1252	CRS
20:32:00,466	65125,2	5,25971	1,05855	1,05804	3053,23	1283,12	31,1305	CRS
20:33:00,465	65225,8	5,28069	1,05841	1,0579	3057,69	1288,24	31,1145	CRS
20:34:00,465	65326,5	5,30009	1,05745	1,05695	3062,19	1292,98	31,0099	CRS
20:35:00,464	65427,2	5,32235	1,05872	1,05823	3066,62	1298,42	31,1487	CRS
20:36:00,464	65527,8	5,3435	1,05906	1,05858	3071,08	1303,58	31,186	CRS
20:37:00,463	65628,5	5,367	1,06214	1,06166	3075,48	1309,32	31,5211	CRS
20:38:00,462	65729,2	5,38852	1,06239	1,06192	3079,93	1314,57	31,5489	CRS
20:39:00,462	65829,8	5,41343	1,06644	1,06597	3084,29	1320,65	31,9899	CRS
20:40:00,461	65930,5	5,43434	1,06516	1,0647	3088,76	1325,76	31,8504	CRS
20:41:00,461	66031,2	5,46023	1,07014	1,0697	3093,1	1332,08	32,3932	CRS
20:42:00,460	66131,8	5,48252	1,06996	1,06952	3097,53	1337,52	32,3736	CRS
20:43:00,460	66232,5	5,50928	1,07549	1,07505	3101,86	1344,05	32,9762	CRS
20:44:00,459	66333,2	5,53126	1,07375	1,07333	3106,3	1349,42	32,7872	CRS
20:45:00,459	66433,8	5,55651	1,07757	1,07715	3110,66	1355,58	33,2037	CRS
20:46:00,459	66534,5	5,57818	1,07552	1,07511	3115,11	1360,88	32,9804	CRS
20:47:00,458	66635,2	5,60454	1,08009	1,0797	3119,44	1367,31	33,4781	CRS
20:48:00,457	66735,8	5,6266	1,07756	1,07717	3123,89	1372,7	33,2021	CRS
20:49:00,458	66836,5	5,65304	1,08231	1,08192	3128,22	1379,15	33,7199	CRS
20:50:00,457	66937,2	5,67442	1,07843	1,07806	3132,68	1384,37	33,2973	CRS
20:51:00,456	67037,9	5,70026	1,08286	1,08248	3137,03	1390,68	33,7798	CRS
20:52:00,456	67138,5	5,72278	1,08002	1,07967	3141,46	1396,18	33,4705	CRS
20:53:00,455	67239,2	5,74879	1,08389	1,08355	3145,81	1402,53	33,8923	CRS
20:54:00,454	67339,9	5,77146	1,08146	1,08112	3150,24	1408,06	33,6274	CRS
20:55:00,454	67440,6	5,7974	1,08545	1,08512	3154,59	1414,4	34,0626	CRS
20:56:00,453	67541,2	5,82127	1,08458	1,08426	3158,99	1420,23	33,9673	CRS
20:57:00,452	67641,9	5,84515	1,08509	1,08478	3163,4	1426,06	34,0228	CRS
20:58:00,452	67742,6	5,87016	1,08559	1,08528	3167,77	1432,16	34,0774	CRS
20:59:00,452	67843,3	5,89448	1,08679	1,08649	3172,17	1438,1	34,2083	CRS
21:00:00,451	67943,9	5,91986	1,08656	1,08627	3176,53	1444,3	34,183	CRS
21:01:00,451	68044,6	5,94386	1,08706	1,08677	3180,94	1450,16	34,2374	CRS
21:02:00,450	68145,3	5,96991	1,08824	1,08796	3185,29	1456,52	34,3659	CRS
21:03:00,449	68246	5,99313	1,08703	1,08677	3189,71	1462,19	34,2348	CRS
21:04:00,449	68346,7	6,02114	1,09076	1,0905	3194,02	1469,02	34,6408	CRS
21:05:00,448	68447,3	6,04491	1,0899	1,08965	3198,43	1474,83	34,547	CRS
21:06:00,448	68548	6,07291	1,09268	1,09244	3202,74	1481,66	34,8507	CRS
21:07:00,447	68648,7	6,09782	1,09295	1,09272	3207,12	1487,75	34,8801	CRS
21:08:00,447	68749,3	6,12624	1,0964	1,09618	3211,42	1494,69	35,2554	CRS
21:09:00,446	68850	6,14989	1,09427	1,09406	3215,83	1500,46	35,0237	CRS
21:10:00,446	68950,7	6,17784	1,09672	1,09652	3220,14	1507,28	35,2906	CRS
21:11:00,445	69051,3	6,20108	1,09394	1,09375	3224,57	1512,96	34,9876	CRS
21:12:00,444	69152	6,23029	1,09852	1,09833	3228,85	1520,09	35,4868	CRS
21:13:00,444	69252,7	6,25433	1,09647	1,09629	3233,26	1525,96	35,2632	CRS
21:14:00,443	69353,3	6,28272	1,09981	1,09964	3237,56	1532,89	35,6273	CRS
21:14:20,443	69386,8	6,29023	1,09738	1,09721	3239,04	1534,72	35,3621	CRS