File: Example - Raw files/Ødo 2015/G7-1_CRS_D9-4m.lvm
Oedometer-1	08.10.2015
*Header*
Operator	G7-1_2015
Site	Stjørdal
Hole
Depth [m]	9,4
Comment
Sample area [cm2]	20
Sample height [mm]	20
*Calibration data *
Motor [steps/rev]	2000
Jack [µm/rev]	217
Load cell fact. [N/V]	490
Pore sens. fact. [kPa/V]	109,3
LVDT fact. [µm/V]	0
SelfDeform factor	3,43129
SelfDeform exp	,534907
Slack [steps]	50

        		Load	Pore			Vertica	Pore
Mean        	Deform.	cell	sens.	LVDT.	Deforma	stress	pressur
time        	[steps]	[V]	[V]	[V]	[µm]	[kPa]	[kPa]	MODE
------------	-------	-------	-------	-------	-------	-------	-------	-------
11:37:54,393	0	-,00271	1,45902	0	-0	0	0	ZERO
11:38:59,392	52,18	-,00137	1,48081	1,47947	3,4153	,327315	2,38216	CRS
11:40:09,392	105,88	,00036	1,48298	1,48162	7,22131	,751669	2,61865	CRS
11:41:19,392	159,64	,004966	1,4892	1,48785	10,3522	1,88026	3,29852	CRS
11:42:29,391	213,44	,008572	1,49403	1,49266	14,5951	2,76369	3,82645	CRS
11:43:39,391	267,2	,011532	1,49812	1,49676	19,2911	3,48905	4,27409	CRS
11:44:49,391	320,96	,0135	1,50102	1,49965	24,4287	3,97112	4,59043	CRS
11:45:59,391	374,72	,015176	1,50368	1,5023	29,6999	4,38171	4,88125	CRS
11:47:09,391	428,5	,016822	1,5062	1,50484	35,0067	4,78498	5,15755	CRS
11:48:19,391	482,28	,018656	1,50834	1,50699	40,2769	5,23436	5,39116	CRS
11:49:29,391	536,04	,020729	1,51095	1,50961	45,4979	5,74222	5,67613	CRS
11:50:39,390	589,8	,022658	1,51346	1,51211	50,7837	6,21476	5,951	CRS
11:51:49,389	643,56	,024729	1,51551	1,51415	56,0502	6,72228	6,1749	CRS
11:52:59,389	697,36	,026704	1,518	1,51664	61,3657	7,20615	6,44689	CRS
11:54:09,389	751,08	,0284	1,51996	1,51859	66,7591	7,6216	6,66134	CRS
11:55:19,389	804,8	,03002	1,52153	1,52018	72,1823	8,01842	6,83289	CRS
11:56:29,389	858,56	,031848	1,52356	1,52222	77,5687	8,46627	7,05409	CRS
11:57:39,389	912,36	,033561	1,52518	1,52382	82,9973	8,88607	7,23155	CRS
11:58:49,388	966,12	,034626	1,52639	1,52504	88,5807	9,14701	7,36377	CRS
11:59:59,387	1019,88	,025911	1,50839	1,50703	96,5668	7,01175	5,39629	CRS
12:01:09,387	1073,64	,028155	1,51141	1,51006	101,819	7,56156	5,72688	CRS
12:02:19,387	1127,44	,02995	1,51362	1,51225	107,206	8,00136	5,96763	CRS
12:03:29,387	1181,2	,031166	1,51527	1,51392	112,74	8,29935	6,14827	CRS
12:04:39,387	1234,96	,032102	1,51645	1,5151	118,347	8,52855	6,27748	CRS
12:05:49,387	1288,72	,032287	1,51668	1,51533	124,135	8,57397	6,30263	CRS
12:06:59,387	1342,5	,033031	1,51808	1,5167	129,793	8,7562	6,45514	CRS
12:08:09,385	1396,28	,033693	1,51817	1,5168	135,472	8,91835	6,46545	CRS
12:09:19,385	1449,98	,034309	1,51876	1,51741	141,153	9,06939	6,52956	CRS
12:10:29,385	1503,72	,035314	1,51952	1,51816	146,751	9,3155	6,61293	CRS
12:11:39,385	1557,5	,035966	1,51899	1,51764	152,436	9,47529	6,55531	CRS
12:12:49,385	1611,28	,036471	1,51857	1,51719	158,156	9,59894	6,50855	CRS
12:13:59,385	1665,04	,037105	1,51876	1,51741	163,845	9,75421	6,52996	CRS
12:15:09,385	1718,8	,037419	1,51837	1,51701	169,607	9,83125	6,4871	CRS
12:16:19,384	1772,56	,037648	1,51744	1,51608	175,389	9,88733	6,38611	CRS
12:17:29,383	1826,36	,038202	1,51707	1,51572	181,102	10,0231	6,34484	CRS
12:18:39,383	1880,12	,038592	1,51653	1,51518	186,848	10,1187	6,28653	CRS
12:19:49,383	1933,88	,039499	1,51663	1,51527	192,481	10,3408	6,29708	CRS
12:20:59,383	1987,64	,040978	1,51784	1,51647	197,992	10,7031	6,42891	CRS
12:22:09,383	2041,44	,042185	1,51807	1,51672	203,569	10,9989	6,45469	CRS
12:23:19,383	2095,2	,043341	1,51842	1,51706	209,157	11,2822	6,493	CRS
12:24:29,382	2148,9	,044116	1,51868	1,51733	214,82	11,4721	6,52139	CRS
12:25:39,381	2202,64	,044717	1,51854	1,51718	220,526	11,6193	6,50557	CRS
12:26:49,382	2256,44	,046081	1,51948	1,51813	226,081	11,9535	6,60864	CRS
12:27:59,381	2310,2	,047611	1,52068	1,51934	231,602	12,3282	6,74013	CRS
12:29:09,381	2363,96	,048982	1,52212	1,52078	237,159	12,6641	6,8972	CRS
12:30:19,381	2417,72	,050465	1,52396	1,52262	242,697	13,0276	7,09868	CRS
12:31:29,381	2471,5	,052246	1,52579	1,52444	248,183	13,4638	7,29784	CRS
12:32:39,380	2525,28	,053579	1,52686	1,52551	253,76	13,7905	7,41559	CRS
12:33:49,379	2579,04	,055102	1,52852	1,52716	259,302	14,1635	7,59637	CRS
12:34:59,379	2632,8	,056299	1,5294	1,52802	264,909	14,4569	7,69234	CRS
12:36:09,379	2686,56	,057529	1,53023	1,52888	270,512	14,7582	7,78366	CRS
12:37:19,379	2740,36	,059264	1,53171	1,53037	276,028	15,1832	7,94576	CRS
12:38:29,379	2794,12	,060644	1,53235	1,53101	281,609	15,5214	8,01544	CRS
12:39:39,379	2847,8	,062329	1,53307	1,53171	287,128	15,9343	8,09384	CRS
12:40:49,378	2901,56	,06415	1,53436	1,53299	292,636	16,3802	8,23516	CRS
12:41:59,377	2955,38	,065785	1,53528	1,53394	298,187	16,781	8,33589	CRS
12:43:09,377	3009,12	,067552	1,5361	1,53475	303,709	17,2138	8,42466	CRS
12:44:19,377	3062,88	,069442	1,53755	1,5362	309,216	17,6769	8,58308	CRS
12:45:29,377	3116,64	,071453	1,53891	1,53755	314,707	18,1695	8,73239	CRS
12:46:39,377	3170,44	,073366	1,54016	1,53879	320,223	18,6383	8,86834	CRS
12:47:49,377	3224,2	,075493	1,54196	1,54062	325,702	19,1594	9,06561	CRS
12:48:59,376	3277,96	,077127	1,54263	1,54129	331,267	19,5598	9,13879	CRS
12:50:09,375	3331,72	,07896	1,54347	1,54212	336,802	20,0088	9,23045	CRS
12:51:19,375	3385,5	,080942	1,54465	1,5433	342,318	20,4944	9,35931	CRS
12:52:29,375	3439,28	,082464	1,54511	1,54377	347,911	20,8674	9,41023	CRS
12:53:39,375	3493,02	,084305	1,5457	1,54435	353,452	21,3183	9,47472	CRS
12:54:49,375	3546,72	,086624	1,54722	1,54586	358,916	21,8864	9,64045	CRS
12:55:59,375	3600,5	,088413	1,54767	1,54631	364,475	22,3248	9,68982	CRS
12:57:09,375	3654,28	,090468	1,54833	1,54699	369,996	22,8283	9,76196	CRS
12:58:19,373	3708,04	,092862	1,54943	1,54808	375,467	23,4148	9,88249	CRS
12:59:29,373	3761,8	,09529	1,5502	1,54883	380,937	24,0095	9,96587	CRS
13:00:39,373	3815,56	,09752	1,5507	1,54933	386,441	24,5559	10,0208	CRS
13:01:49,373	3869,36	,099936	1,55173	1,55037	391,925	25,148	10,1336	CRS
13:02:59,373	3923,12	,101887	1,55175	1,55039	397,475	25,6259	10,1354	CRS
13:04:09,373	3976,88	,104555	1,55242	1,55108	402,926	26,2795	10,2086	CRS
13:05:19,373	4030,64	,106944	1,55266	1,5513	408,42	26,8649	10,2349	CRS
13:06:29,371	4084,44	,109161	1,55195	1,5506	413,946	27,408	10,1578	CRS
13:07:39,371	4138,2	,111973	1,55217	1,55081	419,389	28,097	10,1814	CRS
13:08:49,371	4191,92	,1144	1,55176	1,5504	424,884	28,6916	10,1367	CRS
13:09:59,371	4245,64	,116709	1,55053	1,54918	430,398	29,2573	10,0027	CRS
13:11:09,371	4299,44	,119761	1,55062	1,54926	435,824	30,0049	10,0119	CRS
13:12:19,370	4353,2	,122252	1,5491	1,54775	441,325	30,6152	9,84627	CRS
13:13:29,370	4406,96	,124734	1,54752	1,54618	446,83	31,2233	9,67376	CRS
13:14:39,369	4460,72	,128155	1,54742	1,54608	452,216	32,0615	9,66209	CRS
13:15:49,369	4514,5	,131224	1,54629	1,54496	457,655	32,8134	9,53939	CRS
13:16:59,369	4568,28	,133855	1,54419	1,54286	463,154	33,458	9,30887	CRS
13:18:09,369	4622,04	,137999	1,5449	1,54358	468,463	34,4733	9,38681	CRS
13:19:19,369	4675,8	,141319	1,54327	1,54195	473,881	35,2868	9,2085	CRS
13:20:29,369	4729,56	,144801	1,54208	1,54076	479,284	36,1398	9,07916	CRS
13:21:39,369	4783,36	,149268	1,54303	1,54171	484,576	37,2344	9,18259	CRS
13:22:49,367	4837,12	,152562	1,54159	1,54028	490,012	38,0412	9,02567	CRS
13:23:59,367	4890,82	,156249	1,54047	1,53915	495,399	38,9446	8,90318	CRS
13:25:09,367	4944,56	,161426	1,54186	1,54055	500,62	40,2129	9,05501	CRS
13:26:19,367	4998,36	,165227	1,54059	1,53927	506,016	41,1441	8,91625	CRS
13:27:29,367	5052,12	,169348	1,53955	1,53822	511,375	42,1539	8,80274	CRS
13:28:39,367	5105,88	,174703	1,54094	1,53964	516,6	43,4658	8,95436	CRS
13:29:49,366	5159,64	,178758	1,53981	1,5385	521,978	44,4592	8,83051	CRS
13:30:59,366	5213,44	,183422	1,53906	1,53775	527,298	45,6019	8,74813	CRS
13:32:09,365	5267,2	,188887	1,53987	1,53855	532,533	46,9408	8,83707	CRS
13:33:19,366	5320,96	,193248	1,53833	1,53702	537,894	48,0093	8,66868	CRS
13:34:29,365	5374,72	,198407	1,53772	1,53641	543,175	49,2733	8,6019	CRS
13:35:39,365	5428,5	,204196	1,53848	1,53717	548,398	50,6915	8,68577	CRS
13:36:49,365	5482,28	,209106	1,53729	1,53598	553,721	51,8945	8,55522	CRS
13:37:59,365	5536,04	,214984	1,53744	1,53614	558,948	53,3347	8,57174	CRS
13:39:09,363	5589,74	,220863	1,53804	1,53674	564,175	54,7749	8,63695	CRS
13:40:19,363	5643,5	,225804	1,53632	1,53504	569,51	55,9856	8,4497	CRS
13:41:29,363	5697,28	,231835	1,5369	1,53561	574,745	57,4631	8,51248	CRS
13:42:39,363	5751,04	,238047	1,53765	1,53635	579,967	58,9851	8,59499	CRS
13:43:49,363	5804,8	,243594	1,53628	1,53498	585,26	60,3441	8,4444	CRS
13:44:59,363	5858,56	,250453	1,53759	1,53631	590,433	62,0246	8,58834	CRS
13:46:09,363	5912,36	,256629	1,5374	1,53612	595,684	63,5377	8,56765	CRS
13:47:19,361	5966,12	,2626	1,53644	1,53516	600,956	65,0007	8,46176	CRS
13:48:29,361	6019,88	,269914	1,53806	1,53678	606,109	66,7925	8,63955	CRS
13:49:39,361	6073,64	,276334	1,53718	1,5359	611,353	68,3654	8,5427	CRS
13:50:49,361	6127,44	,282607	1,536	1,53472	616,62	69,9023	8,41443	CRS
13:51:59,361	6181,2	,290212	1,53772	1,53645	621,77	71,7654	8,60218	CRS
13:53:09,361	6234,96	,296737	1,53659	1,53533	627,023	73,3641	8,4789	CRS
13:54:19,361	6288,64	,30324	1,53508	1,53382	632,276	74,9574	8,31412	CRS
13:55:29,359	6342,44	,311564	1,53739	1,53613	637,389	76,9968	8,56585	CRS
13:56:39,359	6396,2	,318706	1,53675	1,53549	642,608	78,7466	8,49589	CRS
13:57:49,359	6449,96	,32565	1,53569	1,53443	647,851	80,4478	8,38028	CRS
13:58:59,359	6503,72	,334566	1,53816	1,5369	652,933	82,6323	8,65048	CRS
14:00:09,359	6557,5	,341566	1,53701	1,53575	658,186	84,3474	8,52413	CRS
14:01:19,359	6611,28	,348493	1,53569	1,53443	663,45	86,0443	8,37986	CRS
14:02:29,358	6665,04	,357043	1,53766	1,5364	668,585	88,1391	8,59584	CRS
14:03:39,358	6718,8	,364005	1,53609	1,53483	673,856	89,8447	8,4236	CRS
14:04:49,358	6772,56	,371408	1,53512	1,53387	679,096	91,6586	8,31807	CRS
14:05:59,357	6826,36	,380091	1,53725	1,536	684,246	93,786	8,55085	CRS
14:07:09,357	6880,12	,387554	1,53635	1,53513	689,493	95,6142	8,45297	CRS
14:08:19,357	6933,86	,395428	1,53624	1,535	694,711	97,5435	8,43997	CRS
14:09:29,357	6987,56	,40417	1,53795	1,53671	699,865	99,6854	8,62711	CRS
14:10:39,356	7041,38	,411572	1,5363	1,53507	705,139	101,499	8,4469	CRS
14:11:49,356	7095,12	,419891	1,537	1,53576	710,341	103,537	8,52331	CRS
14:12:59,355	7148,88	,428626	1,53875	1,5375	715,519	105,677	8,71442	CRS
14:14:09,356	7202,64	,436018	1,53768	1,53646	720,803	107,488	8,59751	CRS
14:15:19,355	7256,44	,444927	1,5376	1,53638	725,984	109,671	8,58855	CRS
14:16:29,355	7310,2	,453955	1,53984	1,53863	731,159	111,883	8,83424	CRS
14:17:39,355	7363,96	,461098	1,53716	1,53595	736,475	113,633	8,54138	CRS
14:18:49,355	7417,72	,470409	1,53825	1,53703	741,64	115,914	8,66034	CRS
14:19:59,353	7471,5	,479338	1,53886	1,53764	746,84	118,101	8,72653	CRS
14:21:09,353	7525,28	,487421	1,53719	1,53598	752,105	120,082	8,54382	CRS
14:22:19,354	7579,04	,497263	1,53893	1,53772	757,249	122,493	8,73497	CRS
14:23:29,353	7632,76	,505635	1,53885	1,53765	762,497	124,544	8,72522	CRS
14:24:39,353	7686,5	,513939	1,53777	1,53657	767,756	126,579	8,6079	CRS
14:25:49,353	7740,28	,523643	1,53973	1,53852	772,929	128,956	8,82136	CRS
14:26:59,352	7794,04	,53185	1,53927	1,53808	778,206	130,967	8,77165	CRS
14:28:09,351	7847,8	,539965	1,53823	1,53704	783,493	132,955	8,65797	CRS
14:29:19,352	7901,56	,550071	1,5406	1,53942	788,652	135,431	8,91702	CRS
14:30:29,352	7955,36	,558473	1,54038	1,53919	793,933	137,49	8,89257	CRS
14:31:39,351	8009,12	,566897	1,53928	1,53811	799,212	139,553	8,77319	CRS
14:32:49,351	8062,88	,57729	1,54238	1,54121	804,367	142,1	9,11102	CRS
14:33:59,351	8116,64	,585034	1,54137	1,54021	809,698	143,997	9,00116	CRS
14:35:09,351	8170,44	,593363	1,54468	1,54352	814,999	146,038	9,36343	CRS
14:36:19,350	8224,2	,603322	1,54347	1,54233	820,196	148,477	9,23083	CRS
14:37:29,350	8277,96	,61136	1,54195	1,5408	825,518	150,447	9,06461	CRS
14:38:39,350	8331,66	,619465	1,54076	1,53961	830,833	152,433	8,93464	CRS
14:39:49,349	8385,44	,62979	1,54377	1,54262	836,022	154,962	9,26342	CRS
14:40:59,349	8439,2	,637836	1,54281	1,54168	841,354	156,933	9,15861	CRS
14:42:09,349	8492,96	,646257	1,54193	1,5408	846,666	158,997	9,06281	CRS
14:43:19,348	8546,72	,655736	1,54432	1,54319	851,916	161,319	9,32354	CRS
14:44:29,348	8600,5	,662997	1,54284	1,5417	857,308	163,098	9,16132	CRS
14:45:39,348	8654,28	,671473	1,54267	1,54154	862,628	165,174	9,14283	CRS
14:46:49,348	8708,04	,680596	1,54487	1,54373	867,91	167,41	9,38358	CRS
14:47:59,347	8761,8	,687959	1,54323	1,5421	873,301	169,214	9,20419	CRS
14:49:09,346	8815,56	,696301	1,54271	1,5416	878,635	171,257	9,14801	CRS
14:50:19,347	8869,36	,705317	1,54518	1,54405	883,937	173,466	9,41796	CRS
14:51:29,347	8923,12	,712324	1,54235	1,54125	889,356	175,183	9,10875	CRS
14:52:39,346	8976,88	,721835	1,54346	1,54235	894,63	177,513	9,22991	CRS
14:53:49,345	9030,56	,730794	1,54518	1,54407	899,931	179,708	9,41805	CRS
14:54:59,346	9084,38	,738186	1,54333	1,54222	905,341	181,519	9,21557	CRS
14:56:09,345	9138,12	,747419	1,54487	1,54378	910,638	183,781	9,38419	CRS
14:57:19,345	9191,88	,755761	1,546	1,54488	915,991	185,825	9,50711	CRS
14:58:29,345	9245,64	,762668	1,54393	1,54283	921,429	187,517	9,281	CRS
14:59:39,345	9299,44	,772245	1,54695	1,54585	926,72	189,864	9,61112	CRS
15:00:49,344	9353,2	,779959	1,54774	1,54664	932,116	191,753	9,69684	CRS
15:01:59,344	9406,96	,787011	1,54616	1,54507	937,552	193,481	9,52503	CRS
15:03:09,344	9460,72	,796134	1,54824	1,54716	942,872	195,716	9,75228	CRS
15:04:19,343	9514,5	,80326	1,54778	1,54668	948,309	197,462	9,70167	CRS
15:05:29,343	9568,28	,809446	1,54527	1,54418	953,8	198,978	9,42761	CRS
15:06:39,343	9622,04	,817912	1,54732	1,54622	959,164	201,052	9,65126	CRS
15:07:49,343	9675,8	,824256	1,5472	1,54611	964,647	202,606	9,63838	CRS
15:08:59,342	9729,5	,83009	1,54524	1,54416	970,152	204,036	9,42454	CRS
15:10:09,342	9783,28	,839209	1,54887	1,54778	975,488	206,27	9,82108	CRS
15:11:19,342	9837,04	,845248	1,54772	1,54664	980,991	207,749	9,69506	CRS
15:12:29,341	9890,8	,85099	1,54611	1,54504	986,512	209,156	9,51915	CRS
15:13:39,341	9944,56	,860437	1,55132	1,55022	991,834	211,471	10,0885	CRS
15:14:49,341	9998,36	,866387	1,55053	1,54944	997,35	212,928	10,0025	CRS
15:15:59,341	10052,1	,872576	1,54982	1,54872	1002,85	214,445	9,92464	CRS
15:17:09,340	10105,9	,881476	1,5541	1,55303	1008,21	216,625	10,3924	CRS
15:18:19,340	10159,6	,886995	1,55261	1,55155	1013,75	217,977	10,2298	CRS
15:19:29,340	10213,4	,892803	1,5507	1,54962	1019,27	219,4	10,0206	CRS
15:20:39,339	10267,2	,900989	1,55475	1,55368	1024,67	221,406	10,4635	CRS
15:21:49,339	10321	,906239	1,55276	1,5517	1030,23	222,692	10,2459	CRS
15:22:59,339	10374,7	,912371	1,55179	1,55074	1035,74	224,194	10,1404	CRS
15:24:09,339	10428,4	,920024	1,55505	1,55398	1041,17	226,069	10,4959	CRS
15:25:19,338	10482,2	,922184	1,54692	1,54587	1046,89	226,599	9,60813	CRS
15:26:29,338	10536	,931246	1,55329	1,55224	1052,25	228,819	10,3038	CRS
15:27:39,338	10589,7	,93807	1,55648	1,55544	1057,72	230,491	10,6529	CRS
15:28:49,337	10643,5	,941944	1,55308	1,55204	1063,36	231,44	10,2808	CRS
15:29:59,337	10697,3	,947704	1,55404	1,55299	1068,9	232,851	10,3857	CRS
15:31:09,337	10751	,953327	1,55594	1,55488	1074,44	234,229	10,594	CRS
15:32:19,337	10804,8	,956739	1,55267	1,55164	1080,1	235,065	10,2365	CRS
15:33:29,336	10858,6	,963178	1,55472	1,55368	1085,6	236,642	10,4602	CRS
15:34:39,336	10912,4	,968798	1,55601	1,55496	1091,15	238,019	10,6012	CRS
15:35:49,336	10966,1	,972448	1,55328	1,55224	1096,8	238,913	10,3027	CRS
15:36:59,336	11019,9	,978971	1,55599	1,55495	1102,3	240,512	10,5996	CRS
15:38:09,335	11073,6	,983463	1,55579	1,55475	1107,9	241,612	10,5768	CRS
15:39:19,335	11127,4	,987019	1,55327	1,55224	1113,55	242,483	10,302	CRS
15:40:29,335	11181,1	,993803	1,55653	1,5555	1119,04	244,145	10,6583	CRS
15:41:39,334	11234,9	,998137	1,55657	1,55554	1124,65	245,207	10,6627	CRS
15:42:49,334	11288,6	1,00127	1,55447	1,55344	1130,33	245,974	10,4326	CRS
15:43:59,334	11342,4	1,00797	1,55786	1,55683	1135,83	247,617	10,804	CRS
15:45:09,334	11396,2	1,01142	1,55663	1,55559	1141,49	248,461	10,6689	CRS
15:46:19,333	11450	1,01431	1,55446	1,55343	1147,18	249,17	10,4319	CRS
15:47:29,333	11503,7	1,02114	1,55874	1,55772	1152,67	250,842	10,8991	CRS
15:48:39,333	11557,5	1,02465	1,55732	1,5563	1158,33	251,702	10,7442	CRS
15:49:49,332	11611,3	1,02759	1,55502	1,554	1164,02	252,424	10,4929	CRS
15:50:59,332	11665	1,03463	1,56039	1,55937	1169,5	254,149	11,0799	CRS
15:52:09,332	11718,8	1,03826	1,55912	1,5581	1175,15	255,038	10,941	CRS
15:53:19,331	11772,5	1,04232	1,55794	1,55692	1180,78	256,031	10,8118	CRS
15:54:29,331	11826,3	1,0491	1,56241	1,56141	1186,28	257,692	11,301	CRS
15:55:39,331	11880	1,05265	1,56072	1,55971	1191,94	258,563	11,116	CRS
15:56:49,331	11933,8	1,05701	1,55957	1,55855	1197,56	259,632	10,9901	CRS
15:57:59,330	11987,6	1,06407	1,56422	1,56322	1203,04	261,36	11,4986	CRS
15:59:09,330	12041,4	1,06727	1,5618	1,56078	1208,72	262,144	11,2341	CRS
16:00:19,330	12095,1	1,07195	1,56107	1,56006	1214,33	263,29	11,1541	CRS
16:01:29,329	12148,9	1,07809	1,56454	1,56354	1219,86	264,795	11,5337	CRS
16:02:39,329	12202,6	1,08103	1,56159	1,56058	1225,55	265,516	11,2111	CRS
16:03:49,329	12256,4	1,08624	1,56242	1,56143	1231,14	266,792	11,3023	CRS
16:04:59,329	12310,2	1,09171	1,56559	1,56459	1236,71	268,132	11,6483	CRS
16:06:09,328	12364	1,09424	1,5624	1,56141	1242,42	268,752	11,3	CRS
16:07:19,328	12417,7	1,09988	1,56411	1,56312	1247,98	270,134	11,4864	CRS
16:08:29,328	12471,4	1,10507	1,5668	1,56579	1253,56	271,406	11,7801	CRS
16:09:39,328	12525,2	1,10752	1,56343	1,56245	1259,27	272,006	11,412	CRS
16:10:49,327	12579	1,1131	1,56608	1,56508	1264,84	273,372	11,7015	CRS
16:11:59,327	12632,7	1,11728	1,56733	1,56634	1270,47	274,398	11,8386	CRS
16:13:09,327	12686,5	1,11948	1,564	1,56303	1276,2	274,936	11,4745	CRS
16:14:19,327	12740,3	1,12489	1,5668	1,56579	1281,78	276,263	11,781	CRS
16:15:29,326	12794	1,12796	1,56656	1,56557	1287,46	277,014	11,754	CRS
16:16:39,326	12847,8	1,13004	1,56368	1,56271	1293,2	277,523	11,4401	CRS
16:17:49,326	12901,6	1,13607	1,56747	1,56649	1298,74	279,001	11,8542	CRS
16:18:59,325	12955,4	1,1391	1,56704	1,56605	1304,44	279,743	11,8069	CRS
16:20:09,325	13009,1	1,14062	1,56295	1,56199	1310,2	280,115	11,3594	CRS
16:21:19,325	13062,9	1,1469	1,56718	1,56621	1315,73	281,655	11,822	CRS
16:22:29,325	13116,6	1,14996	1,56653	1,56553	1321,42	282,404	11,7506	CRS
16:23:39,324	13170,4	1,15205	1,56392	1,56294	1327,15	282,917	11,4653	CRS
16:24:49,324	13224,1	1,15864	1,56892	1,56795	1332,67	284,531	12,0126	CRS
16:25:59,324	13277,9	1,16098	1,56683	1,56585	1338,4	285,105	11,7842	CRS
16:27:09,323	13331,6	1,16311	1,56419	1,56322	1344,13	285,626	11,4952	CRS
16:28:19,323	13385,4	1,16948	1,56919	1,56821	1349,67	287,186	12,0414	CRS
16:29:29,323	13439,2	1,17194	1,56745	1,56648	1355,39	287,79	11,8517	CRS
16:30:39,323	13493	1,17439	1,56518	1,56422	1361,1	288,389	11,6033	CRS
16:31:49,322	13546,7	1,18078	1,57067	1,56969	1366,64	289,955	12,2034	CRS
16:32:59,322	13600,5	1,18315	1,56864	1,56766	1372,36	290,535	11,9812	CRS
16:34:09,322	13654,3	1,18632	1,5669	1,56594	1378,05	291,311	11,7919	CRS
16:35:19,321	13708	1,19209	1,57177	1,57079	1383,62	292,725	12,3238	CRS
16:36:29,321	13761,8	1,19467	1,56965	1,56868	1389,33	293,358	12,0925	CRS
16:37:39,321	13815,6	1,19821	1,56843	1,56746	1395	294,226	11,9585	CRS
16:38:49,321	13869,3	1,20404	1,57309	1,57214	1400,56	295,654	12,468	CRS
16:39:59,320	13923	1,20607	1,56984	1,56887	1406,3	296,151	12,1127	CRS
16:41:09,320	13976,8	1,21129	1,57092	1,56995	1411,89	297,429	12,2306	CRS
16:42:19,320	14030,6	1,21658	1,57452	1,57357	1417,48	298,727	12,6243	CRS
16:43:29,319	14084,4	1,21924	1,57144	1,57047	1423,19	299,377	12,2883	CRS
16:44:39,319	14138,1	1,22458	1,5731	1,57213	1428,78	300,686	12,4687	CRS
16:45:49,319	14191,9	1,22949	1,57548	1,57452	1434,39	301,887	12,7289	CRS
16:46:59,319	14245,6	1,23182	1,57218	1,57122	1440,11	302,459	12,3687	CRS
16:48:09,318	14299,4	1,23742	1,57442	1,57348	1445,7	303,83	12,6132	CRS
16:49:19,318	14353,2	1,24153	1,57542	1,57447	1451,34	304,838	12,7226	CRS
16:50:29,318	14407	1,24384	1,57222	1,57126	1457,07	305,405	12,3733	CRS
16:51:39,317	14460,7	1,24921	1,57511	1,57415	1462,66	306,72	12,689	CRS
16:52:49,317	14514,5	1,25313	1,57576	1,5748	1468,31	307,679	12,7603	CRS
16:53:59,317	14568,2	1,25494	1,57171	1,57076	1474,06	308,123	12,3176	CRS
16:55:09,317	14622	1,26129	1,57564	1,57469	1479,6	309,68	12,7466	CRS
16:56:19,317	14675,7	1,26452	1,57491	1,57396	1485,29	310,47	12,6667	CRS
16:57:29,316	14729,5	1,26696	1,57203	1,57108	1491,02	311,068	12,3521	CRS
16:58:39,316	14783,3	1,27357	1,57608	1,57513	1496,55	312,687	12,7944	CRS
16:59:49,316	14837	1,2766	1,57477	1,57384	1502,25	313,43	12,652	CRS
17:00:59,315	14890,8	1,27898	1,57194	1,57099	1507,98	314,015	12,3421	CRS
17:02:09,315	14944,6	1,28635	1,57778	1,57685	1513,48	315,82	12,9803	CRS
17:03:19,315	14998,4	1,2891	1,57628	1,57534	1519,19	316,492	12,8163	CRS
17:04:29,315	15052,1	1,29139	1,57357	1,57265	1524,92	317,055	12,5211	CRS
17:05:39,315	15105,9	1,29821	1,57917	1,57824	1530,45	318,726	13,1322	CRS
17:06:49,315	15159,6	1,30091	1,57732	1,57638	1536,16	319,386	12,93	CRS
17:07:59,314	15213,4	1,3035	1,57435	1,57343	1541,88	320,021	12,606	CRS
17:09:09,313	15267,1	1,30979	1,57962	1,57871	1547,43	321,561	13,1815	CRS
17:10:19,313	15320,9	1,31211	1,57703	1,5761	1553,16	322,132	12,8988	CRS
17:11:29,313	15374,6	1,31563	1,57571	1,57478	1558,84	322,992	12,7545	CRS
17:12:39,313	15428,4	1,32168	1,57993	1,57901	1564,41	324,476	13,216	CRS
17:13:49,313	15482,2	1,32409	1,57699	1,57608	1570,13	325,065	12,8948	CRS
17:14:59,312	15536	1,32841	1,57642	1,57549	1575,77	326,124	12,8318	CRS
17:16:09,312	15589,7	1,33431	1,58069	1,57976	1581,35	327,569	13,2986	CRS
17:17:19,311	15643,5	1,33666	1,5774	1,57648	1587,08	328,145	12,9395	CRS
17:18:29,311	15697,3	1,34202	1,57825	1,57734	1592,68	329,46	13,0324	CRS
17:19:39,311	15751	1,34757	1,58136	1,58046	1598,27	330,819	13,3721	CRS
17:20:49,311	15804,8	1,35029	1,57832	1,57741	1603,98	331,484	13,0401	CRS
17:21:59,311	15858,6	1,35599	1,58036	1,57945	1609,56	332,881	13,2627	CRS
17:23:09,311	15912,3	1,36111	1,58271	1,58184	1615,17	334,136	13,5194	CRS
17:24:19,310	15966	1,364	1,57961	1,5787	1620,88	334,843	13,1808	CRS
17:25:29,309	16019,8	1,37013	1,58268	1,58181	1626,44	336,345	13,5162	CRS
17:26:39,309	16073,6	1,3745	1,58305	1,58218	1632,09	337,416	13,5567	CRS
17:27:49,309	16127,4	1,37765	1,58047	1,57957	1637,79	338,189	13,2749	CRS
17:28:59,309	16181,1	1,38428	1,58389	1,58305	1643,33	339,811	13,6488	CRS
17:30:09,309	16234,9	1,38874	1,5842	1,58335	1648,97	340,904	13,6822	CRS
17:31:19,309	16288,6	1,39142	1,58046	1,57956	1654,69	341,56	13,274	CRS
17:32:29,308	16342,4	1,39849	1,58453	1,58369	1660,22	343,294	13,7189	CRS
17:33:39,307	16396,2	1,40243	1,5834	1,58255	1665,88	344,26	13,5951	CRS
17:34:49,307	16450	1,40535	1,57996	1,57906	1671,59	344,974	13,2188	CRS
17:35:59,307	16503,7	1,41323	1,58558	1,5847	1677,09	346,904	13,833	CRS
17:37:09,307	16557,5	1,41696	1,5845	1,58367	1682,76	347,818	13,7148	CRS
17:38:19,307	16611,2	1,41963	1,58056	1,57966	1688,47	348,472	13,2845	CRS
17:39:29,306	16665	1,42758	1,58592	1,58504	1693,97	350,422	13,87	CRS
17:40:39,307	16718,7	1,4313	1,58444	1,5836	1699,64	351,332	13,7091	CRS
17:41:49,305	16772,5	1,4348	1,58162	1,58077	1705,33	352,19	13,4009	CRS
17:42:59,305	16826,3	1,44201	1,5867	1,58581	1710,85	353,956	13,9554	CRS
17:44:09,305	16880	1,44551	1,58493	1,58408	1716,54	354,813	13,7623	CRS
17:45:19,305	16933,8	1,44934	1,58283	1,58198	1722,21	355,752	13,5325	CRS
17:46:29,304	16987,6	1,45704	1,58818	1,5873	1727,72	357,639	14,118	CRS
17:47:39,305	17041,4	1,46005	1,58494	1,58409	1733,43	358,376	13,7629	CRS
17:48:49,305	17095,1	1,46455	1,58341	1,58258	1739,07	359,479	13,5957	CRS
17:49:59,303	17148,9	1,47178	1,58828	1,5874	1744,6	361,251	14,128	CRS
17:51:09,303	17202,6	1,4748	1,58461	1,58378	1750,3	361,989	13,7268	CRS
17:52:19,303	17256,4	1,48028	1,58437	1,58354	1755,91	363,332	13,7007	CRS
17:53:29,303	17310,1	1,48684	1,5878	1,58692	1761,46	364,939	14,0756	CRS
17:54:39,303	17363,9	1,4899	1,58411	1,5833	1767,16	365,688	13,6728	CRS
17:55:49,303	17417,6	1,4961	1,58542	1,58459	1772,74	367,208	13,816	CRS
17:56:59,303	17471,4	1,50298	1,58891	1,58803	1778,29	368,894	14,1968	CRS
17:58:09,301	17525,2	1,5064	1,58558	1,58473	1783,98	369,731	13,8328	CRS
17:59:19,301	17579	1,51315	1,5879	1,58704	1789,53	371,386	14,0866	CRS
18:00:29,301	17632,7	1,51899	1,58978	1,58892	1795,12	372,817	14,2921	CRS
18:01:39,301	17686,5	1,5223	1,58625	1,58539	1800,82	373,628	13,9061	CRS
18:02:49,301	17740,3	1,52944	1,58942	1,58858	1806,36	375,376	14,2535	CRS
18:03:59,301	17794	1,53535	1,59078	1,58992	1811,95	376,824	14,4018	CRS
18:05:09,301	17847,8	1,539	1,58705	1,5862	1817,63	377,717	13,9938	CRS
18:06:19,300	17901,6	1,54716	1,59084	1,58999	1823,13	379,718	14,408	CRS
18:07:29,299	17955,4	1,55263	1,59095	1,5901	1828,74	381,058	14,4204	CRS
18:08:39,299	18009	1,55655	1,58792	1,58708	1834,4	382,017	14,0886	CRS
18:09:49,299	18062,8	1,56513	1,59247	1,59163	1839,88	384,121	14,5868	CRS
18:10:59,299	18116,6	1,57051	1,59222	1,59138	1845,5	385,439	14,5592	CRS
18:12:09,299	18170,4	1,57441	1,58887	1,58802	1851,17	386,395	14,1927	CRS
18:13:19,299	18224,1	1,58389	1,59488	1,59404	1856,62	388,717	14,8497	CRS
18:14:29,298	18277,9	1,58866	1,59363	1,59278	1862,26	389,886	14,7129	CRS
18:15:39,297	18331,6	1,59273	1,59012	1,58928	1867,93	390,882	14,3298	CRS
18:16:49,297	18385,4	1,60187	1,59609	1,59525	1873,39	393,122	14,9824	CRS
18:17:59,297	18439,2	1,60665	1,59457	1,59374	1879,03	394,294	14,8156	CRS
18:19:09,297	18493	1,61083	1,59115	1,59033	1884,7	395,318	14,442	CRS
18:20:19,297	18546,7	1,61981	1,59731	1,59648	1890,17	397,517	15,115	CRS
18:21:29,297	18600,5	1,62361	1,59421	1,59338	1895,85	398,448	14,7763	CRS
18:22:39,296	18654,2	1,62858	1,59185	1,59103	1901,48	399,665	14,5182	CRS
18:23:49,295	18708	1,63675	1,59741	1,59659	1906,98	401,666	15,1264	CRS
18:24:59,296	18761,7	1,64069	1,59402	1,59321	1912,66	402,634	14,7554	CRS
18:26:09,295	18815,5	1,64598	1,59257	1,59177	1918,28	403,929	14,5971	CRS
18:27:19,295	18869,3	1,65394	1,59728	1,59648	1923,8	405,879	15,112	CRS
18:28:29,295	18923	1,65805	1,5936	1,59279	1929,47	406,886	14,7096	CRS
18:29:39,295	18976,8	1,66481	1,59386	1,59306	1935,03	408,542	14,7387	CRS
18:30:49,294	19030,6	1,67216	1,59718	1,59638	1940,57	410,342	15,1014	CRS
18:31:59,293	19084,4	1,67654	1,59367	1,59288	1946,24	411,417	14,7177	CRS
18:33:09,293	19138,1	1,68378	1,59541	1,59461	1951,78	413,189	14,9076	CRS
18:34:19,293	19191,9	1,69143	1,59815	1,59735	1957,31	415,063	15,2075	CRS
18:35:29,293	19245,6	1,69534	1,59365	1,59286	1962,99	416,022	14,7153	CRS
18:36:39,293	19299,4	1,70265	1,59584	1,59506	1968,54	417,812	14,9544	CRS
18:37:49,293	19353,2	1,70882	1,59784	1,59706	1974,13	419,325	15,1735	CRS
18:38:59,292	19406,9	1,71257	1,59407	1,59328	1979,81	420,244	14,7612	CRS
18:40:09,291	19460,6	1,7204	1,59684	1,59607	1985,34	422,163	15,0645	CRS
18:41:19,292	19514,4	1,72656	1,59786	1,59707	1990,93	423,67	15,1752	CRS
18:42:29,291	19568,2	1,7311	1,59444	1,59367	1996,59	424,783	14,8017	CRS
18:43:39,291	19622	1,73991	1,59804	1,59726	2002,08	426,943	15,1956	CRS
18:44:49,291	19675,7	1,74561	1,59731	1,59654	2007,69	428,339	15,1157	CRS
18:45:59,291	19729,5	1,75068	1,59482	1,59405	2013,33	429,579	14,8437	CRS
18:47:09,290	19783,3	1,76009	1,59891	1,59814	2018,8	431,886	15,29	CRS
18:48:19,289	19837	1,76598	1,59827	1,5975	2024,4	433,328	15,2206	CRS
18:49:29,289	19890,8	1,77055	1,59477	1,59401	2030,06	434,448	14,8378	CRS
18:50:39,289	19944,6	1,78113	1,60084	1,60009	2035,48	437,04	15,5017	CRS
18:51:49,289	19998,4	1,78728	1,59964	1,59888	2041,08	438,547	15,37	CRS
18:52:59,289	20052,1	1,79311	1,59755	1,59678	2046,68	439,975	15,1411	CRS
18:54:09,289	20105,8	1,80366	1,60425	1,60351	2052,11	442,561	15,8743	CRS
18:55:19,288	20159,6	1,80957	1,60196	1,60121	2057,72	444,008	15,6235	CRS
18:56:29,288	20213,4	1,81491	1,59919	1,59844	2063,35	445,316	15,3207	CRS
18:57:39,288	20267,1	1,82497	1,60621	1,60545	2068,8	447,782	16,0877	CRS
18:58:49,287	20320,9	1,82904	1,60158	1,60083	2074,48	448,779	15,5823	CRS
18:59:59,287	20374,6	1,83488	1,59985	1,5991	2080,09	450,209	15,3929	CRS
19:01:09,287	20428,4	1,84452	1,60593	1,60519	2085,56	452,571	16,0574	CRS
19:02:19,287	20482,2	1,8491	1,60233	1,60159	2091,22	453,692	15,6638	CRS
19:03:29,285	20536	1,85638	1,60106	1,60032	2096,78	455,478	15,5249	CRS
19:04:39,285	20589,7	1,86566	1,60593	1,6052	2102,26	457,751	16,0579	CRS
19:05:49,285	20643,5	1,8703	1,60166	1,60094	2107,92	458,886	15,591	CRS
19:06:59,285	20697,3	1,87843	1,6029	1,60216	2113,45	460,879	15,7262	CRS
19:08:09,285	20751	1,88716	1,60663	1,60591	2118,94	463,019	16,1339	CRS
19:09:19,285	20804,7	1,89195	1,60254	1,60181	2124,6	464,191	15,6865	CRS
19:10:29,285	20858,5	1,89975	1,60279	1,60207	2130,14	466,101	15,7148	CRS
19:11:39,283	20912,3	1,90871	1,60665	1,60591	2135,64	468,297	16,1359	CRS
19:12:49,283	20966	1,91339	1,60232	1,60159	2141,3	469,445	15,6626	CRS
19:13:59,283	21019,8	1,92201	1,60413	1,60342	2146,81	471,556	15,8612	CRS
19:15:09,283	21073,6	1,92967	1,60637	1,60567	2152,36	473,432	16,1061	CRS
19:16:19,283	21127,4	1,93471	1,60162	1,60092	2158,01	474,667	15,5864	CRS
19:17:29,283	21181,1	1,94407	1,60525	1,60455	2163,5	476,96	15,9834	CRS
19:18:39,282	21234,9	1,95132	1,60539	1,60469	2169,06	478,737	15,9985	CRS
19:19:49,282	21288,6	1,95615	1,60122	1,60052	2174,72	479,921	15,5424	CRS
19:20:59,282	21342,4	1,96627	1,60607	1,60537	2180,18	482,401	16,0723	CRS
19:22:09,282	21396,2	1,97279	1,60544	1,60474	2185,77	483,998	16,0035	CRS
19:23:19,281	21449,9	1,97836	1,60123	1,60052	2191,39	485,361	15,5434	CRS
19:24:29,281	21503,6	1,98901	1,6066	1,60592	2196,84	487,971	16,131	CRS
19:25:39,280	21557,4	1,99641	1,60648	1,60579	2202,4	489,784	16,1176	CRS
19:26:49,280	21611,2	2,00193	1,60216	1,60147	2208,03	491,137	15,645	CRS
19:27:59,279	21665	2,0139	1,60885	1,60818	2213,43	494,069	16,3771	CRS
19:29:09,280	21718,7	2,02067	1,60736	1,60669	2219,02	495,727	16,2143	CRS
19:30:19,279	21772,5	2,02681	1,60382	1,60315	2224,63	497,231	15,8274	CRS
19:31:29,279	21826,3	2,0386	1,61095	1,61027	2230,04	500,121	16,6064	CRS
19:32:39,279	21880	2,04593	1,60959	1,60891	2235,61	501,918	16,4576	CRS
19:33:49,279	21933,8	2,05285	1,60661	1,60595	2241,19	503,613	16,1318	CRS
19:34:59,278	21987,6	2,06507	1,61372	1,61306	2246,58	506,605	16,9095	CRS
19:36:09,277	22041,4	2,07225	1,61175	1,61109	2252,16	508,366	16,6939	CRS
19:37:19,277	22095,1	2,08001	1,60994	1,60927	2257,71	510,265	16,4961	CRS
19:38:29,277	22148,8	2,09101	1,61493	1,61429	2263,15	512,962	17,0414	CRS
19:39:39,277	22202,6	2,09744	1,61128	1,61063	2268,75	514,536	16,6427	CRS
19:40:49,277	22256,4	2,10637	1,61097	1,61031	2274,27	516,723	16,6081	CRS
19:41:59,277	22310,1	2,11715	1,61589	1,61526	2279,72	519,364	17,1462	CRS
19:43:09,276	22363,9	2,12329	1,61116	1,61051	2285,33	520,87	16,6292	CRS
19:44:19,275	22417,6	2,13338	1,61236	1,61171	2290,81	523,342	16,76	CRS
19:45:29,276	22471,4	2,1437	1,61631	1,61567	2296,28	525,87	17,1918	CRS
19:46:39,275	22525,2	2,15004	1,61201	1,61137	2301,89	527,423	16,7222	CRS
19:47:49,275	22579	2,15997	1,61338	1,61274	2307,37	529,856	16,872	CRS
19:48:59,275	22632,7	2,17013	1,61662	1,61599	2312,85	532,345	17,2256	CRS
19:50:09,275	22686,5	2,17646	1,61199	1,61136	2318,46	533,895	16,72	CRS
19:51:19,274	22740,3	2,18708	1,61498	1,61435	2323,92	536,498	17,0472	CRS
19:52:29,274	22794	2,19613	1,6166	1,61599	2329,43	538,715	17,224	CRS
19:53:39,273	22847,7	2,20227	1,61119	1,61057	2335,05	540,219	16,6328	CRS
19:54:49,273	22901,5	2,21419	1,61647	1,61586	2340,47	543,139	17,2092	CRS
19:55:59,273	22955,3	2,22299	1,61636	1,61575	2346	545,296	17,1979	CRS
19:57:09,273	23009	2,2298	1,61238	1,61177	2351,59	546,965	16,762	CRS
19:58:19,273	23062,8	2,24188	1,61699	1,61638	2357,01	549,925	17,2659	CRS
19:59:29,272	23116,6	2,25059	1,61662	1,61602	2362,54	552,059	17,226	CRS
20:00:39,272	23170,4	2,25726	1,61188	1,61127	2368,14	553,692	16,7077	CRS
20:01:49,272	23224,1	2,26989	1,61792	1,61732	2373,54	556,788	17,3676	CRS
20:02:59,271	23277,9	2,27785	1,61573	1,61513	2379,1	558,736	17,1287	CRS
20:04:09,271	23331,6	2,28462	1,61163	1,61104	2384,7	560,395	16,6801	CRS
20:05:19,271	23385,4	2,298	1,61801	1,61741	2390,08	563,674	17,3778	CRS
20:06:29,271	23439,2	2,30641	1,61632	1,61574	2395,63	565,735	17,1934	CRS
20:07:39,270	23492,9	2,31409	1,61327	1,61269	2401,19	567,615	16,8599	CRS
20:08:49,269	23546,6	2,32837	1,62163	1,62105	2406,53	571,115	17,7735	CRS
20:09:59,270	23600,4	2,33608	1,61773	1,61718	2412,11	573,004	17,3476	CRS
20:11:09,269	23654,2	2,34447	1,61486	1,61428	2417,66	575,06	17,0338	CRS
20:12:19,269	23708	2,35785	1,62171	1,62113	2423,04	578,337	17,7823	CRS
20:13:29,269	23761,7	2,36603	1,61937	1,61879	2428,59	580,34	17,526	CRS
20:14:39,268	23815,5	2,37518	1,61737	1,61681	2434,12	582,583	17,3081	CRS
20:15:49,268	23869,3	2,38873	1,62385	1,62329	2439,5	585,903	18,0159	CRS
20:16:59,268	23923	2,39716	1,62082	1,62026	2445,05	587,967	17,6854	CRS
20:18:09,268	23976,8	2,40842	1,62122	1,62067	2450,5	590,728	17,7289	CRS
20:19:19,267	24030,6	2,42149	1,62563	1,62509	2455,9	593,928	18,2104	CRS
20:20:29,267	24084,4	2,42956	1,62171	1,62115	2461,47	595,905	17,7821	CRS
20:21:39,267	24138,1	2,4414	1,62323	1,6227	2466,91	598,807	17,9481	CRS
20:22:49,267	24191,8	2,45386	1,62731	1,62678	2472,32	601,86	18,3939	CRS
20:23:59,266	24245,6	2,46195	1,62254	1,62202	2477,88	603,842	17,8731	CRS
20:25:09,266	24299,4	2,4743	1,62497	1,62444	2483,31	606,866	18,1384	CRS
20:26:19,266	24353,1	2,48559	1,62788	1,62737	2488,77	609,634	18,4566	CRS
20:27:29,265	24406,9	2,49381	1,62303	1,6225	2494,33	611,648	17,9263	CRS
20:28:39,265	24460,6	2,50596	1,62591	1,6254	2499,76	614,623	18,2418	CRS
20:29:49,265	24514,4	2,51712	1,62837	1,62787	2505,23	617,358	18,5098	CRS
20:30:59,264	24568,2	2,52479	1,62227	1,62176	2510,82	619,238	17,843	CRS
20:32:09,264	24622	2,53861	1,62764	1,62715	2516,2	622,622	18,4305	CRS
20:33:19,264	24675,7	2,5487	1,62655	1,62606	2521,7	625,095	18,3118	CRS
20:34:29,263	24729,5	2,55751	1,62323	1,62273	2527,25	627,252	17,9486	CRS
20:35:39,263	24783,3	2,5717	1,62766	1,62718	2532,62	630,729	18,4326	CRS
20:36:49,263	24837	2,58179	1,62702	1,62655	2538,13	633,202	18,3625	CRS
20:37:59,263	24890,7	2,58994	1,62232	1,62184	2543,69	635,2	17,8494	CRS
20:39:09,262	24944,5	2,60526	1,62951	1,62903	2549,03	638,953	18,635	CRS
20:40:19,262	24998,3	2,61547	1,62833	1,62786	2554,53	641,454	18,5063	CRS
20:41:29,262	25052	2,62402	1,62331	1,62285	2560,09	643,548	17,9566	CRS
20:42:39,262	25105,8	2,63975	1,63126	1,63079	2565,42	647,402	18,8259	CRS
20:43:49,261	25159,6	2,64977	1,62893	1,62848	2570,93	649,856	18,5719	CRS
20:44:59,261	25213,4	2,65857	1,62413	1,62368	2576,49	652,013	18,0466	CRS
20:46:09,261	25267,1	2,67394	1,6319	1,63143	2581,83	655,778	18,8957	CRS
20:47:19,260	25320,9	2,68304	1,6282	1,62775	2587,37	658,009	18,4914	CRS
20:48:29,260	25374,6	2,69345	1,62621	1,62578	2592,87	660,558	18,274	CRS
20:49:39,260	25428,4	2,70801	1,63194	1,63149	2598,25	664,126	18,9001	CRS
20:50:49,259	25482,2	2,71799	1,62901	1,62858	2603,76	666,571	18,5805	CRS
20:51:59,259	25535,9	2,72917	1,62725	1,62681	2609,24	669,31	18,3879	CRS
20:53:09,259	25589,6	2,744	1,63279	1,63236	2614,6	672,943	18,9938	CRS
20:54:19,259	25643,4	2,75319	1,62892	1,6285	2620,15	675,194	18,5705	CRS
20:55:29,258	25697,2	2,76588	1,62998	1,62956	2625,58	678,304	18,6865	CRS
20:56:39,258	25751	2,78039	1,63553	1,63512	2630,96	681,86	19,2927	CRS
20:57:49,258	25804,7	2,78994	1,6301	1,62968	2636,49	684,2	18,6996	CRS
20:58:59,257	25858,5	2,80291	1,63179	1,63138	2641,92	687,376	18,8837	CRS
21:00:09,257	25912,3	2,81756	1,63702	1,63662	2647,3	690,966	19,4561	CRS
21:01:19,257	25966	2,82722	1,63231	1,63191	2652,83	693,332	18,9409	CRS
21:02:29,257	26019,8	2,84213	1,63595	1,63555	2658,2	696,986	19,3385	CRS
21:03:39,256	26073,6	2,85641	1,63985	1,63948	2663,59	700,484	19,7652	CRS
21:04:49,256	26127,4	2,8666	1,63498	1,63459	2669,12	702,982	19,2324	CRS
21:05:59,256	26181,1	2,88148	1,63878	1,63839	2674,49	706,627	19,6482	CRS
21:07:09,255	26234,8	2,89436	1,64012	1,63976	2679,92	709,781	19,795	CRS
21:08:19,255	26288,6	2,90383	1,63499	1,63462	2685,46	712,103	19,2338	CRS
21:09:29,255	26342,4	2,91978	1,64021	1,63985	2690,81	716,009	19,804	CRS
21:10:39,254	26396,1	2,93143	1,63891	1,63855	2696,28	718,865	19,6618	CRS
21:11:49,254	26449,9	2,94159	1,63348	1,63311	2701,81	721,353	19,0684	CRS
21:12:59,254	26503,6	2,95869	1,64059	1,64024	2707,12	725,543	19,846	CRS
21:14:09,254	26557,4	2,97122	1,63925	1,6389	2712,57	728,613	19,6994	CRS
21:15:19,253	26611,2	2,98109	1,63394	1,63361	2718,11	731,031	19,1194	CRS
21:16:29,253	26665	2,99905	1,64181	1,64146	2723,4	735,432	19,9797	CRS
21:17:39,253	26718,7	3,01117	1,6405	1,64018	2728,86	738,4	19,8365	CRS
21:18:49,252	26772,5	3,02203	1,63642	1,63609	2734,37	741,061	19,3899	CRS
21:19:59,252	26826,3	3,03986	1,64437	1,64404	2739,67	745,43	20,2589	CRS
21:21:09,252	26880	3,05171	1,64092	1,64061	2745,15	748,333	19,8823	CRS
21:22:19,251	26933,7	3,06351	1,63779	1,63747	2750,62	751,223	19,5398	CRS
21:23:29,251	26987,5	3,08132	1,64563	1,64532	2755,92	755,586	20,3967	CRS
21:24:39,251	27041,3	3,09203	1,64142	1,64112	2761,43	758,21	19,9371	CRS
21:25:49,251	27095	3,10443	1,63989	1,63959	2766,9	761,25	19,769	CRS
21:26:59,250	27148,8	3,12153	1,64582	1,64551	2772,22	765,438	20,4172	CRS
21:28:09,250	27202,6	3,1326	1,6416	1,64131	2777,73	768,15	19,9565	CRS
21:29:19,250	27256,4	3,14575	1,6399	1,63962	2783,18	771,372	19,7704	CRS
21:30:29,249	27310,1	3,16241	1,64629	1,64601	2788,52	775,453	20,4691	CRS
21:31:39,249	27363,9	3,17331	1,64087	1,6406	2794,03	778,124	19,8766	CRS
21:32:49,249	27417,6	3,18804	1,64073	1,64046	2799,43	781,733	19,8616	CRS
21:33:59,248	27471,4	3,20523	1,64796	1,64768	2804,76	785,945	20,6509	CRS
21:35:09,248	27525,2	3,21634	1,64272	1,64246	2810,27	788,666	20,0787	CRS
21:36:19,248	27579	3,23217	1,64382	1,64355	2815,64	792,546	20,1985	CRS
21:37:29,248	27632,6	3,24821	1,64821	1,64795	2820,99	796,474	20,6786	CRS
21:38:39,247	27686,4	3,25968	1,64334	1,64309	2826,5	799,285	20,147	CRS
21:39:49,247	27740,2	3,27635	1,6473	1,64706	2831,84	803,37	20,5789	CRS
21:40:59,247	27794	3,29174	1,64893	1,64869	2837,23	807,139	20,7576	CRS
21:42:09,246	27847,7	3,30414	1,64469	1,64445	2842,71	810,178	20,2935	CRS
21:43:19,246	27901,5	3,32248	1,64986	1,64963	2848,01	814,672	20,8586	CRS
21:44:29,246	27955,3	3,33792	1,65194	1,65171	2853,4	818,453	21,0868	CRS
21:45:39,245	28009	3,35067	1,64702	1,6468	2858,87	821,578	20,5484	CRS
21:46:49,245	28062,8	3,36986	1,6529	1,65266	2864,15	826,28	21,1918	CRS
21:47:59,245	28116,6	3,38493	1,65321	1,65301	2869,55	829,971	21,2255	CRS
21:49:09,245	28170,4	3,39681	1,6472	1,64701	2875,05	832,882	20,5689	CRS
21:50:19,244	28224,1	3,41722	1,65549	1,6553	2880,3	837,881	21,4746	CRS
21:51:29,244	28277,9	3,43152	1,65308	1,65289	2885,72	841,387	21,2106	CRS
21:52:39,244	28331,6	3,4436	1,64752	1,64734	2891,21	844,345	20,6038	CRS
21:53:49,243	28385,4	3,46433	1,65642	1,65624	2896,46	849,424	21,5766	CRS
21:54:59,243	28439,1	3,47886	1,6549	1,65472	2901,88	852,984	21,4101	CRS
21:56:09,243	28492,9	3,49135	1,64917	1,64899	2907,36	856,044	20,7833	CRS
21:57:19,243	28546,6	3,51254	1,65875	1,6586	2912,6	861,237	21,831	CRS
21:58:29,242	28600,4	3,52564	1,6549	1,65474	2918,07	864,444	21,4096	CRS
21:59:39,243	28654,2	3,53955	1,6518	1,65163	2923,51	867,854	21,0715	CRS
22:00:49,242	28708	3,55971	1,6595	1,65934	2928,78	872,794	21,9127	CRS
22:01:59,241	28761,7	3,57299	1,65533	1,65519	2934,24	876,046	21,4566	CRS
22:03:09,241	28815,5	3,58754	1,65195	1,6518	2939,67	879,61	21,0873	CRS
22:04:19,241	28869,3	3,60667	1,65898	1,65886	2944,97	884,298	21,8556	CRS
22:05:29,240	28923	3,62024	1,65397	1,65384	2950,43	887,622	21,3083	CRS
22:06:39,240	28976,8	3,6366	1,65318	1,65306	2955,81	891,631	21,2222	CRS
22:07:49,240	29030,5	3,65583	1,65973	1,65962	2961,11	896,341	21,938	CRS
22:08:59,239	29084,3	3,6695	1,65539	1,65527	2966,56	899,692	21,4639	CRS
22:10:09,239	29138	3,68676	1,65595	1,65585	2971,92	903,921	21,5248	CRS
22:11:19,239	29191,8	3,70618	1,66144	1,66135	2977,22	908,678	22,1252	CRS
22:12:29,239	29245,6	3,71942	1,65517	1,65509	2982,69	911,923	21,4398	CRS
22:13:39,239	29299,4	3,73722	1,65789	1,6578	2988,04	916,282	21,7368	CRS
22:14:49,239	29353,1	3,75538	1,66037	1,66028	2993,38	920,731	22,0074	CRS
22:15:59,238	29406,9	3,76906	1,65617	1,65611	2998,84	924,083	21,5493	CRS
22:17:09,237	29460,6	3,78816	1,65765	1,65757	3004,16	928,764	21,7103	CRS
22:18:19,237	29514,4	3,80618	1,66262	1,66254	3009,5	933,178	22,2539	CRS
22:19:29,237	29568,2	3,82045	1,65672	1,65667	3014,95	936,673	21,6092	CRS
22:20:39,237	29622	3,841	1,66191	1,66186	3020,23	941,709	22,1763	CRS
22:21:49,237	29675,7	3,85804	1,66243	1,66239	3025,6	945,884	22,2335	CRS
22:22:59,237	29729,4	3,8729	1,65716	1,65714	3031,03	949,525	21,6571	CRS
22:24:09,235	29783,2	3,894	1,66303	1,663	3036,3	954,694	22,2981	CRS
22:25:19,235	29837	3,91169	1,66382	1,6638	3041,66	959,027	22,3847	CRS
22:26:29,235	29890,7	3,92659	1,65917	1,65915	3047,09	962,679	21,8766	CRS
22:27:39,235	29944,5	3,95011	1,66681	1,6668	3052,3	968,442	22,712	CRS
22:28:49,235	29998,3	3,96764	1,66648	1,66649	3057,67	972,735	22,6753	CRS
22:29:59,235	30052	3,9833	1,66232	1,66232	3063,09	976,572	22,2209	CRS
22:31:09,235	30105,8	4,00706	1,67033	1,67035	3068,29	982,394	23,0968	CRS
22:32:19,233	30159,6	4,02449	1,67059	1,67061	3073,66	986,664	23,1248	CRS
22:33:29,233	30213,4	4,03948	1,66401	1,66402	3079,11	990,337	22,4059	CRS
22:34:39,233	30267,1	4,06395	1,674	1,67403	3084,3	996,33	23,4979	CRS
22:35:49,233	30320,9	4,07991	1,66955	1,66956	3089,71	1000,24	23,0109	CRS
22:36:59,233	30374,6	4,09688	1,66629	1,66634	3095,09	1004,4	22,655	CRS
22:38:09,233	30428,4	4,12007	1,67487	1,67492	3100,32	1010,08	23,5929	CRS
22:39:19,232	30482,1	4,13617	1,67081	1,67086	3105,73	1014,02	23,1487	CRS
22:40:29,231	30535,9	4,15469	1,66921	1,66926	3111,09	1018,56	22,9737	CRS
22:41:39,231	30589,6	4,17701	1,67443	1,6745	3116,34	1024,03	23,5445	CRS
22:42:49,231	30643,4	4,19317	1,67104	1,67112	3121,76	1027,99	23,1742	CRS
22:43:59,231	30697,2	4,21242	1,6704	1,67049	3127,09	1032,71	23,1036	CRS
22:45:09,231	30751	4,23457	1,67597	1,67605	3132,35	1038,13	23,7127	CRS
22:46:19,231	30804,7	4,25041	1,67037	1,67047	3137,78	1042,01	23,1006	CRS
22:47:29,229	30858,5	4,27017	1,67102	1,67114	3143,11	1046,85	23,1724	CRS
22:48:39,229	30912,3	4,29237	1,67655	1,67666	3148,37	1052,29	23,7762	CRS
22:49:49,229	30966	4,30851	1,66993	1,67005	3153,79	1056,25	23,0523	CRS
22:50:59,229	31019,8	4,33038	1,67401	1,67413	3159,07	1061,61	23,4983	CRS
22:52:09,229	31073,5	4,35143	1,67717	1,6773	3164,36	1066,76	23,8438	CRS
22:53:19,229	31127,3	4,36765	1,67126	1,67142	3169,78	1070,74	23,1982	CRS
22:54:29,228	31181	4,3899	1,67489	1,67503	3175,05	1076,19	23,5951	CRS
22:55:39,227	31234,8	4,41031	1,67694	1,67709	3180,37	1081,19	23,8193	CRS
22:56:49,227	31288,6	4,42625	1,67079	1,67097	3185,8	1085,09	23,1469	CRS
22:57:59,227	31342,4	4,44887	1,67465	1,67482	3191,06	1090,64	23,5691	CRS
22:59:09,227	31396,1	4,46872	1,67619	1,67636	3196,4	1095,5	23,7373	CRS
23:00:19,227	31449,9	4,48529	1,67034	1,67052	3201,81	1099,56	23,097	CRS
23:01:29,227	31503,6	4,50999	1,67607	1,67625	3207,03	1105,61	23,7238	CRS
23:02:39,226	31557,4	4,53152	1,6786	1,67879	3212,33	1110,89	23,9998	CRS
23:03:49,225	31611,2	4,54804	1,67098	1,6712	3217,75	1114,93	23,1675	CRS
23:04:59,225	31665	4,57527	1,68143	1,68163	3222,9	1121,6	24,3096	CRS
23:06:09,225	31718,7	4,59483	1,68049	1,6807	3228,25	1126,4	24,2064	CRS
23:07:19,225	31772,4	4,61261	1,67525	1,67547	3233,64	1130,75	23,6344	CRS
23:08:29,225	31826,2	4,63899	1,6825	1,68272	3238,82	1137,22	24,4263	CRS
23:09:39,224	31880	4,66014	1,68346	1,6837	3244,13	1142,4	24,5318	CRS
23:10:49,224	31933,7	4,67805	1,6786	1,67885	3249,52	1146,79	24,0005	CRS
23:11:59,224	31987,5	4,70598	1,68825	1,68849	3254,67	1153,63	25,0546	CRS
23:13:09,223	32041,3	4,7265	1,68448	1,68475	3260	1158,66	24,6426	CRS
23:14:19,223	32095	4,74592	1,68128	1,68154	3265,36	1163,41	24,293	CRS
23:15:29,223	32148,8	4,77271	1,69051	1,69078	3270,54	1169,98	25,3023	CRS
23:16:39,223	32202,6	4,79253	1,68665	1,68693	3275,89	1174,83	24,8802	CRS
23:17:49,222	32256,4	4,8141	1,68438	1,68467	3281,2	1180,12	24,6324	CRS
23:18:59,221	32310,1	4,83984	1,6929	1,69317	3286,41	1186,42	25,5629	CRS
23:20:09,221	32363,9	4,85874	1,68653	1,68683	3291,79	1191,06	24,8669	CRS
23:21:19,221	32417,6	4,88154	1,68665	1,68697	3297,06	1196,64	24,8803	CRS
23:22:29,220	32471,4	4,90713	1,69206	1,69237	3302,28	1202,91	25,471	CRS
23:23:39,220	32525,1	4,9263	1,68732	1,68767	3307,65	1207,61	24,954	CRS
23:24:49,221	32578,9	4,95019	1,68818	1,68851	3312,91	1213,46	25,0472	CRS
23:25:59,219	32632,6	4,97588	1,69436	1,69469	3318,13	1219,75	25,7227	CRS
23:27:09,220	32686,4	4,99455	1,68601	1,68636	3323,52	1224,33	24,8098	CRS
23:28:19,219	32740,2	5,02054	1,69106	1,69141	3328,74	1230,7	25,3618	CRS
23:29:29,218	32794	5,04497	1,69428	1,69464	3333,99	1236,68	25,7143	CRS
23:30:39,219	32847,7	5,06411	1,68865	1,68902	3339,37	1241,37	25,0984	CRS
23:31:49,218	32901,5	5,09032	1,69275	1,69312	3344,58	1247,79	25,5472	CRS
23:32:59,218	32955,3	5,11449	1,69511	1,69549	3349,85	1253,71	25,8053	CRS
23:34:09,218	33009	5,13435	1,68834	1,68873	3355,21	1258,58	25,0651	CRS
23:35:19,217	33062,8	5,16114	1,69331	1,69371	3360,41	1265,14	25,608	CRS
23:36:29,217	33116,5	5,18474	1,69498	1,6954	3365,69	1270,92	25,7906	CRS
23:37:39,217	33170,3	5,20424	1,6877	1,68811	3371,06	1275,7	24,9953	CRS
23:38:49,217	33224	5,23311	1,69421	1,69464	3376,22	1282,78	25,7067	CRS
23:39:59,217	33277,8	5,25656	1,69483	1,69527	3381,51	1288,52	25,7744	CRS
23:41:09,215	33331,6	5,27612	1,68774	1,68818	3386,88	1293,31	24,9997	CRS
23:42:19,215	33385,4	5,30587	1,69661	1,69707	3392,03	1300,6	25,969	CRS
23:43:29,215	33439,1	5,32877	1,69498	1,69544	3397,33	1306,21	25,7903	CRS
23:44:39,215	33492,9	5,34907	1,68808	1,68855	3402,7	1311,19	25,0366	CRS
23:45:49,215	33546,6	5,38098	1,70054	1,70102	3407,79	1319	26,3979	CRS
23:46:59,214	33600,4	5,40352	1,69679	1,69728	3413,11	1324,52	25,9884	CRS
23:48:09,214	33654,2	5,42519	1,69156	1,69205	3418,45	1329,83	25,4165	CRS
23:49:19,213	33708	5,45574	1,70076	1,70127	3423,58	1337,32	26,4224	CRS
23:50:29,214	33761,7	5,47977	1,69948	1,69998	3428,86	1343,21	26,2825	CRS
23:51:39,213	33815,4	5,50195	1,69327	1,69378	3434,18	1348,64	25,6038	CRS
23:52:49,213	33869,2	5,53368	1,70549	1,70603	3439,29	1356,42	26,9394	CRS
23:53:59,213	33923	5,55662	1,70092	1,70146	3444,6	1362,03	26,4397	CRS
23:55:09,213	33976,7	5,58296	1,69821	1,69876	3449,84	1368,49	26,1438	CRS
23:56:19,211	34030,5	5,61448	1,70839	1,70896	3454,96	1376,21	27,2563	CRS
23:57:29,211	34084,3	5,63874	1,70482	1,70539	3460,25	1382,16	26,8664	CRS
23:58:39,211	34138	5,66661	1,70404	1,70462	3465,45	1388,98	26,7812	CRS
23:59:49,211	34191,8	5,69667	1,71059	1,71117	3470,61	1396,35	27,4967	CRS
00:00:59,211	34245,6	5,71988	1,70455	1,70514	3475,92	1402,03	26,8366	CRS
00:02:09,211	34299,4	5,74901	1,70649	1,7071	3481,11	1409,17	27,049	CRS
00:03:19,210	34353,1	5,77844	1,71174	1,71236	3486,28	1416,38	27,6221	CRS
00:04:29,210	34406,9	5,80174	1,70561	1,70623	3491,6	1422,09	26,9526	CRS
00:05:39,209	34460,6	5,8317	1,70948	1,71012	3496,76	1429,43	27,3756	CRS
00:06:49,209	34514,4	5,86075	1,71204	1,71267	3501,95	1436,55	27,6551	CRS
00:07:59,208	34568,1	5,88414	1,70694	1,7076	3507,26	1442,28	27,0977	CRS
00:09:09,209	34621,9	5,9152	1,71116	1,71182	3512,41	1449,89	27,5597	CRS
00:10:19,208	34675,6	5,94325	1,71314	1,71379	3517,63	1456,76	27,7753	CRS
00:11:29,207	34729,4	5,96693	1,70696	1,70764	3522,94	1462,56	27,0999	CRS
00:12:39,207	34783,2	5,99845	1,7114	1,71209	3528,08	1470,28	27,5857	CRS
00:13:49,207	34837	6,02712	1,71384	1,71453	3533,29	1477,31	27,8522	CRS
00:14:59,207	34890,7	6,05025	1,706	1,7067	3538,62	1482,97	26,9947	CRS
00:16:09,207	34944,5	6,08473	1,714	1,71471	3543,7	1491,42	27,8699	CRS
00:17:19,207	34998,3	6,11231	1,71462	1,71533	3548,94	1498,18	27,9371	CRS
00:18:29,205	35052	6,13617	1,70693	1,70766	3554,25	1504,03	27,097	CRS
00:19:39,205	35105,8	6,17097	1,71693	1,71768	3559,33	1512,55	28,1897	CRS
00:20:49,205	35159,5	6,19828	1,7144	1,71514	3564,57	1519,24	27,9128	CRS
00:21:59,205	35213,3	6,2221	1,70614	1,70692	3569,89	1525,08	27,0107	CRS
00:22:09,205	35221	6,23064	1,71355	1,71431	3570,54	1527,17	27,82	CRS